Workbook

Sheet 시험
C4: 장비요소 주기점검
D5: if 50회 주기도래:
D6: 필터세척
D8: if 100회 주기도래:
D9: 필터세척
D10: 벨트 텐션 점검 (XL : / ZL : / XR : / ZR : / Y : )
D11: 유량 점검 (T1, T4 : / T2, T3 : / T4 : )

Sheet ES#8
A1: LM-10 SPINDLE 내구도 신뢰성 시험이력
A2: 수행기간 | B2: 적용 BUR | G2: 적용 가공물 | K2: 실험상수 | L2: 사전점검(시험 전 점검항목) | AB2: 특이사항 | AD2: 산출 결과
M4: 5회 가공회차 주기 | Z4: 40회 가공회차 주기 | AA4: 160회 가공회차 주기
B5: BUR 가공누적사용횟수 | L5: 스핀들 유격 | M5: 스핀들 유격 | Q5: AG Mode Current(min-max) | U5: 35000 RPM Current(min-max) and 스핀들 소음
A6: 가공일 | B6: T1 | C6: T2 | D6: T3 | E6: T4 | F6: SPINDLE REV | G6: BLOCK 제조사 | H6: BLOCK 식별자 | I6: BLOCK 강도(MPa) | J6: BLOCK 재질 | K6: 가속 Factor | L6: WATER TANK FILTER 청결상태 | M6: T1 | N6: T2 | O6: T3 | P6: T4 | Q6: T1 | R6: T2 | S6: T3 | T6: T4 | U6: T1 | V6: T2 | W6: T3 | X6: T4 | Y6: 스핀들 소음유무 측정 | Z6: 필터세척/유량계 유량 측정 | AA6: 필터교체/BELT TENSION 측정 | AD6: 가공회차 | AE6: 산출가공물 치수 측정결과 | AF6: 시험완료여부 | AG6: 가공시간(분단위 반올림) | AH6: 비고
A7: 45971 | B7: 누락 | C7: - | D7: - | E7: 누락 | G7: VITA | H7: MARK II | I7: 160 | K7: =IF(LEN(A7)>0, 상수!B$4, "") -> 2.26 | L7: - | M7: =IF(MOD($AD7,5)=0, "스핀들유격: ","-" ) -> - | N7: =IF(MOD($AD7,5)=0, "스핀들유격: ","-" ) -> - | O7: =IF(MOD($AD7,5)=0, "스핀들유격: ","-" ) -> - | P7: =IF(MOD($AD7,5)=0, "스핀들유격: ","-" ) -> - | Q7: =IF(MOD($AD7,5)=0, "000-000 :","-" ) -> - | R7: =IF(MOD($AD7,5)=0, "000-000 :","-" ) -> - | S7: =IF(MOD($AD7,5)=0, "000-000 :","-" ) -> - | T7: =IF(MOD($AD7,5)=0, "000-000 :","-" ) -> - | U7: =IF(MOD($AD7,5)=0, "000-000 :","-" ) -> - | V7: =IF(MOD($AD7,5)=0, "000-000 :","-" ) -> - | W7: =IF(MOD($AD7,5)=0, "000-000 :","-" ) -> - | X7: =IF(MOD($AD7,5)=0, "000-000 :","-" ) -> - | Y7: =IF(MOD($AD7,5)=0, "스핀들소음 :","-" ) -> - | Z7: =IF(MOD($AD7,40)=0, "필터세척 :"& CHAR(10) & "FLOW (T1, T4 : / T2, T3 : / T4 : )","-" ) -> - | AA7: =IF($AD7="","", IF(MOD($AD7,160)=0, "TENSION (XL : / ZL : / XR : / ZR : / Y : )" & CHAR(10) & "필터교체", "-" ) ) -> - | AB7: - | AD7: 1 | AE7: =IF(AD7="","", IF(MOD($AD7,1)=0, "Dimensions: L W H", "-" ) ) -> Dimensions: L W H | AF7: =IF(AG7="","", IF(MOD($AD7,1)=0, "완료", "-" ) ) -> 완료 | AG7: 21분
A8: 45971 | B8: 누락 | C8: - | D8: - | E8: 누락 | G8: VITA | H8: MARK II | I8: 160 | K8: =IF(LEN(A8)>0, 상수!B$4, "") -> 2.26 | L8: - | M8: =IF(MOD($AD8,5)=0, "스핀들유격: ","-" ) -> - | N8: =IF(MOD($AD8,5)=0, "스핀들유격: ","-" ) -> - | O8: =IF(MOD($AD8,5)=0, "스핀들유격: ","-" ) -> - | P8: =IF(MOD($AD8,5)=0, "스핀들유격: ","-" ) -> - | Q8: =IF(MOD($AD8,5)=0, "000-000 :","-" ) -> - | R8: =IF(MOD($AD8,5)=0, "000-000 :","-" ) -> - | S8: =IF(MOD($AD8,5)=0, "000-000 :","-" ) -> - | T8: =IF(MOD($AD8,5)=0, "000-000 :","-" ) -> - | U8: =IF(MOD($AD8,5)=0, "000-000 :","-" ) -> - | V8: =IF(MOD($AD8,5)=0, "000-000 :","-" ) -> - | W8: =IF(MOD($AD8,5)=0, "000-000 :","-" ) -> - | X8: =IF(MOD($AD8,5)=0, "000-000 :","-" ) -> - | Y8: =IF(MOD($AD8,5)=0, "스핀들소음 :","-" ) -> - | Z8: =IF(MOD($AD8,40)=0, "필터세척 :"& CHAR(10) & "FLOW (T1, T4 : / T2, T3 : / T4 : )","-" ) -> - | AA8: =IF($AD8="","", IF(MOD(AD8,160)=0, "TENSION (XL : / ZL : / XR : / ZR : / Y : )" & CHAR(10) & "필터교체", "-" ) ) -> - | AB8: - | AD8: 2 | AE8: =IF(AD8="","", IF(MOD($AD8,1)=0, "Dimensions: L W H", "-" ) ) -> Dimensions: L W H | AF8: =IF(AG8="","", IF(MOD($AD8,1)=0, "완료", "-" ) ) -> 완료 | AG8: 21분
A9: 45971 | B9: 누락 | C9: - | D9: - | E9: 누락 | G9: VITA | H9: MARK II | I9: 160 | K9: =IF(LEN(A9)>0, 상수!B$4, "") -> 2.26 | L9: - | M9: =IF(MOD($AD9,5)=0, "스핀들유격: ","-" ) -> - | N9: =IF(MOD($AD9,5)=0, "스핀들유격: ","-" ) -> - | O9: =IF(MOD($AD9,5)=0, "스핀들유격: ","-" ) -> - | P9: =IF(MOD($AD9,5)=0, "스핀들유격: ","-" ) -> - | Q9: =IF(MOD($AD9,5)=0, "000-000 :","-" ) -> - | R9: =IF(MOD($AD9,5)=0, "000-000 :","-" ) -> - | S9: =IF(MOD($AD9,5)=0, "000-000 :","-" ) -> - | T9: =IF(MOD($AD9,5)=0, "000-000 :","-" ) -> - | U9: =IF(MOD($AD9,5)=0, "000-000 :","-" ) -> - | V9: =IF(MOD($AD9,5)=0, "000-000 :","-" ) -> - | W9: =IF(MOD($AD9,5)=0, "000-000 :","-" ) -> - | X9: =IF(MOD($AD9,5)=0, "000-000 :","-" ) -> - | Y9: =IF(MOD($AD9,5)=0, "스핀들소음 :","-" ) -> - | Z9: =IF(MOD($AD9,40)=0, "필터세척 :"& CHAR(10) & "FLOW (T1, T4 : / T2, T3 : / T4 : )","-" ) -> - | AA9: =IF($AD9="","", IF(MOD(AD9,160)=0, "TENSION (XL : / ZL : / XR : / ZR : / Y : )" & CHAR(10) & "필터교체", "-" ) ) -> - | AB9: - | AD9: 2 | AE9: =IF(AD9="","", IF(MOD($AD9,1)=0, "Dimensions: L W H", "-" ) ) -> Dimensions: L W H | AF9: =IF(AG9="","", IF(MOD($AD9,1)=0, "완료", "-" ) ) -> 완료 | AG9: 21분
A10: 45971 | B10: 누락 | C10: - | D10: - | E10: 누락 | G10: VITA | H10: MARK II | I10: 160 | K10: =IF(LEN(A10)>0, 상수!B$4, "") -> 2.26 | L10: - | M10: =IF(MOD($AD10,5)=0, "스핀들유격: ","-" ) -> - | N10: =IF(MOD($AD10,5)=0, "스핀들유격: ","-" ) -> - | O10: =IF(MOD($AD10,5)=0, "스핀들유격: ","-" ) -> - | P10: =IF(MOD($AD10,5)=0, "스핀들유격: ","-" ) -> - | Q10: =IF(MOD($AD10,5)=0, "000-000 :","-" ) -> - | R10: =IF(MOD($AD10,5)=0, "000-000 :","-" ) -> - | S10: =IF(MOD($AD10,5)=0, "000-000 :","-" ) -> - | T10: =IF(MOD($AD10,5)=0, "000-000 :","-" ) -> - | U10: =IF(MOD($AD10,5)=0, "000-000 :","-" ) -> - | V10: =IF(MOD($AD10,5)=0, "000-000 :","-" ) -> - | W10: =IF(MOD($AD10,5)=0, "000-000 :","-" ) -> - | X10: =IF(MOD($AD10,5)=0, "000-000 :","-" ) -> - | Y10: =IF(MOD($AD10,5)=0, "스핀들소음 :","-" ) -> - | Z10: =IF(MOD($AD10,40)=0, "필터세척 :"& CHAR(10) & "FLOW (T1, T4 : / T2, T3 : / T4 : )","-" ) -> - | AA10: =IF($AD10="","", IF(MOD(AD10,160)=0, "TENSION (XL : / ZL : / XR : / ZR : / Y : )" & CHAR(10) & "필터교체", "-" ) ) -> - | AB10: - | AD10: 4 | AE10: =IF(AD10="","", IF(MOD($AD10,1)=0, "Dimensions: L W H", "-" ) ) -> Dimensions: L W H | AF10: =IF(AG10="","", IF(MOD($AD10,1)=0, "완료", "-" ) ) -> 완료 | AG10: 21분
A11: TABLE OUTLINE | B11: TABLE OUTLINE | C11: TABLE OUTLINE | D11: TABLE OUTLINE | E11: TABLE OUTLINE | F11: TABLE OUTLINE | G11: TABLE OUTLINE | H11: TABLE OUTLINE | I11: TABLE OUTLINE | J11: TABLE OUTLINE | K11: TABLE OUTLINE | L11: TABLE OUTLINE | M11: TABLE OUTLINE | N11: TABLE OUTLINE | O11: TABLE OUTLINE | P11: TABLE OUTLINE | Q11: TABLE OUTLINE | R11: TABLE OUTLINE | S11: TABLE OUTLINE | T11: TABLE OUTLINE | U11: TABLE OUTLINE | V11: TABLE OUTLINE | W11: TABLE OUTLINE | X11: TABLE OUTLINE | Y11: TABLE OUTLINE | Z11: TABLE OUTLINE | AA11: TABLE OUTLINE | AB11: TABLE OUTLINE | AC11: TABLE OUTLINE | AD11: TABLE OUTLINE | AE11: TABLE OUTLINE | AF11: TABLE OUTLINE | AG11: TABLE OUTLINE | AH11: TABLE OUTLINE

Sheet ES#9
A1: LM-10 SPINDLE 내구도 신뢰성 시험이력
A2: 수행기간 | B2: 적용 BUR | G2: 적용 가공물 | K2: 실험상수 | L2: 사전점검(시험 전 점검항목) | AB2: 특이사항 | AD2: 산출 결과
M4: 5회 가공회차 주기 | Z4: 40회 가공회차 주기 | AA4: 160회 가공회차 주기
B5: BUR 가공누적사용횟수 | L5: 스핀들 유격 | M5: 스핀들 유격 | Q5: AG Mode Current(min-max) | U5: 35000 RPM Current(min-max) and 스핀들 소음
A6: 가공일 | B6: T1 | C6: T2 | D6: T3 | E6: T4 | F6: SPINDLE REV | G6: BLOCK 제조사 | H6: BLOCK 식별자 | I6: BLOCK 강도(MPa) | J6: BLOCK 재질 | K6: 가속 Factor | L6: WATER TANK FILTER 청결상태 | M6: T1 | N6: T2 | O6: T3 | P6: T4 | Q6: T1 | R6: T2 | S6: T3 | T6: T4 | U6: T1 | V6: T2 | W6: T3 | X6: T4 | Y6: 스핀들 소음유무 측정 | Z6: 필터세척/유량계 유량 측정 | AA6: 필터교체/BELT TENSION 측정 | AD6: 가공회차 | AE6: 산출가공물 치수 측정결과 | AF6: 시험완료여부 | AG6: 가공시간(분단위 반올림) | AH6: 비고
A7: 45971 | B7: 누락 | C7: - | D7: - | E7: 누락 | G7: VITA | H7: MARK II | I7: 160 | K7: =IF(LEN(A7)>0, 상수!B$4, "") -> 2.26 | L7: - | M7: =IF(MOD($AD7,5)=0, "스핀들유격: ","-" ) -> - | N7: =IF(MOD($AD7,5)=0, "스핀들유격: ","-" ) -> - | O7: =IF(MOD($AD7,5)=0, "스핀들유격: ","-" ) -> - | P7: =IF(MOD($AD7,5)=0, "스핀들유격: ","-" ) -> - | Q7: =IF(MOD($AD7,5)=0, "000-000 :","-" ) -> - | R7: =IF(MOD($AD7,5)=0, "000-000 :","-" ) -> - | S7: =IF(MOD($AD7,5)=0, "000-000 :","-" ) -> - | T7: =IF(MOD($AD7,5)=0, "000-000 :","-" ) -> - | U7: =IF(MOD($AD7,5)=0, "000-000 :","-" ) -> - | V7: =IF(MOD($AD7,5)=0, "000-000 :","-" ) -> - | W7: =IF(MOD($AD7,5)=0, "000-000 :","-" ) -> - | X7: =IF(MOD($AD7,5)=0, "000-000 :","-" ) -> - | Y7: =IF(MOD($AD7,5)=0, "스핀들소음 :","-" ) -> - | Z7: =IF(MOD($AD7,40)=0, "필터세척 :"& CHAR(10) & "FLOW (T1, T4 : / T2, T3 : / T4 : )","-" ) -> - | AA7: =IF($AD7="","", IF(MOD($AD7,160)=0, "TENSION (XL : / ZL : / XR : / ZR : / Y : )" & CHAR(10) & "필터교체", "-" ) ) -> - | AB7: - | AD7: 1 | AE7: =IF(AD7="","", IF(MOD($AD7,1)=0, "Dimensions: L W H", "-" ) ) -> Dimensions: L W H | AF7: =IF(AG7="","", IF(MOD($AD7,1)=0, "완료", "-" ) ) -> 완료 | AG7: 21분
A8: 45971 | B8: 누락 | C8: - | D8: - | E8: 누락 | G8: VITA | H8: MARK II | I8: 160 | K8: =IF(LEN(A8)>0, 상수!B$4, "") -> 2.26 | L8: - | M8: =IF(MOD($AD8,5)=0, "스핀들유격: ","-" ) -> - | N8: =IF(MOD($AD8,5)=0, "스핀들유격: ","-" ) -> - | O8: =IF(MOD($AD8,5)=0, "스핀들유격: ","-" ) -> - | P8: =IF(MOD($AD8,5)=0, "스핀들유격: ","-" ) -> - | Q8: =IF(MOD($AD8,5)=0, "000-000 :","-" ) -> - | R8: =IF(MOD($AD8,5)=0, "000-000 :","-" ) -> - | S8: =IF(MOD($AD8,5)=0, "000-000 :","-" ) -> - | T8: =IF(MOD($AD8,5)=0, "000-000 :","-" ) -> - | U8: =IF(MOD($AD8,5)=0, "000-000 :","-" ) -> - | V8: =IF(MOD($AD8,5)=0, "000-000 :","-" ) -> - | W8: =IF(MOD($AD8,5)=0, "000-000 :","-" ) -> - | X8: =IF(MOD($AD8,5)=0, "000-000 :","-" ) -> - | Y8: =IF(MOD($AD8,5)=0, "스핀들소음 :","-" ) -> - | Z8: =IF(MOD($AD8,40)=0, "필터세척 :"& CHAR(10) & "FLOW (T1, T4 : / T2, T3 : / T4 : )","-" ) -> - | AA8: =IF($AD8="","", IF(MOD(AD8,160)=0, "TENSION (XL : / ZL : / XR : / ZR : / Y : )" & CHAR(10) & "필터교체", "-" ) ) -> - | AB8: - | AD8: 2 | AE8: =IF(AD8="","", IF(MOD($AD8,1)=0, "Dimensions: L W H", "-" ) ) -> Dimensions: L W H | AF8: =IF(AG8="","", IF(MOD($AD8,1)=0, "완료", "-" ) ) -> 완료 | AG8: 21분
A9: 45971 | B9: 누락 | C9: - | D9: - | E9: 누락 | G9: VITA | H9: MARK II | I9: 160 | K9: =IF(LEN(A9)>0, 상수!B$4, "") -> 2.26 | L9: - | M9: =IF(MOD($AD9,5)=0, "스핀들유격: ","-" ) -> - | N9: =IF(MOD($AD9,5)=0, "스핀들유격: ","-" ) -> - | O9: =IF(MOD($AD9,5)=0, "스핀들유격: ","-" ) -> - | P9: =IF(MOD($AD9,5)=0, "스핀들유격: ","-" ) -> - | Q9: =IF(MOD($AD9,5)=0, "000-000 :","-" ) -> - | R9: =IF(MOD($AD9,5)=0, "000-000 :","-" ) -> - | S9: =IF(MOD($AD9,5)=0, "000-000 :","-" ) -> - | T9: =IF(MOD($AD9,5)=0, "000-000 :","-" ) -> - | U9: =IF(MOD($AD9,5)=0, "000-000 :","-" ) -> - | V9: =IF(MOD($AD9,5)=0, "000-000 :","-" ) -> - | W9: =IF(MOD($AD9,5)=0, "000-000 :","-" ) -> - | X9: =IF(MOD($AD9,5)=0, "000-000 :","-" ) -> - | Y9: =IF(MOD($AD9,5)=0, "스핀들소음 :","-" ) -> - | Z9: =IF(MOD($AD9,40)=0, "필터세척 :"& CHAR(10) & "FLOW (T1, T4 : / T2, T3 : / T4 : )","-" ) -> - | AA9: =IF($AD9="","", IF(MOD(AD9,160)=0, "TENSION (XL : / ZL : / XR : / ZR : / Y : )" & CHAR(10) & "필터교체", "-" ) ) -> - | AB9: - | AD9: 2 | AE9: =IF(AD9="","", IF(MOD($AD9,1)=0, "Dimensions: L W H", "-" ) ) -> Dimensions: L W H | AF9: =IF(AG9="","", IF(MOD($AD9,1)=0, "완료", "-" ) ) -> 완료 | AG9: 21분
A10: 45971 | B10: 누락 | C10: - | D10: - | E10: 누락 | G10: VITA | H10: MARK II | I10: 160 | K10: =IF(LEN(A10)>0, 상수!B$4, "") -> 2.26 | L10: - | M10: =IF(MOD($AD10,5)=0, "스핀들유격: ","-" ) -> - | N10: =IF(MOD($AD10,5)=0, "스핀들유격: ","-" ) -> - | O10: =IF(MOD($AD10,5)=0, "스핀들유격: ","-" ) -> - | P10: =IF(MOD($AD10,5)=0, "스핀들유격: ","-" ) -> - | Q10: =IF(MOD($AD10,5)=0, "000-000 :","-" ) -> - | R10: =IF(MOD($AD10,5)=0, "000-000 :","-" ) -> - | S10: =IF(MOD($AD10,5)=0, "000-000 :","-" ) -> - | T10: =IF(MOD($AD10,5)=0, "000-000 :","-" ) -> - | U10: =IF(MOD($AD10,5)=0, "000-000 :","-" ) -> - | V10: =IF(MOD($AD10,5)=0, "000-000 :","-" ) -> - | W10: =IF(MOD($AD10,5)=0, "000-000 :","-" ) -> - | X10: =IF(MOD($AD10,5)=0, "000-000 :","-" ) -> - | Y10: =IF(MOD($AD10,5)=0, "스핀들소음 :","-" ) -> - | Z10: =IF(MOD($AD10,40)=0, "필터세척 :"& CHAR(10) & "FLOW (T1, T4 : / T2, T3 : / T4 : )","-" ) -> - | AA10: =IF($AD10="","", IF(MOD(AD10,160)=0, "TENSION (XL : / ZL : / XR : / ZR : / Y : )" & CHAR(10) & "필터교체", "-" ) ) -> - | AB10: - | AD10: 4 | AE10: =IF(AD10="","", IF(MOD($AD10,1)=0, "Dimensions: L W H", "-" ) ) -> Dimensions: L W H | AF10: =IF(AG10="","", IF(MOD($AD10,1)=0, "완료", "-" ) ) -> 완료 | AG10: 21분
A11: TABLE OUTLINE | B11: TABLE OUTLINE | C11: TABLE OUTLINE | D11: TABLE OUTLINE | E11: TABLE OUTLINE | F11: TABLE OUTLINE | G11: TABLE OUTLINE | H11: TABLE OUTLINE | I11: TABLE OUTLINE | J11: TABLE OUTLINE | K11: TABLE OUTLINE | L11: TABLE OUTLINE | M11: TABLE OUTLINE | N11: TABLE OUTLINE | O11: TABLE OUTLINE | P11: TABLE OUTLINE | Q11: TABLE OUTLINE | R11: TABLE OUTLINE | S11: TABLE OUTLINE | T11: TABLE OUTLINE | U11: TABLE OUTLINE | V11: TABLE OUTLINE | W11: TABLE OUTLINE | X11: TABLE OUTLINE | Y11: TABLE OUTLINE | Z11: TABLE OUTLINE | AA11: TABLE OUTLINE | AB11: TABLE OUTLINE | AC11: TABLE OUTLINE | AD11: TABLE OUTLINE | AE11: TABLE OUTLINE | AF11: TABLE OUTLINE | AG11: TABLE OUTLINE | AH11: TABLE OUTLINE

Sheet PP#2
A1: LM-10 SPINDLE 내구도 신뢰성 시험이력
A2: 수행기간 | B2: 적용 BUR | G2: 적용 가공물 | K2: 실험상수 | L2: 사전점검(시험 전 점검항목) | AB2: 특이사항 | AD2: 산출 결과
M4: 5회 가공회차 주기 | Z4: 40회 가공회차 주기 | AA4: 160회 가공회차 주기
B5: BUR 가공누적사용횟수 | L5: 스핀들 유격 | M5: 스핀들 유격 | Q5: AG Mode Current(min-max) | U5: 35000 RPM Current(min-max) and 스핀들 소음
A6: 가공일 | B6: T1 | C6: T2 | D6: T3 | E6: T4 | F6: SPINDLE REV | G6: BLOCK 제조사 | H6: BLOCK 식별자 | I6: BLOCK 강도(MPa) | J6: BLOCK 재질 | K6: 가속 Factor | L6: WATER TANK FILTER 청결상태 | M6: T1 | N6: T2 | O6: T3 | P6: T4 | Q6: T1 | R6: T2 | S6: T3 | T6: T4 | U6: T1 | V6: T2 | W6: T3 | X6: T4 | Y6: 스핀들 소음유무 측정 | Z6: 필터세척/유량계 유량 측정 | AA6: 필터교체/BELT TENSION 측정 | AD6: 가공회차 | AE6: 산출가공물 치수 측정결과 | AF6: 시험완료여부 | AG6: 가공시간(분단위 반올림) | AH6: 비고
A7: 45971 | B7: 누락 | C7: - | D7: - | E7: 누락 | G7: VITA | H7: MARK II | I7: 160 | K7: =IF(LEN(A7)>0, 상수!B$4, "") -> 2.26 | L7: - | M7: =IF(MOD($AD7,5)=0, "스핀들유격: ","-" ) -> - | N7: =IF(MOD($AD7,5)=0, "스핀들유격: ","-" ) -> - | O7: =IF(MOD($AD7,5)=0, "스핀들유격: ","-" ) -> - | P7: =IF(MOD($AD7,5)=0, "스핀들유격: ","-" ) -> - | Q7: =IF(MOD($AD7,5)=0, "000-000 :","-" ) -> - | R7: =IF(MOD($AD7,5)=0, "000-000 :","-" ) -> - | S7: =IF(MOD($AD7,5)=0, "000-000 :","-" ) -> - | T7: =IF(MOD($AD7,5)=0, "000-000 :","-" ) -> - | U7: =IF(MOD($AD7,5)=0, "000-000 :","-" ) -> - | V7: =IF(MOD($AD7,5)=0, "000-000 :","-" ) -> - | W7: =IF(MOD($AD7,5)=0, "000-000 :","-" ) -> - | X7: =IF(MOD($AD7,5)=0, "000-000 :","-" ) -> - | Y7: =IF(MOD($AD7,5)=0, "스핀들소음 :","-" ) -> - | Z7: =IF(MOD($AD7,40)=0, "필터세척 :"& CHAR(10) & "FLOW (T1, T4 : / T2, T3 : / T4 : )","-" ) -> - | AA7: =IF($AD7="","", IF(MOD($AD7,160)=0, "TENSION (XL : / ZL : / XR : / ZR : / Y : )" & CHAR(10) & "필터교체", "-" ) ) -> - | AB7: - | AD7: 1 | AE7: =IF(AD7="","", IF(MOD($AD7,1)=0, "Dimensions: L W H", "-" ) ) -> Dimensions: L W H | AF7: =IF(AG7="","", IF(MOD($AD7,1)=0, "완료", "-" ) ) -> 완료 | AG7: 21분
A8: 45971 | B8: 누락 | C8: - | D8: - | E8: 누락 | G8: VITA | H8: MARK II | I8: 160 | K8: =IF(LEN(A8)>0, 상수!B$4, "") -> 2.26 | L8: - | M8: =IF(MOD($AD8,5)=0, "스핀들유격: ","-" ) -> - | N8: =IF(MOD($AD8,5)=0, "스핀들유격: ","-" ) -> - | O8: =IF(MOD($AD8,5)=0, "스핀들유격: ","-" ) -> - | P8: =IF(MOD($AD8,5)=0, "스핀들유격: ","-" ) -> - | Q8: =IF(MOD($AD8,5)=0, "000-000 :","-" ) -> - | R8: =IF(MOD($AD8,5)=0, "000-000 :","-" ) -> - | S8: =IF(MOD($AD8,5)=0, "000-000 :","-" ) -> - | T8: =IF(MOD($AD8,5)=0, "000-000 :","-" ) -> - | U8: =IF(MOD($AD8,5)=0, "000-000 :","-" ) -> - | V8: =IF(MOD($AD8,5)=0, "000-000 :","-" ) -> - | W8: =IF(MOD($AD8,5)=0, "000-000 :","-" ) -> - | X8: =IF(MOD($AD8,5)=0, "000-000 :","-" ) -> - | Y8: =IF(MOD($AD8,5)=0, "스핀들소음 :","-" ) -> - | Z8: =IF(MOD($AD8,40)=0, "필터세척 :"& CHAR(10) & "FLOW (T1, T4 : / T2, T3 : / T4 : )","-" ) -> - | AA8: =IF($AD8="","", IF(MOD(AD8,160)=0, "TENSION (XL : / ZL : / XR : / ZR : / Y : )" & CHAR(10) & "필터교체", "-" ) ) -> - | AB8: - | AD8: 2 | AE8: =IF(AD8="","", IF(MOD($AD8,1)=0, "Dimensions: L W H", "-" ) ) -> Dimensions: L W H | AF8: =IF(AG8="","", IF(MOD($AD8,1)=0, "완료", "-" ) ) -> 완료 | AG8: 19분
A9: 45971 | B9: 누락 | C9: - | D9: - | E9: 누락 | G9: VITA | H9: MARK II | I9: 160 | K9: =IF(LEN(A9)>0, 상수!B$4, "") -> 2.26 | L9: - | M9: =IF(MOD($AD9,5)=0, "스핀들유격: ","-" ) -> - | N9: =IF(MOD($AD9,5)=0, "스핀들유격: ","-" ) -> - | O9: =IF(MOD($AD9,5)=0, "스핀들유격: ","-" ) -> - | P9: =IF(MOD($AD9,5)=0, "스핀들유격: ","-" ) -> - | Q9: =IF(MOD($AD9,5)=0, "000-000 :","-" ) -> - | R9: =IF(MOD($AD9,5)=0, "000-000 :","-" ) -> - | S9: =IF(MOD($AD9,5)=0, "000-000 :","-" ) -> - | T9: =IF(MOD($AD9,5)=0, "000-000 :","-" ) -> - | U9: =IF(MOD($AD9,5)=0, "000-000 :","-" ) -> - | V9: =IF(MOD($AD9,5)=0, "000-000 :","-" ) -> - | W9: =IF(MOD($AD9,5)=0, "000-000 :","-" ) -> - | X9: =IF(MOD($AD9,5)=0, "000-000 :","-" ) -> - | Y9: =IF(MOD($AD9,5)=0, "스핀들소음 :","-" ) -> - | Z9: =IF(MOD($AD9,40)=0, "필터세척 :"& CHAR(10) & "FLOW (T1, T4 : / T2, T3 : / T4 : )","-" ) -> - | AA9: =IF($AD9="","", IF(MOD(AD9,160)=0, "TENSION (XL : / ZL : / XR : / ZR : / Y : )" & CHAR(10) & "필터교체", "-" ) ) -> - | AB9: - | AD9: 2 | AE9: =IF(AD9="","", IF(MOD($AD9,1)=0, "Dimensions: L W H", "-" ) ) -> Dimensions: L W H | AF9: =IF(AG9="","", IF(MOD($AD9,1)=0, "완료", "-" ) ) -> 완료 | AG9: 19분
A10: 45971 | B10: 누락 | C10: - | D10: - | E10: 누락 | G10: VITA | H10: MARK II | I10: 160 | K10: =IF(LEN(A10)>0, 상수!B$4, "") -> 2.26 | L10: - | M10: =IF(MOD($AD10,5)=0, "스핀들유격: ","-" ) -> - | N10: =IF(MOD($AD10,5)=0, "스핀들유격: ","-" ) -> - | O10: =IF(MOD($AD10,5)=0, "스핀들유격: ","-" ) -> - | P10: =IF(MOD($AD10,5)=0, "스핀들유격: ","-" ) -> - | Q10: =IF(MOD($AD10,5)=0, "000-000 :","-" ) -> - | R10: =IF(MOD($AD10,5)=0, "000-000 :","-" ) -> - | S10: =IF(MOD($AD10,5)=0, "000-000 :","-" ) -> - | T10: =IF(MOD($AD10,5)=0, "000-000 :","-" ) -> - | U10: =IF(MOD($AD10,5)=0, "000-000 :","-" ) -> - | V10: =IF(MOD($AD10,5)=0, "000-000 :","-" ) -> - | W10: =IF(MOD($AD10,5)=0, "000-000 :","-" ) -> - | X10: =IF(MOD($AD10,5)=0, "000-000 :","-" ) -> - | Y10: =IF(MOD($AD10,5)=0, "스핀들소음 :","-" ) -> - | Z10: =IF(MOD($AD10,40)=0, "필터세척 :"& CHAR(10) & "FLOW (T1, T4 : / T2, T3 : / T4 : )","-" ) -> - | AA10: =IF($AD10="","", IF(MOD(AD10,160)=0, "TENSION (XL : / ZL : / XR : / ZR : / Y : )" & CHAR(10) & "필터교체", "-" ) ) -> - | AB10: - | AD10: 4 | AE10: =IF(AD10="","", IF(MOD($AD10,1)=0, "Dimensions: L W H", "-" ) ) -> Dimensions: L W H | AF10: =IF(AG10="","", IF(MOD($AD10,1)=0, "완료", "-" ) ) -> 완료 | AG10: 19분
A11: 45971 | B11: 누락 | C11: - | D11: - | E11: 누락 | G11: VITA | H11: MARK II | I11: 160 | K11: =IF(LEN(A11)>0, 상수!B$4, "") -> 2.26 | L11: - | M11: =IF(MOD($AD11,5)=0, "스핀들유격: ","-" ) -> 스핀들유격: | N11: =IF(MOD($AD11,5)=0, "스핀들유격: ","-" ) -> 스핀들유격: | O11: =IF(MOD($AD11,5)=0, "스핀들유격: ","-" ) -> 스핀들유격: | P11: =IF(MOD($AD11,5)=0, "스핀들유격: ","-" ) -> 스핀들유격: | Q11: =IF(MOD($AD11,5)=0, "000-000 :","-" ) -> 000-000 : | R11: =IF(MOD($AD11,5)=0, "000-000 :","-" ) -> 000-000 : | S11: =IF(MOD($AD11,5)=0, "000-000 :","-" ) -> 000-000 : | T11: =IF(MOD($AD11,5)=0, "000-000 :","-" ) -> 000-000 : | U11: =IF(MOD($AD11,5)=0, "000-000 :","-" ) -> 000-000 : | V11: =IF(MOD($AD11,5)=0, "000-000 :","-" ) -> 000-000 : | W11: =IF(MOD($AD11,5)=0, "000-000 :","-" ) -> 000-000 : | X11: =IF(MOD($AD11,5)=0, "000-000 :","-" ) -> 000-000 : | Y11: =IF(MOD($AD11,5)=0, "스핀들소음 :","-" ) -> 스핀들소음 : | Z11: =IF(MOD($AD11,40)=0, "필터세척 :"& CHAR(10) & "FLOW (T1, T4 : / T2, T3 : / T4 : )","-" ) -> - | AA11: =IF($AD11="","", IF(MOD(AD11,160)=0, "TENSION (XL : / ZL : / XR : / ZR : / Y : )" & CHAR(10) & "필터교체", "-" ) ) -> - | AB11: - | AD11: 5 | AE11: =IF(AD11="","", IF(MOD($AD11,1)=0, "Dimensions: L W H", "-" ) ) -> Dimensions: L W H | AF11: =IF(AG11="","", IF(MOD($AD11,1)=0, "완료", "-" ) ) -> 완료 | AG11: 19분
A12: TABLE OUTLINE | B12: TABLE OUTLINE | C12: TABLE OUTLINE | D12: TABLE OUTLINE | E12: TABLE OUTLINE | F12: TABLE OUTLINE | G12: TABLE OUTLINE | H12: TABLE OUTLINE | I12: TABLE OUTLINE | J12: TABLE OUTLINE | K12: TABLE OUTLINE | L12: TABLE OUTLINE | M12: TABLE OUTLINE | N12: TABLE OUTLINE | O12: TABLE OUTLINE | P12: TABLE OUTLINE | Q12: TABLE OUTLINE | R12: TABLE OUTLINE | S12: TABLE OUTLINE | T12: TABLE OUTLINE | U12: TABLE OUTLINE | V12: TABLE OUTLINE | W12: TABLE OUTLINE | X12: TABLE OUTLINE | Y12: TABLE OUTLINE | Z12: TABLE OUTLINE | AA12: TABLE OUTLINE | AB12: TABLE OUTLINE | AC12: TABLE OUTLINE | AD12: TABLE OUTLINE | AE12: TABLE OUTLINE | AF12: TABLE OUTLINE | AG12: TABLE OUTLINE | AH12: TABLE OUTLINE

Sheet PP#3
A1: LM-10 SPINDLE 내구도 신뢰성 시험이력
A2: 수행기간 | B2: 적용 BUR | G2: 적용 가공물 | K2: 실험상수 | L2: 사전점검(시험 전 점검항목) | AB2: 특이사항 | AD2: 산출 결과
M4: 5회 가공회차 주기 | Z4: 40회 가공회차 주기 | AA4: 160회 가공회차 주기
B5: BUR 가공누적사용횟수 | L5: 스핀들 유격 | M5: 스핀들 유격 | Q5: AG Mode Current(min-max) | U5: 35000 RPM Current(min-max) and 스핀들 소음
A6: 가공일 | B6: T1 | C6: T2 | D6: T3 | E6: T4 | F6: SPINDLE REV | G6: BLOCK 제조사 | H6: BLOCK 식별자 | I6: BLOCK 강도(MPa) | J6: BLOCK 재질 | K6: 가속 Factor | L6: WATER TANK FILTER 청결상태 | M6: T1 | N6: T2 | O6: T3 | P6: T4 | Q6: T1 | R6: T2 | S6: T3 | T6: T4 | U6: T1 | V6: T2 | W6: T3 | X6: T4 | Y6: 스핀들 소음유무 측정 | Z6: 필터세척/유량계 유량 측정 | AA6: 필터교체/BELT TENSION 측정 | AD6: 가공회차 | AE6: 산출가공물 치수 측정결과 | AF6: 시험완료여부 | AG6: 가공시간(분단위 반올림) | AH6: 비고
A7: 45971 | B7: 누락 | C7: - | D7: - | E7: 누락 | G7: VITA | H7: MARK II | I7: 160 | K7: =IF(LEN(A7)>0, 상수!B$4, "") -> 2.26 | L7: - | M7: =IF(MOD($AD7,5)=0, "스핀들유격: ","-" ) -> - | N7: =IF(MOD($AD7,5)=0, "스핀들유격: ","-" ) -> - | O7: =IF(MOD($AD7,5)=0, "스핀들유격: ","-" ) -> - | P7: =IF(MOD($AD7,5)=0, "스핀들유격: ","-" ) -> - | Q7: =IF(MOD($AD7,5)=0, "000-000 :","-" ) -> - | R7: =IF(MOD($AD7,5)=0, "000-000 :","-" ) -> - | S7: =IF(MOD($AD7,5)=0, "000-000 :","-" ) -> - | T7: =IF(MOD($AD7,5)=0, "000-000 :","-" ) -> - | U7: =IF(MOD($AD7,5)=0, "000-000 :","-" ) -> - | V7: =IF(MOD($AD7,5)=0, "000-000 :","-" ) -> - | W7: =IF(MOD($AD7,5)=0, "000-000 :","-" ) -> - | X7: =IF(MOD($AD7,5)=0, "000-000 :","-" ) -> - | Y7: =IF(MOD($AD7,5)=0, "스핀들소음 :","-" ) -> - | Z7: =IF(MOD($AD7,40)=0, "필터세척 :"& CHAR(10) & "FLOW (T1, T4 : / T2, T3 : / T4 : )","-" ) -> - | AA7: =IF($AD7="","", IF(MOD($AD7,160)=0, "TENSION (XL : / ZL : / XR : / ZR : / Y : )" & CHAR(10) & "필터교체", "-" ) ) -> - | AB7: - | AD7: 1 | AE7: =IF(AD7="","", IF(MOD($AD7,1)=0, "Dimensions: L W H", "-" ) ) -> Dimensions: L W H | AF7: =IF(AG7="","", IF(MOD($AD7,1)=0, "완료", "-" ) ) -> 완료 | AG7: 21분
A8: 45971 | B8: 누락 | C8: - | D8: - | E8: 누락 | G8: VITA | H8: MARK II | I8: 160 | K8: =IF(LEN(A8)>0, 상수!B$4, "") -> 2.26 | L8: - | M8: =IF(MOD($AD8,5)=0, "스핀들유격: ","-" ) -> - | N8: =IF(MOD($AD8,5)=0, "스핀들유격: ","-" ) -> - | O8: =IF(MOD($AD8,5)=0, "스핀들유격: ","-" ) -> - | P8: =IF(MOD($AD8,5)=0, "스핀들유격: ","-" ) -> - | Q8: =IF(MOD($AD8,5)=0, "000-000 :","-" ) -> - | R8: =IF(MOD($AD8,5)=0, "000-000 :","-" ) -> - | S8: =IF(MOD($AD8,5)=0, "000-000 :","-" ) -> - | T8: =IF(MOD($AD8,5)=0, "000-000 :","-" ) -> - | U8: =IF(MOD($AD8,5)=0, "000-000 :","-" ) -> - | V8: =IF(MOD($AD8,5)=0, "000-000 :","-" ) -> - | W8: =IF(MOD($AD8,5)=0, "000-000 :","-" ) -> - | X8: =IF(MOD($AD8,5)=0, "000-000 :","-" ) -> - | Y8: =IF(MOD($AD8,5)=0, "스핀들소음 :","-" ) -> - | Z8: =IF(MOD($AD8,40)=0, "필터세척 :"& CHAR(10) & "FLOW (T1, T4 : / T2, T3 : / T4 : )","-" ) -> - | AA8: =IF($AD8="","", IF(MOD(AD8,160)=0, "TENSION (XL : / ZL : / XR : / ZR : / Y : )" & CHAR(10) & "필터교체", "-" ) ) -> - | AB8: - | AD8: 2 | AE8: =IF(AD8="","", IF(MOD($AD8,1)=0, "Dimensions: L W H", "-" ) ) -> Dimensions: L W H | AF8: =IF(AG8="","", IF(MOD($AD8,1)=0, "완료", "-" ) ) -> 완료 | AG8: 19분
A9: 45971 | B9: 누락 | C9: - | D9: - | E9: 누락 | G9: VITA | H9: MARK II | I9: 160 | K9: =IF(LEN(A9)>0, 상수!B$4, "") -> 2.26 | L9: - | M9: =IF(MOD($AD9,5)=0, "스핀들유격: ","-" ) -> - | N9: =IF(MOD($AD9,5)=0, "스핀들유격: ","-" ) -> - | O9: =IF(MOD($AD9,5)=0, "스핀들유격: ","-" ) -> - | P9: =IF(MOD($AD9,5)=0, "스핀들유격: ","-" ) -> - | Q9: =IF(MOD($AD9,5)=0, "000-000 :","-" ) -> - | R9: =IF(MOD($AD9,5)=0, "000-000 :","-" ) -> - | S9: =IF(MOD($AD9,5)=0, "000-000 :","-" ) -> - | T9: =IF(MOD($AD9,5)=0, "000-000 :","-" ) -> - | U9: =IF(MOD($AD9,5)=0, "000-000 :","-" ) -> - | V9: =IF(MOD($AD9,5)=0, "000-000 :","-" ) -> - | W9: =IF(MOD($AD9,5)=0, "000-000 :","-" ) -> - | X9: =IF(MOD($AD9,5)=0, "000-000 :","-" ) -> - | Y9: =IF(MOD($AD9,5)=0, "스핀들소음 :","-" ) -> - | Z9: =IF(MOD($AD9,40)=0, "필터세척 :"& CHAR(10) & "FLOW (T1, T4 : / T2, T3 : / T4 : )","-" ) -> - | AA9: =IF($AD9="","", IF(MOD(AD9,160)=0, "TENSION (XL : / ZL : / XR : / ZR : / Y : )" & CHAR(10) & "필터교체", "-" ) ) -> - | AB9: - | AD9: 2 | AE9: =IF(AD9="","", IF(MOD($AD9,1)=0, "Dimensions: L W H", "-" ) ) -> Dimensions: L W H | AF9: =IF(AG9="","", IF(MOD($AD9,1)=0, "완료", "-" ) ) -> 완료 | AG9: 19분
A10: 45971 | B10: 누락 | C10: - | D10: - | E10: 누락 | G10: VITA | H10: MARK II | I10: 160 | K10: =IF(LEN(A10)>0, 상수!B$4, "") -> 2.26 | L10: - | M10: =IF(MOD($AD10,5)=0, "스핀들유격: ","-" ) -> - | N10: =IF(MOD($AD10,5)=0, "스핀들유격: ","-" ) -> - | O10: =IF(MOD($AD10,5)=0, "스핀들유격: ","-" ) -> - | P10: =IF(MOD($AD10,5)=0, "스핀들유격: ","-" ) -> - | Q10: =IF(MOD($AD10,5)=0, "000-000 :","-" ) -> - | R10: =IF(MOD($AD10,5)=0, "000-000 :","-" ) -> - | S10: =IF(MOD($AD10,5)=0, "000-000 :","-" ) -> - | T10: =IF(MOD($AD10,5)=0, "000-000 :","-" ) -> - | U10: =IF(MOD($AD10,5)=0, "000-000 :","-" ) -> - | V10: =IF(MOD($AD10,5)=0, "000-000 :","-" ) -> - | W10: =IF(MOD($AD10,5)=0, "000-000 :","-" ) -> - | X10: =IF(MOD($AD10,5)=0, "000-000 :","-" ) -> - | Y10: =IF(MOD($AD10,5)=0, "스핀들소음 :","-" ) -> - | Z10: =IF(MOD($AD10,40)=0, "필터세척 :"& CHAR(10) & "FLOW (T1, T4 : / T2, T3 : / T4 : )","-" ) -> - | AA10: =IF($AD10="","", IF(MOD(AD10,160)=0, "TENSION (XL : / ZL : / XR : / ZR : / Y : )" & CHAR(10) & "필터교체", "-" ) ) -> - | AB10: - | AD10: 4 | AE10: =IF(AD10="","", IF(MOD($AD10,1)=0, "Dimensions: L W H", "-" ) ) -> Dimensions: L W H | AF10: =IF(AG10="","", IF(MOD($AD10,1)=0, "완료", "-" ) ) -> 완료 | AG10: 19분
A11: 45971 | B11: 누락 | C11: - | D11: - | E11: 누락 | G11: VITA | H11: MARK II | I11: 160 | K11: =IF(LEN(A11)>0, 상수!B$4, "") -> 2.26 | L11: - | M11: =IF(MOD($AD11,5)=0, "스핀들유격: ","-" ) -> 스핀들유격: | N11: =IF(MOD($AD11,5)=0, "스핀들유격: ","-" ) -> 스핀들유격: | O11: =IF(MOD($AD11,5)=0, "스핀들유격: ","-" ) -> 스핀들유격: | P11: =IF(MOD($AD11,5)=0, "스핀들유격: ","-" ) -> 스핀들유격: | Q11: =IF(MOD($AD11,5)=0, "000-000 :","-" ) -> 000-000 : | R11: =IF(MOD($AD11,5)=0, "000-000 :","-" ) -> 000-000 : | S11: =IF(MOD($AD11,5)=0, "000-000 :","-" ) -> 000-000 : | T11: =IF(MOD($AD11,5)=0, "000-000 :","-" ) -> 000-000 : | U11: =IF(MOD($AD11,5)=0, "000-000 :","-" ) -> 000-000 : | V11: =IF(MOD($AD11,5)=0, "000-000 :","-" ) -> 000-000 : | W11: =IF(MOD($AD11,5)=0, "000-000 :","-" ) -> 000-000 : | X11: =IF(MOD($AD11,5)=0, "000-000 :","-" ) -> 000-000 : | Y11: =IF(MOD($AD11,5)=0, "스핀들소음 :","-" ) -> 스핀들소음 : | Z11: =IF(MOD($AD11,40)=0, "필터세척 :"& CHAR(10) & "FLOW (T1, T4 : / T2, T3 : / T4 : )","-" ) -> - | AA11: =IF($AD11="","", IF(MOD(AD11,160)=0, "TENSION (XL : / ZL : / XR : / ZR : / Y : )" & CHAR(10) & "필터교체", "-" ) ) -> - | AB11: - | AD11: 5 | AE11: =IF(AD11="","", IF(MOD($AD11,1)=0, "Dimensions: L W H", "-" ) ) -> Dimensions: L W H | AF11: =IF(AG11="","", IF(MOD($AD11,1)=0, "완료", "-" ) ) -> 완료 | AG11: 19분
A12: TABLE OUTLINE | B12: TABLE OUTLINE | C12: TABLE OUTLINE | D12: TABLE OUTLINE | E12: TABLE OUTLINE | F12: TABLE OUTLINE | G12: TABLE OUTLINE | H12: TABLE OUTLINE | I12: TABLE OUTLINE | J12: TABLE OUTLINE | K12: TABLE OUTLINE | L12: TABLE OUTLINE | M12: TABLE OUTLINE | N12: TABLE OUTLINE | O12: TABLE OUTLINE | P12: TABLE OUTLINE | Q12: TABLE OUTLINE | R12: TABLE OUTLINE | S12: TABLE OUTLINE | T12: TABLE OUTLINE | U12: TABLE OUTLINE | V12: TABLE OUTLINE | W12: TABLE OUTLINE | X12: TABLE OUTLINE | Y12: TABLE OUTLINE | Z12: TABLE OUTLINE | AA12: TABLE OUTLINE | AB12: TABLE OUTLINE | AC12: TABLE OUTLINE | AD12: TABLE OUTLINE | AE12: TABLE OUTLINE | AF12: TABLE OUTLINE | AG12: TABLE OUTLINE | AH12: TABLE OUTLINE

Sheet PP#4
A1: LM-10 SPINDLE 내구도 신뢰성 시험이력
A2: 수행기간 | B2: 적용 BUR | G2: 적용 가공물 | K2: 실험상수 | L2: 사전점검(시험 전 점검항목) | AB2: 특이사항 | AD2: 산출 결과
M4: 5회 가공회차 주기 | Z4: 40회 가공회차 주기 | AA4: 160회 가공회차 주기
B5: BUR 가공누적사용횟수 | L5: 스핀들 유격 | M5: 스핀들 유격 | Q5: AG Mode Current(min-max) | U5: 35000 RPM Current(min-max) and 스핀들 소음
A6: 가공일 | B6: T1 | C6: T2 | D6: T3 | E6: T4 | F6: SPINDLE REV | G6: BLOCK 제조사 | H6: BLOCK 식별자 | I6: BLOCK 강도(MPa) | J6: BLOCK 재질 | K6: 가속 Factor | L6: WATER TANK FILTER 청결상태 | M6: T1 | N6: T2 | O6: T3 | P6: T4 | Q6: T1 | R6: T2 | S6: T3 | T6: T4 | U6: T1 | V6: T2 | W6: T3 | X6: T4 | Y6: 스핀들 소음유무 측정 | Z6: 필터세척/유량계 유량 측정 | AA6: 필터교체/BELT TENSION 측정 | AD6: 가공회차 | AE6: 산출가공물 치수 측정결과 | AF6: 시험완료여부 | AG6: 가공시간(분단위 반올림) | AH6: 비고
A7: 45971 | B7: 누락 | C7: - | D7: - | E7: 누락 | G7: VITA | H7: MARK II | I7: 160 | K7: =IF(LEN(A7)>0, 상수!B$4, "") -> 2.26 | L7: - | M7: =IF(MOD($AD7,5)=0, "스핀들유격: ","-" ) -> - | N7: =IF(MOD($AD7,5)=0, "스핀들유격: ","-" ) -> - | O7: =IF(MOD($AD7,5)=0, "스핀들유격: ","-" ) -> - | P7: =IF(MOD($AD7,5)=0, "스핀들유격: ","-" ) -> - | Q7: =IF(MOD($AD7,5)=0, "000-000 :","-" ) -> - | R7: =IF(MOD($AD7,5)=0, "000-000 :","-" ) -> - | S7: =IF(MOD($AD7,5)=0, "000-000 :","-" ) -> - | T7: =IF(MOD($AD7,5)=0, "000-000 :","-" ) -> - | U7: =IF(MOD($AD7,5)=0, "000-000 :","-" ) -> - | V7: =IF(MOD($AD7,5)=0, "000-000 :","-" ) -> - | W7: =IF(MOD($AD7,5)=0, "000-000 :","-" ) -> - | X7: =IF(MOD($AD7,5)=0, "000-000 :","-" ) -> - | Y7: =IF(MOD($AD7,5)=0, "스핀들소음 :","-" ) -> - | Z7: =IF(MOD($AD7,40)=0, "필터세척 :"& CHAR(10) & "FLOW (T1, T4 : / T2, T3 : / T4 : )","-" ) -> - | AA7: =IF($AD7="","", IF(MOD($AD7,160)=0, "TENSION (XL : / ZL : / XR : / ZR : / Y : )" & CHAR(10) & "필터교체", "-" ) ) -> - | AB7: - | AD7: 1 | AE7: =IF(AD7="","", IF(MOD($AD7,1)=0, "Dimensions: L W H", "-" ) ) -> Dimensions: L W H | AF7: =IF(AG7="","", IF(MOD($AD7,1)=0, "완료", "-" ) ) -> 완료 | AG7: 21분
A8: 45971 | B8: 누락 | C8: - | D8: - | E8: 누락 | G8: VITA | H8: MARK II | I8: 160 | K8: =IF(LEN(A8)>0, 상수!B$4, "") -> 2.26 | L8: - | M8: =IF(MOD($AD8,5)=0, "스핀들유격: ","-" ) -> - | N8: =IF(MOD($AD8,5)=0, "스핀들유격: ","-" ) -> - | O8: =IF(MOD($AD8,5)=0, "스핀들유격: ","-" ) -> - | P8: =IF(MOD($AD8,5)=0, "스핀들유격: ","-" ) -> - | Q8: =IF(MOD($AD8,5)=0, "000-000 :","-" ) -> - | R8: =IF(MOD($AD8,5)=0, "000-000 :","-" ) -> - | S8: =IF(MOD($AD8,5)=0, "000-000 :","-" ) -> - | T8: =IF(MOD($AD8,5)=0, "000-000 :","-" ) -> - | U8: =IF(MOD($AD8,5)=0, "000-000 :","-" ) -> - | V8: =IF(MOD($AD8,5)=0, "000-000 :","-" ) -> - | W8: =IF(MOD($AD8,5)=0, "000-000 :","-" ) -> - | X8: =IF(MOD($AD8,5)=0, "000-000 :","-" ) -> - | Y8: =IF(MOD($AD8,5)=0, "스핀들소음 :","-" ) -> - | Z8: =IF(MOD($AD8,40)=0, "필터세척 :"& CHAR(10) & "FLOW (T1, T4 : / T2, T3 : / T4 : )","-" ) -> - | AA8: =IF($AD8="","", IF(MOD(AD8,160)=0, "TENSION (XL : / ZL : / XR : / ZR : / Y : )" & CHAR(10) & "필터교체", "-" ) ) -> - | AB8: - | AD8: 2 | AE8: =IF(AD8="","", IF(MOD($AD8,1)=0, "Dimensions: L W H", "-" ) ) -> Dimensions: L W H | AF8: =IF(AG8="","", IF(MOD($AD8,1)=0, "완료", "-" ) ) -> 완료 | AG8: 19분
A9: 45971 | B9: 누락 | C9: - | D9: - | E9: 누락 | G9: VITA | H9: MARK II | I9: 160 | K9: =IF(LEN(A9)>0, 상수!B$4, "") -> 2.26 | L9: - | M9: =IF(MOD($AD9,5)=0, "스핀들유격: ","-" ) -> - | N9: =IF(MOD($AD9,5)=0, "스핀들유격: ","-" ) -> - | O9: =IF(MOD($AD9,5)=0, "스핀들유격: ","-" ) -> - | P9: =IF(MOD($AD9,5)=0, "스핀들유격: ","-" ) -> - | Q9: =IF(MOD($AD9,5)=0, "000-000 :","-" ) -> - | R9: =IF(MOD($AD9,5)=0, "000-000 :","-" ) -> - | S9: =IF(MOD($AD9,5)=0, "000-000 :","-" ) -> - | T9: =IF(MOD($AD9,5)=0, "000-000 :","-" ) -> - | U9: =IF(MOD($AD9,5)=0, "000-000 :","-" ) -> - | V9: =IF(MOD($AD9,5)=0, "000-000 :","-" ) -> - | W9: =IF(MOD($AD9,5)=0, "000-000 :","-" ) -> - | X9: =IF(MOD($AD9,5)=0, "000-000 :","-" ) -> - | Y9: =IF(MOD($AD9,5)=0, "스핀들소음 :","-" ) -> - | Z9: =IF(MOD($AD9,40)=0, "필터세척 :"& CHAR(10) & "FLOW (T1, T4 : / T2, T3 : / T4 : )","-" ) -> - | AA9: =IF($AD9="","", IF(MOD(AD9,160)=0, "TENSION (XL : / ZL : / XR : / ZR : / Y : )" & CHAR(10) & "필터교체", "-" ) ) -> - | AB9: - | AD9: 2 | AE9: =IF(AD9="","", IF(MOD($AD9,1)=0, "Dimensions: L W H", "-" ) ) -> Dimensions: L W H | AF9: =IF(AG9="","", IF(MOD($AD9,1)=0, "완료", "-" ) ) -> 완료 | AG9: 19분
A10: 45971 | B10: 누락 | C10: - | D10: - | E10: 누락 | G10: VITA | H10: MARK II | I10: 160 | K10: =IF(LEN(A10)>0, 상수!B$4, "") -> 2.26 | L10: - | M10: =IF(MOD($AD10,5)=0, "스핀들유격: ","-" ) -> - | N10: =IF(MOD($AD10,5)=0, "스핀들유격: ","-" ) -> - | O10: =IF(MOD($AD10,5)=0, "스핀들유격: ","-" ) -> - | P10: =IF(MOD($AD10,5)=0, "스핀들유격: ","-" ) -> - | Q10: =IF(MOD($AD10,5)=0, "000-000 :","-" ) -> - | R10: =IF(MOD($AD10,5)=0, "000-000 :","-" ) -> - | S10: =IF(MOD($AD10,5)=0, "000-000 :","-" ) -> - | T10: =IF(MOD($AD10,5)=0, "000-000 :","-" ) -> - | U10: =IF(MOD($AD10,5)=0, "000-000 :","-" ) -> - | V10: =IF(MOD($AD10,5)=0, "000-000 :","-" ) -> - | W10: =IF(MOD($AD10,5)=0, "000-000 :","-" ) -> - | X10: =IF(MOD($AD10,5)=0, "000-000 :","-" ) -> - | Y10: =IF(MOD($AD10,5)=0, "스핀들소음 :","-" ) -> - | Z10: =IF(MOD($AD10,40)=0, "필터세척 :"& CHAR(10) & "FLOW (T1, T4 : / T2, T3 : / T4 : )","-" ) -> - | AA10: =IF($AD10="","", IF(MOD(AD10,160)=0, "TENSION (XL : / ZL : / XR : / ZR : / Y : )" & CHAR(10) & "필터교체", "-" ) ) -> - | AB10: - | AD10: 4 | AE10: =IF(AD10="","", IF(MOD($AD10,1)=0, "Dimensions: L W H", "-" ) ) -> Dimensions: L W H | AF10: =IF(AG10="","", IF(MOD($AD10,1)=0, "완료", "-" ) ) -> 완료 | AG10: 19분
A11: 45971 | B11: 누락 | C11: - | D11: - | E11: 누락 | G11: VITA | H11: MARK II | I11: 160 | K11: =IF(LEN(A11)>0, 상수!B$4, "") -> 2.26 | L11: - | M11: =IF(MOD($AD11,5)=0, "스핀들유격: ","-" ) -> 스핀들유격: | N11: =IF(MOD($AD11,5)=0, "스핀들유격: ","-" ) -> 스핀들유격: | O11: =IF(MOD($AD11,5)=0, "스핀들유격: ","-" ) -> 스핀들유격: | P11: =IF(MOD($AD11,5)=0, "스핀들유격: ","-" ) -> 스핀들유격: | Q11: =IF(MOD($AD11,5)=0, "000-000 :","-" ) -> 000-000 : | R11: =IF(MOD($AD11,5)=0, "000-000 :","-" ) -> 000-000 : | S11: =IF(MOD($AD11,5)=0, "000-000 :","-" ) -> 000-000 : | T11: =IF(MOD($AD11,5)=0, "000-000 :","-" ) -> 000-000 : | U11: =IF(MOD($AD11,5)=0, "000-000 :","-" ) -> 000-000 : | V11: =IF(MOD($AD11,5)=0, "000-000 :","-" ) -> 000-000 : | W11: =IF(MOD($AD11,5)=0, "000-000 :","-" ) -> 000-000 : | X11: =IF(MOD($AD11,5)=0, "000-000 :","-" ) -> 000-000 : | Y11: =IF(MOD($AD11,5)=0, "스핀들소음 :","-" ) -> 스핀들소음 : | Z11: =IF(MOD($AD11,40)=0, "필터세척 :"& CHAR(10) & "FLOW (T1, T4 : / T2, T3 : / T4 : )","-" ) -> - | AA11: =IF($AD11="","", IF(MOD(AD11,160)=0, "TENSION (XL : / ZL : / XR : / ZR : / Y : )" & CHAR(10) & "필터교체", "-" ) ) -> - | AB11: - | AD11: 5 | AE11: =IF(AD11="","", IF(MOD($AD11,1)=0, "Dimensions: L W H", "-" ) ) -> Dimensions: L W H | AF11: =IF(AG11="","", IF(MOD($AD11,1)=0, "완료", "-" ) ) -> 완료 | AG11: 19분
A12: TABLE OUTLINE | B12: TABLE OUTLINE | C12: TABLE OUTLINE | D12: TABLE OUTLINE | E12: TABLE OUTLINE | F12: TABLE OUTLINE | G12: TABLE OUTLINE | H12: TABLE OUTLINE | I12: TABLE OUTLINE | J12: TABLE OUTLINE | K12: TABLE OUTLINE | L12: TABLE OUTLINE | M12: TABLE OUTLINE | N12: TABLE OUTLINE | O12: TABLE OUTLINE | P12: TABLE OUTLINE | Q12: TABLE OUTLINE | R12: TABLE OUTLINE | S12: TABLE OUTLINE | T12: TABLE OUTLINE | U12: TABLE OUTLINE | V12: TABLE OUTLINE | W12: TABLE OUTLINE | X12: TABLE OUTLINE | Y12: TABLE OUTLINE | Z12: TABLE OUTLINE | AA12: TABLE OUTLINE | AB12: TABLE OUTLINE | AC12: TABLE OUTLINE | AD12: TABLE OUTLINE | AE12: TABLE OUTLINE | AF12: TABLE OUTLINE | AG12: TABLE OUTLINE | AH12: TABLE OUTLINE

Sheet PP#5
A1: LM-10 SPINDLE 내구도 신뢰성 시험이력
A2: 수행기간 | B2: 적용 BUR | G2: 적용 가공물 | K2: 실험상수 | L2: 사전점검(시험 전 점검항목) | AB2: 특이사항 | AD2: 산출 결과
M4: 5회 가공회차 주기 | Z4: 40회 가공회차 주기 | AA4: 160회 가공회차 주기
B5: BUR 가공누적사용횟수 | L5: 스핀들 유격 | M5: 스핀들 유격 | Q5: AG Mode Current(min-max) | U5: 35000 RPM Current(min-max) and 스핀들 소음
A6: 가공일 | B6: T1 | C6: T2 | D6: T3 | E6: T4 | F6: SPINDLE REV | G6: BLOCK 제조사 | H6: BLOCK 식별자 | I6: BLOCK 강도(MPa) | J6: BLOCK 재질 | K6: 가속 Factor | L6: WATER TANK FILTER 청결상태 | M6: T1 | N6: T2 | O6: T3 | P6: T4 | Q6: T1 | R6: T2 | S6: T3 | T6: T4 | U6: T1 | V6: T2 | W6: T3 | X6: T4 | Y6: 스핀들 소음유무 측정 | Z6: 필터세척/유량계 유량 측정 | AA6: 필터교체/BELT TENSION 측정 | AD6: 가공회차 | AE6: 산출가공물 치수 측정결과 | AF6: 시험완료여부 | AG6: 가공시간(분단위 반올림) | AH6: 비고
A7: 45971 | B7: 누락 | C7: - | D7: - | E7: 누락 | G7: VITA | H7: MARK II | I7: 160 | K7: =IF(LEN(A7)>0, 상수!B$4, "") -> 2.26 | L7: - | M7: =IF(MOD($AD7,5)=0, "스핀들유격: ","-" ) -> - | N7: =IF(MOD($AD7,5)=0, "스핀들유격: ","-" ) -> - | O7: =IF(MOD($AD7,5)=0, "스핀들유격: ","-" ) -> - | P7: =IF(MOD($AD7,5)=0, "스핀들유격: ","-" ) -> - | Q7: =IF(MOD($AD7,5)=0, "000-000 :","-" ) -> - | R7: =IF(MOD($AD7,5)=0, "000-000 :","-" ) -> - | S7: =IF(MOD($AD7,5)=0, "000-000 :","-" ) -> - | T7: =IF(MOD($AD7,5)=0, "000-000 :","-" ) -> - | U7: =IF(MOD($AD7,5)=0, "000-000 :","-" ) -> - | V7: =IF(MOD($AD7,5)=0, "000-000 :","-" ) -> - | W7: =IF(MOD($AD7,5)=0, "000-000 :","-" ) -> - | X7: =IF(MOD($AD7,5)=0, "000-000 :","-" ) -> - | Y7: =IF(MOD($AD7,5)=0, "스핀들소음 :","-" ) -> - | Z7: =IF(MOD($AD7,40)=0, "필터세척 :"& CHAR(10) & "FLOW (T1, T4 : / T2, T3 : / T4 : )","-" ) -> - | AA7: =IF($AD7="","", IF(MOD($AD7,160)=0, "TENSION (XL : / ZL : / XR : / ZR : / Y : )" & CHAR(10) & "필터교체", "-" ) ) -> - | AB7: - | AD7: 1 | AE7: =IF(AD7="","", IF(MOD($AD7,1)=0, "Dimensions: L W H", "-" ) ) -> Dimensions: L W H | AF7: =IF(AG7="","", IF(MOD($AD7,1)=0, "완료", "-" ) ) -> 완료 | AG7: 21분
A8: 45971 | B8: 누락 | C8: - | D8: - | E8: 누락 | G8: VITA | H8: MARK II | I8: 160 | K8: =IF(LEN(A8)>0, 상수!B$4, "") -> 2.26 | L8: - | M8: =IF(MOD($AD8,5)=0, "스핀들유격: ","-" ) -> - | N8: =IF(MOD($AD8,5)=0, "스핀들유격: ","-" ) -> - | O8: =IF(MOD($AD8,5)=0, "스핀들유격: ","-" ) -> - | P8: =IF(MOD($AD8,5)=0, "스핀들유격: ","-" ) -> - | Q8: =IF(MOD($AD8,5)=0, "000-000 :","-" ) -> - | R8: =IF(MOD($AD8,5)=0, "000-000 :","-" ) -> - | S8: =IF(MOD($AD8,5)=0, "000-000 :","-" ) -> - | T8: =IF(MOD($AD8,5)=0, "000-000 :","-" ) -> - | U8: =IF(MOD($AD8,5)=0, "000-000 :","-" ) -> - | V8: =IF(MOD($AD8,5)=0, "000-000 :","-" ) -> - | W8: =IF(MOD($AD8,5)=0, "000-000 :","-" ) -> - | X8: =IF(MOD($AD8,5)=0, "000-000 :","-" ) -> - | Y8: =IF(MOD($AD8,5)=0, "스핀들소음 :","-" ) -> - | Z8: =IF(MOD($AD8,40)=0, "필터세척 :"& CHAR(10) & "FLOW (T1, T4 : / T2, T3 : / T4 : )","-" ) -> - | AA8: =IF($AD8="","", IF(MOD(AD8,160)=0, "TENSION (XL : / ZL : / XR : / ZR : / Y : )" & CHAR(10) & "필터교체", "-" ) ) -> - | AB8: - | AD8: 2 | AE8: =IF(AD8="","", IF(MOD($AD8,1)=0, "Dimensions: L W H", "-" ) ) -> Dimensions: L W H | AF8: =IF(AG8="","", IF(MOD($AD8,1)=0, "완료", "-" ) ) -> 완료 | AG8: 19분
A9: 45971 | B9: 누락 | C9: - | D9: - | E9: 누락 | G9: VITA | H9: MARK II | I9: 160 | K9: =IF(LEN(A9)>0, 상수!B$4, "") -> 2.26 | L9: - | M9: =IF(MOD($AD9,5)=0, "스핀들유격: ","-" ) -> - | N9: =IF(MOD($AD9,5)=0, "스핀들유격: ","-" ) -> - | O9: =IF(MOD($AD9,5)=0, "스핀들유격: ","-" ) -> - | P9: =IF(MOD($AD9,5)=0, "스핀들유격: ","-" ) -> - | Q9: =IF(MOD($AD9,5)=0, "000-000 :","-" ) -> - | R9: =IF(MOD($AD9,5)=0, "000-000 :","-" ) -> - | S9: =IF(MOD($AD9,5)=0, "000-000 :","-" ) -> - | T9: =IF(MOD($AD9,5)=0, "000-000 :","-" ) -> - | U9: =IF(MOD($AD9,5)=0, "000-000 :","-" ) -> - | V9: =IF(MOD($AD9,5)=0, "000-000 :","-" ) -> - | W9: =IF(MOD($AD9,5)=0, "000-000 :","-" ) -> - | X9: =IF(MOD($AD9,5)=0, "000-000 :","-" ) -> - | Y9: =IF(MOD($AD9,5)=0, "스핀들소음 :","-" ) -> - | Z9: =IF(MOD($AD9,40)=0, "필터세척 :"& CHAR(10) & "FLOW (T1, T4 : / T2, T3 : / T4 : )","-" ) -> - | AA9: =IF($AD9="","", IF(MOD(AD9,160)=0, "TENSION (XL : / ZL : / XR : / ZR : / Y : )" & CHAR(10) & "필터교체", "-" ) ) -> - | AB9: - | AD9: 2 | AE9: =IF(AD9="","", IF(MOD($AD9,1)=0, "Dimensions: L W H", "-" ) ) -> Dimensions: L W H | AF9: =IF(AG9="","", IF(MOD($AD9,1)=0, "완료", "-" ) ) -> 완료 | AG9: 19분
A10: 45971 | B10: 누락 | C10: - | D10: - | E10: 누락 | G10: VITA | H10: MARK II | I10: 160 | K10: =IF(LEN(A10)>0, 상수!B$4, "") -> 2.26 | L10: - | M10: =IF(MOD($AD10,5)=0, "스핀들유격: ","-" ) -> - | N10: =IF(MOD($AD10,5)=0, "스핀들유격: ","-" ) -> - | O10: =IF(MOD($AD10,5)=0, "스핀들유격: ","-" ) -> - | P10: =IF(MOD($AD10,5)=0, "스핀들유격: ","-" ) -> - | Q10: =IF(MOD($AD10,5)=0, "000-000 :","-" ) -> - | R10: =IF(MOD($AD10,5)=0, "000-000 :","-" ) -> - | S10: =IF(MOD($AD10,5)=0, "000-000 :","-" ) -> - | T10: =IF(MOD($AD10,5)=0, "000-000 :","-" ) -> - | U10: =IF(MOD($AD10,5)=0, "000-000 :","-" ) -> - | V10: =IF(MOD($AD10,5)=0, "000-000 :","-" ) -> - | W10: =IF(MOD($AD10,5)=0, "000-000 :","-" ) -> - | X10: =IF(MOD($AD10,5)=0, "000-000 :","-" ) -> - | Y10: =IF(MOD($AD10,5)=0, "스핀들소음 :","-" ) -> - | Z10: =IF(MOD($AD10,40)=0, "필터세척 :"& CHAR(10) & "FLOW (T1, T4 : / T2, T3 : / T4 : )","-" ) -> - | AA10: =IF($AD10="","", IF(MOD(AD10,160)=0, "TENSION (XL : / ZL : / XR : / ZR : / Y : )" & CHAR(10) & "필터교체", "-" ) ) -> - | AB10: - | AD10: 4 | AE10: =IF(AD10="","", IF(MOD($AD10,1)=0, "Dimensions: L W H", "-" ) ) -> Dimensions: L W H | AF10: =IF(AG10="","", IF(MOD($AD10,1)=0, "완료", "-" ) ) -> 완료 | AG10: 19분
A11: 45971 | B11: 누락 | C11: - | D11: - | E11: 누락 | G11: VITA | H11: MARK II | I11: 160 | K11: =IF(LEN(A11)>0, 상수!B$4, "") -> 2.26 | L11: - | M11: =IF(MOD($AD11,5)=0, "스핀들유격: ","-" ) -> 스핀들유격: | N11: =IF(MOD($AD11,5)=0, "스핀들유격: ","-" ) -> 스핀들유격: | O11: =IF(MOD($AD11,5)=0, "스핀들유격: ","-" ) -> 스핀들유격: | P11: =IF(MOD($AD11,5)=0, "스핀들유격: ","-" ) -> 스핀들유격: | Q11: =IF(MOD($AD11,5)=0, "000-000 :","-" ) -> 000-000 : | R11: =IF(MOD($AD11,5)=0, "000-000 :","-" ) -> 000-000 : | S11: =IF(MOD($AD11,5)=0, "000-000 :","-" ) -> 000-000 : | T11: =IF(MOD($AD11,5)=0, "000-000 :","-" ) -> 000-000 : | U11: =IF(MOD($AD11,5)=0, "000-000 :","-" ) -> 000-000 : | V11: =IF(MOD($AD11,5)=0, "000-000 :","-" ) -> 000-000 : | W11: =IF(MOD($AD11,5)=0, "000-000 :","-" ) -> 000-000 : | X11: =IF(MOD($AD11,5)=0, "000-000 :","-" ) -> 000-000 : | Y11: =IF(MOD($AD11,5)=0, "스핀들소음 :","-" ) -> 스핀들소음 : | Z11: =IF(MOD($AD11,40)=0, "필터세척 :"& CHAR(10) & "FLOW (T1, T4 : / T2, T3 : / T4 : )","-" ) -> - | AA11: =IF($AD11="","", IF(MOD(AD11,160)=0, "TENSION (XL : / ZL : / XR : / ZR : / Y : )" & CHAR(10) & "필터교체", "-" ) ) -> - | AB11: - | AD11: 5 | AE11: =IF(AD11="","", IF(MOD($AD11,1)=0, "Dimensions: L W H", "-" ) ) -> Dimensions: L W H | AF11: =IF(AG11="","", IF(MOD($AD11,1)=0, "완료", "-" ) ) -> 완료 | AG11: 19분
A12: TABLE OUTLINE | B12: TABLE OUTLINE | C12: TABLE OUTLINE | D12: TABLE OUTLINE | E12: TABLE OUTLINE | F12: TABLE OUTLINE | G12: TABLE OUTLINE | H12: TABLE OUTLINE | I12: TABLE OUTLINE | J12: TABLE OUTLINE | K12: TABLE OUTLINE | L12: TABLE OUTLINE | M12: TABLE OUTLINE | N12: TABLE OUTLINE | O12: TABLE OUTLINE | P12: TABLE OUTLINE | Q12: TABLE OUTLINE | R12: TABLE OUTLINE | S12: TABLE OUTLINE | T12: TABLE OUTLINE | U12: TABLE OUTLINE | V12: TABLE OUTLINE | W12: TABLE OUTLINE | X12: TABLE OUTLINE | Y12: TABLE OUTLINE | Z12: TABLE OUTLINE | AA12: TABLE OUTLINE | AB12: TABLE OUTLINE | AC12: TABLE OUTLINE | AD12: TABLE OUTLINE | AE12: TABLE OUTLINE | AF12: TABLE OUTLINE | AG12: TABLE OUTLINE | AH12: TABLE OUTLINE

Sheet 상수
A1: 실험가정 | E1: 기대
A2: 고정상수 | E2: BUR 기대수명
A3: 권장 버교체 주기 | B3: 가속 Factor
A4: 버교체/15가공 | B4: 2.26

Sheet 작성 EX
A1: LM-10 SPINDLE 내구도 신뢰성 시험이력
A2: 수행기간 | B2: 적용 BUR | G2: 적용 가공물 | K2: 실험상수 | L2: 사전점검(시험 전 점검항목) | AB2: 특이사항 | AD2: 산출 결과
M4: 5회 가공회차 주기 | Z4: 40회 가공회차 주기 | AA4: 160회 가공회차 주기
B5: BUR 가공누적사용횟수 | L5: 스핀들 유격 | M5: 스핀들 유격 | Q5: AG Mode Current(min-max) | U5: 35000 RPM Current(min-max) and 스핀들 소음
A6: 가공일 | B6: T1 | C6: T2 | D6: T3 | E6: T4 | F6: SPINDLE REV | G6: BLOCK 제조사 | H6: BLOCK 식별자 | I6: BLOCK 강도(MPa) | J6: BLOCK 재질 | K6: 가속 Factor | L6: WATER TANK FILTER 청결상태 | M6: T1 | N6: T2 | O6: T3 | P6: T4 | Q6: T1 | R6: T2 | S6: T3 | T6: T4 | U6: T1 | V6: T2 | W6: T3 | X6: T4 | Y6: 스핀들 소음유무 측정 | Z6: 필터세척/유량계 유량 측정 | AA6: 필터교체/BELT TENSION 측정 | AD6: 가공회차 | AE6: 산출가공물 치수 측정결과 | AF6: 시험완료여부 | AG6: 가공시간(분단위 반올림) | AH6: 비고
A7: 45971 | B7: 0 | C7: - | D7: - | E7: 0 | G7: VITA | H7: MARK II | I7: 160 | K7: =IF(LEN(A7)>0, 상수!B$4, "") -> 2.26 | L7: - | M7: =IF(MOD($AD7,5)=0, "스핀들유격: ","-" ) -> - | N7: =IF(MOD($AD7,5)=0, "스핀들유격: ","-" ) -> - | O7: =IF(MOD($AD7,5)=0, "스핀들유격: ","-" ) -> - | P7: =IF(MOD($AD7,5)=0, "스핀들유격: ","-" ) -> - | Q7: =IF(MOD($AD7,5)=0, "000-000 :","-" ) -> - | R7: =IF(MOD($AD7,5)=0, "000-000 :","-" ) -> - | S7: =IF(MOD($AD7,5)=0, "000-000 :","-" ) -> - | T7: =IF(MOD($AD7,5)=0, "000-000 :","-" ) -> - | U7: =IF(MOD($AD7,5)=0, "000-000 :","-" ) -> - | V7: =IF(MOD($AD7,5)=0, "000-000 :","-" ) -> - | W7: =IF(MOD($AD7,5)=0, "000-000 :","-" ) -> - | X7: =IF(MOD($AD7,5)=0, "000-000 :","-" ) -> - | Y7: =IF(MOD($AD7,5)=0, "스핀들소음 :","-" ) -> - | Z7: =IF(MOD($AD7,40)=0, "필터세척 :"& CHAR(10) & "FLOW (T1, T4 : / T2, T3 : / T4 : )","-" ) -> - | AA7: =IF($AD7="","", IF(MOD($AD7,160)=0, "TENSION (XL : / ZL : / XR : / ZR : / Y : )" & CHAR(10) & "필터교체", "-" ) ) -> - | AB7: - | AC7: 조치: BUR 장착 → 시험진행 | AD7: 1 | AE7: =IF(AD7="","", IF(MOD($AD7,1)=0, "Dimensions: L W H", "-" ) ) -> Dimensions: L W H | AF7: =IF(AG7="","", IF(MOD($AD7,1)=0, "완료", "-" ) ) -> 완료 | AG7: 21분
K8: =IF(LEN(A8)>0, 상수!B$4, "") | L8: - | M8: =IF(MOD($AD8,5)=0, "스핀들유격: ","-" ) -> - | N8: =IF(MOD($AD8,5)=0, "스핀들유격: ","-" ) -> - | O8: =IF(MOD($AD8,5)=0, "스핀들유격: ","-" ) -> - | P8: =IF(MOD($AD8,5)=0, "스핀들유격: ","-" ) -> - | Q8: =IF(MOD($AD8,5)=0, "000-000 :","-" ) -> - | R8: =IF(MOD($AD8,5)=0, "000-000 :","-" ) -> - | S8: =IF(MOD($AD8,5)=0, "000-000 :","-" ) -> - | T8: =IF(MOD($AD8,5)=0, "000-000 :","-" ) -> - | U8: =IF(MOD($AD8,5)=0, "000-000 :","-" ) -> - | V8: =IF(MOD($AD8,5)=0, "000-000 :","-" ) -> - | W8: =IF(MOD($AD8,5)=0, "000-000 :","-" ) -> - | X8: =IF(MOD($AD8,5)=0, "000-000 :","-" ) -> - | Y8: =IF(MOD($AD8,5)=0, "스핀들소음 :","-" ) -> - | Z8: =IF(MOD($AD8,40)=0, "필터세척 :"& CHAR(10) & "FLOW (T1, T4 : / T2, T3 : / T4 : )","-" ) -> - | AA8: =IF($AD8="","", IF(MOD(AD8,160)=0, "TENSION (XL : / ZL : / XR : / ZR : / Y : )" & CHAR(10) & "필터교체", "-" ) ) -> - | AB8: - | AC8: BUR 교체 → 시험진행 | AD8: 2 | AE8: =IF(AD8="","", IF(MOD($AD8,1)=0, "Dimensions: L W H", "-" ) ) -> Dimensions: L W H | AF8: =IF(AG8="","", IF(MOD($AD8,1)=0, "완료", "-" ) ) -> 완료 | AG8: 19분
K9: =IF(LEN(A9)>0, 상수!B$4, "") | L9: - | M9: =IF(MOD($AD9,5)=0, "스핀들유격: ","-" ) -> - | N9: =IF(MOD($AD9,5)=0, "스핀들유격: ","-" ) -> - | O9: =IF(MOD($AD9,5)=0, "스핀들유격: ","-" ) -> - | P9: =IF(MOD($AD9,5)=0, "스핀들유격: ","-" ) -> - | Q9: =IF(MOD($AD9,5)=0, "000-000 :","-" ) -> - | R9: =IF(MOD($AD9,5)=0, "000-000 :","-" ) -> - | S9: =IF(MOD($AD9,5)=0, "000-000 :","-" ) -> - | T9: =IF(MOD($AD9,5)=0, "000-000 :","-" ) -> - | U9: =IF(MOD($AD9,5)=0, "000-000 :","-" ) -> - | V9: =IF(MOD($AD9,5)=0, "000-000 :","-" ) -> - | W9: =IF(MOD($AD9,5)=0, "000-000 :","-" ) -> - | X9: =IF(MOD($AD9,5)=0, "000-000 :","-" ) -> - | Y9: =IF(MOD($AD9,5)=0, "스핀들소음 :","-" ) -> - | Z9: =IF(MOD($AD9,40)=0, "필터세척 :"& CHAR(10) & "FLOW (T1, T4 : / T2, T3 : / T4 : )","-" ) -> - | AA9: =IF($AD9="","", IF(MOD(AD9,160)=0, "TENSION (XL : / ZL : / XR : / ZR : / Y : )" & CHAR(10) & "필터교체", "-" ) ) -> - | AB9: - | AC9: BUR 교체 → 시험진행 | AD9: 3 | AE9: =IF(AD9="","", IF(MOD($AD9,1)=0, "Dimensions: L W H", "-" ) ) -> Dimensions: L W H | AF9: =IF(AG9="","", IF(MOD($AD9,1)=0, "완료", "-" ) ) -> 완료 | AG9: 19분
K10: =IF(LEN(A10)>0, 상수!B$4, "") | L10: - | M10: =IF(MOD($AD10,5)=0, "스핀들유격: ","-" ) -> 스핀들유격: | N10: =IF(MOD($AD10,5)=0, "스핀들유격: ","-" ) -> 스핀들유격: | O10: =IF(MOD($AD10,5)=0, "스핀들유격: ","-" ) -> 스핀들유격: | P10: =IF(MOD($AD10,5)=0, "스핀들유격: ","-" ) -> 스핀들유격: | Q10: =IF(MOD($AD10,5)=0, "000-000 :","-" ) -> 000-000 : | R10: =IF(MOD($AD10,5)=0, "000-000 :","-" ) -> 000-000 : | S10: =IF(MOD($AD10,5)=0, "000-000 :","-" ) -> 000-000 : | T10: =IF(MOD($AD10,5)=0, "000-000 :","-" ) -> 000-000 : | U10: =IF(MOD($AD10,5)=0, "000-000 :","-" ) -> 000-000 : | V10: =IF(MOD($AD10,5)=0, "000-000 :","-" ) -> 000-000 : | W10: =IF(MOD($AD10,5)=0, "000-000 :","-" ) -> 000-000 : | X10: =IF(MOD($AD10,5)=0, "000-000 :","-" ) -> 000-000 : | Y10: =IF(MOD($AD10,5)=0, "스핀들소음 :","-" ) -> 스핀들소음 : | Z10: =IF(MOD($AD10,40)=0, "필터세척 :"& CHAR(10) & "FLOW (T1, T4 : / T2, T3 : / T4 : )","-" ) -> 필터세척 : FLOW (T1, T4 : / T2, T3 : / T4 : ) | AA10: =IF($AD10="","", IF(MOD(AD10,160)=0, "TENSION (XL : / ZL : / XR : / ZR : / Y : )" & CHAR(10) & "필터교체", "-" ) ) | AB10: 시험 전 T1, T4 BUR 파손발견 | AC10: BUR 교체 : T1(중고), T4(중고) | AE10: =IF(AD10="","", IF(MOD($AD10,1)=0, "Dimensions: L W H", "-" ) ) | AF10: =IF(AG10="","", IF(MOD($AD10,1)=0, "완료", "-" ) ) -> 완료 | AG10: 19분
K11: =IF(LEN(A11)>0, 상수!B$4, "") | L11: - | M11: =IF(MOD($AD11,5)=0, "스핀들유격: ","-" ) -> 스핀들유격: | N11: =IF(MOD($AD11,5)=0, "스핀들유격: ","-" ) -> 스핀들유격: | O11: =IF(MOD($AD11,5)=0, "스핀들유격: ","-" ) -> 스핀들유격: | P11: =IF(MOD($AD11,5)=0, "스핀들유격: ","-" ) -> 스핀들유격: | Q11: =IF(MOD($AD11,5)=0, "000-000 :","-" ) -> 000-000 : | R11: =IF(MOD($AD11,5)=0, "000-000 :","-" ) -> 000-000 : | S11: =IF(MOD($AD11,5)=0, "000-000 :","-" ) -> 000-000 : | T11: =IF(MOD($AD11,5)=0, "000-000 :","-" ) -> 000-000 : | U11: =IF(MOD($AD11,5)=0, "000-000 :","-" ) -> 000-000 : | V11: =IF(MOD($AD11,5)=0, "000-000 :","-" ) -> 000-000 : | W11: =IF(MOD($AD11,5)=0, "000-000 :","-" ) -> 000-000 : | X11: =IF(MOD($AD11,5)=0, "000-000 :","-" ) -> 000-000 : | Y11: =IF(MOD($AD11,5)=0, "스핀들소음 :","-" ) -> 스핀들소음 : | Z11: =IF(MOD($AD11,40)=0, "필터세척 :"& CHAR(10) & "FLOW (T1, T4 : / T2, T3 : / T4 : )","-" ) -> 필터세척 : FLOW (T1, T4 : / T2, T3 : / T4 : ) | AA11: =IF($AD11="","", IF(MOD(AD11,160)=0, "TENSION (XL : / ZL : / XR : / ZR : / Y : )" & CHAR(10) & "필터교체", "-" ) ) | AB11: - | AC11: - | AE11: =IF(AD11="","", IF(MOD($AD11,1)=0, "Dimensions: L W H", "-" ) ) | AF11: =IF(AG11="","", IF(MOD($AD11,1)=0, "완료", "-" ) )
K12: =IF(LEN(A12)>0, 상수!B$4, "") | L12: - | M12: =IF(MOD($AD12,5)=0, "스핀들유격: ","-" ) -> 스핀들유격: | N12: =IF(MOD($AD12,5)=0, "스핀들유격: ","-" ) -> 스핀들유격: | O12: =IF(MOD($AD12,5)=0, "스핀들유격: ","-" ) -> 스핀들유격: | P12: =IF(MOD($AD12,5)=0, "스핀들유격: ","-" ) -> 스핀들유격: | Q12: =IF(MOD($AD12,5)=0, "000-000 :","-" ) -> 000-000 : | R12: =IF(MOD($AD12,5)=0, "000-000 :","-" ) -> 000-000 : | S12: =IF(MOD($AD12,5)=0, "000-000 :","-" ) -> 000-000 : | T12: =IF(MOD($AD12,5)=0, "000-000 :","-" ) -> 000-000 : | U12: =IF(MOD($AD12,5)=0, "000-000 :","-" ) -> 000-000 : | V12: =IF(MOD($AD12,5)=0, "000-000 :","-" ) -> 000-000 : | W12: =IF(MOD($AD12,5)=0, "000-000 :","-" ) -> 000-000 : | X12: =IF(MOD($AD12,5)=0, "000-000 :","-" ) -> 000-000 : | Y12: =IF(MOD($AD12,5)=0, "스핀들소음 :","-" ) -> 스핀들소음 : | Z12: =IF(MOD($AD12,40)=0, "필터세척 :"& CHAR(10) & "FLOW (T1, T4 : / T2, T3 : / T4 : )","-" ) -> 필터세척 : FLOW (T1, T4 : / T2, T3 : / T4 : ) | AA12: =IF($AD12="","", IF(MOD(AD12,160)=0, "TENSION (XL : / ZL : / XR : / ZR : / Y : )" & CHAR(10) & "필터교체", "-" ) ) | AB12: - | AC12: - | AE12: =IF(AD12="","", IF(MOD($AD12,1)=0, "Dimensions: L W H", "-" ) ) | AF12: =IF(AG12="","", IF(MOD($AD12,1)=0, "완료", "-" ) )
K13: =IF(LEN(A13)>0, 상수!B$4, "") | M13: =IF(MOD($AD13,5)=0, "스핀들유격: ","-" ) -> 스핀들유격: | N13: =IF(MOD($AD13,5)=0, "스핀들유격: ","-" ) -> 스핀들유격: | O13: =IF(MOD($AD13,5)=0, "스핀들유격: ","-" ) -> 스핀들유격: | P13: =IF(MOD($AD13,5)=0, "스핀들유격: ","-" ) -> 스핀들유격: | Q13: =IF(MOD($AD13,5)=0, "000-000 :","-" ) -> 000-000 : | R13: =IF(MOD($AD13,5)=0, "000-000 :","-" ) -> 000-000 : | S13: =IF(MOD($AD13,5)=0, "000-000 :","-" ) -> 000-000 : | T13: =IF(MOD($AD13,5)=0, "000-000 :","-" ) -> 000-000 : | U13: =IF(MOD($AD13,5)=0, "000-000 :","-" ) -> 000-000 : | V13: =IF(MOD($AD13,5)=0, "000-000 :","-" ) -> 000-000 : | W13: =IF(MOD($AD13,5)=0, "000-000 :","-" ) -> 000-000 : | X13: =IF(MOD($AD13,5)=0, "000-000 :","-" ) -> 000-000 : | Y13: =IF(MOD($AD13,5)=0, "스핀들소음 :","-" ) -> 스핀들소음 : | Z13: =IF(MOD($AD13,40)=0, "필터세척 :"& CHAR(10) & "FLOW (T1, T4 : / T2, T3 : / T4 : )","-" ) -> 필터세척 : FLOW (T1, T4 : / T2, T3 : / T4 : ) | AA13: =IF($AD13="","", IF(MOD(AD13,160)=0, "TENSION (XL : / ZL : / XR : / ZR : / Y : )" & CHAR(10) & "필터교체", "-" ) ) | AB13: - | AC13: - | AE13: =IF(AD13="","", IF(MOD($AD13,1)=0, "Dimensions: L W H", "-" ) ) | AF13: =IF(AG13="","", IF(MOD($AD13,1)=0, "완료", "-" ) )
K14: =IF(LEN(A14)>0, 상수!B$4, "") | M14: =IF(MOD($AD14,5)=0, "스핀들유격: ","-" ) -> 스핀들유격: | N14: =IF(MOD($AD14,5)=0, "스핀들유격: ","-" ) -> 스핀들유격: | O14: =IF(MOD($AD14,5)=0, "스핀들유격: ","-" ) -> 스핀들유격: | P14: =IF(MOD($AD14,5)=0, "스핀들유격: ","-" ) -> 스핀들유격: | Q14: =IF(MOD($AD14,5)=0, "000-000 :","-" ) -> 000-000 : | R14: =IF(MOD($AD14,5)=0, "000-000 :","-" ) -> 000-000 : | S14: =IF(MOD($AD14,5)=0, "000-000 :","-" ) -> 000-000 : | T14: =IF(MOD($AD14,5)=0, "000-000 :","-" ) -> 000-000 : | U14: =IF(MOD($AD14,5)=0, "000-000 :","-" ) -> 000-000 : | V14: =IF(MOD($AD14,5)=0, "000-000 :","-" ) -> 000-000 : | W14: =IF(MOD($AD14,5)=0, "000-000 :","-" ) -> 000-000 : | X14: =IF(MOD($AD14,5)=0, "000-000 :","-" ) -> 000-000 : | Y14: =IF(MOD($AD14,5)=0, "스핀들소음 :","-" ) -> 스핀들소음 : | Z14: =IF(MOD($AD14,40)=0, "필터세척 :"& CHAR(10) & "FLOW (T1, T4 : / T2, T3 : / T4 : )","-" ) -> 필터세척 : FLOW (T1, T4 : / T2, T3 : / T4 : ) | AA14: =IF($AD14="","", IF(MOD(AD14,160)=0, "TENSION (XL : / ZL : / XR : / ZR : / Y : )" & CHAR(10) & "필터교체", "-" ) ) | AB14: - | AC14: - | AE14: =IF(AD14="","", IF(MOD($AD14,1)=0, "Dimensions: L W H", "-" ) ) | AF14: =IF(AG14="","", IF(MOD($AD14,1)=0, "완료", "-" ) )
K15: =IF(LEN(A15)>0, 상수!B$4, "") | M15: =IF(MOD($AD15,5)=0, "스핀들유격: ","-" ) -> 스핀들유격: | N15: =IF(MOD($AD15,5)=0, "스핀들유격: ","-" ) -> 스핀들유격: | O15: =IF(MOD($AD15,5)=0, "스핀들유격: ","-" ) -> 스핀들유격: | P15: =IF(MOD($AD15,5)=0, "스핀들유격: ","-" ) -> 스핀들유격: | Q15: =IF(MOD($AD15,5)=0, "000-000 :","-" ) -> 000-000 : | R15: =IF(MOD($AD15,5)=0, "000-000 :","-" ) -> 000-000 : | S15: =IF(MOD($AD15,5)=0, "000-000 :","-" ) -> 000-000 : | T15: =IF(MOD($AD15,5)=0, "000-000 :","-" ) -> 000-000 : | U15: =IF(MOD($AD15,5)=0, "000-000 :","-" ) -> 000-000 : | V15: =IF(MOD($AD15,5)=0, "000-000 :","-" ) -> 000-000 : | W15: =IF(MOD($AD15,5)=0, "000-000 :","-" ) -> 000-000 : | X15: =IF(MOD($AD15,5)=0, "000-000 :","-" ) -> 000-000 : | Y15: =IF(MOD($AD15,5)=0, "스핀들소음 :","-" ) -> 스핀들소음 : | Z15: =IF(MOD($AD15,40)=0, "필터세척 :"& CHAR(10) & "FLOW (T1, T4 : / T2, T3 : / T4 : )","-" ) -> 필터세척 : FLOW (T1, T4 : / T2, T3 : / T4 : ) | AA15: =IF($AD15="","", IF(MOD(AD15,160)=0, "TENSION (XL : / ZL : / XR : / ZR : / Y : )" & CHAR(10) & "필터교체", "-" ) ) | AB15: - | AC15: - | AE15: =IF(AD15="","", IF(MOD($AD15,1)=0, "Dimensions: L W H", "-" ) ) | AF15: =IF(AG15="","", IF(MOD($AD15,1)=0, "완료", "-" ) )
K16: =IF(LEN(A16)>0, 상수!B$4, "") | M16: =IF(MOD($AD16,5)=0, "스핀들유격: ","-" ) -> 스핀들유격: | N16: =IF(MOD($AD16,5)=0, "스핀들유격: ","-" ) -> 스핀들유격: | O16: =IF(MOD($AD16,5)=0, "스핀들유격: ","-" ) -> 스핀들유격: | P16: =IF(MOD($AD16,5)=0, "스핀들유격: ","-" ) -> 스핀들유격: | Q16: =IF(MOD($AD16,5)=0, "000-000 :","-" ) -> 000-000 : | R16: =IF(MOD($AD16,5)=0, "000-000 :","-" ) -> 000-000 : | S16: =IF(MOD($AD16,5)=0, "000-000 :","-" ) -> 000-000 : | T16: =IF(MOD($AD16,5)=0, "000-000 :","-" ) -> 000-000 : | U16: =IF(MOD($AD16,5)=0, "000-000 :","-" ) -> 000-000 : | V16: =IF(MOD($AD16,5)=0, "000-000 :","-" ) -> 000-000 : | W16: =IF(MOD($AD16,5)=0, "000-000 :","-" ) -> 000-000 : | X16: =IF(MOD($AD16,5)=0, "000-000 :","-" ) -> 000-000 : | Y16: =IF(MOD($AD16,5)=0, "스핀들소음 :","-" ) -> 스핀들소음 : | Z16: =IF(MOD($AD16,40)=0, "필터세척 :"& CHAR(10) & "FLOW (T1, T4 : / T2, T3 : / T4 : )","-" ) -> 필터세척 : FLOW (T1, T4 : / T2, T3 : / T4 : ) | AA16: =IF($AD16="","", IF(MOD(AD16,160)=0, "TENSION (XL : / ZL : / XR : / ZR : / Y : )" & CHAR(10) & "필터교체", "-" ) ) | AB16: - | AC16: - | AE16: =IF(AD16="","", IF(MOD($AD16,1)=0, "Dimensions: L W H", "-" ) ) | AF16: =IF(AG16="","", IF(MOD($AD16,1)=0, "완료", "-" ) )
K17: =IF(LEN(A17)>0, 상수!B$4, "") | M17: =IF(MOD($AD17,5)=0, "스핀들유격: ","-" ) -> 스핀들유격: | N17: =IF(MOD($AD17,5)=0, "스핀들유격: ","-" ) -> 스핀들유격: | O17: =IF(MOD($AD17,5)=0, "스핀들유격: ","-" ) -> 스핀들유격: | P17: =IF(MOD($AD17,5)=0, "스핀들유격: ","-" ) -> 스핀들유격: | Q17: =IF(MOD($AD17,5)=0, "000-000 :","-" ) -> 000-000 : | R17: =IF(MOD($AD17,5)=0, "000-000 :","-" ) -> 000-000 : | S17: =IF(MOD($AD17,5)=0, "000-000 :","-" ) -> 000-000 : | T17: =IF(MOD($AD17,5)=0, "000-000 :","-" ) -> 000-000 : | U17: =IF(MOD($AD17,5)=0, "000-000 :","-" ) -> 000-000 : | V17: =IF(MOD($AD17,5)=0, "000-000 :","-" ) -> 000-000 : | W17: =IF(MOD($AD17,5)=0, "000-000 :","-" ) -> 000-000 : | X17: =IF(MOD($AD17,5)=0, "000-000 :","-" ) -> 000-000 : | Y17: =IF(MOD($AD17,5)=0, "스핀들소음 :","-" ) -> 스핀들소음 : | Z17: =IF(MOD($AD17,40)=0, "필터세척 :"& CHAR(10) & "FLOW (T1, T4 : / T2, T3 : / T4 : )","-" ) -> 필터세척 : FLOW (T1, T4 : / T2, T3 : / T4 : ) | AA17: =IF($AD17="","", IF(MOD(AD17,160)=0, "TENSION (XL : / ZL : / XR : / ZR : / Y : )" & CHAR(10) & "필터교체", "-" ) ) | AB17: - | AC17: - | AE17: =IF(AD17="","", IF(MOD($AD17,1)=0, "Dimensions: L W H", "-" ) ) | AF17: =IF(AG17="","", IF(MOD($AD17,1)=0, "완료", "-" ) )
K18: =IF(LEN(A18)>0, 상수!B$4, "") | M18: =IF(MOD($AD18,5)=0, "스핀들유격: ","-" ) -> 스핀들유격: | N18: =IF(MOD($AD18,5)=0, "스핀들유격: ","-" ) -> 스핀들유격: | O18: =IF(MOD($AD18,5)=0, "스핀들유격: ","-" ) -> 스핀들유격: | P18: =IF(MOD($AD18,5)=0, "스핀들유격: ","-" ) -> 스핀들유격: | Q18: =IF(MOD($AD18,5)=0, "000-000 :","-" ) -> 000-000 : | R18: =IF(MOD($AD18,5)=0, "000-000 :","-" ) -> 000-000 : | S18: =IF(MOD($AD18,5)=0, "000-000 :","-" ) -> 000-000 : | T18: =IF(MOD($AD18,5)=0, "000-000 :","-" ) -> 000-000 : | U18: =IF(MOD($AD18,5)=0, "000-000 :","-" ) -> 000-000 : | V18: =IF(MOD($AD18,5)=0, "000-000 :","-" ) -> 000-000 : | W18: =IF(MOD($AD18,5)=0, "000-000 :","-" ) -> 000-000 : | X18: =IF(MOD($AD18,5)=0, "000-000 :","-" ) -> 000-000 : | Y18: =IF(MOD($AD18,5)=0, "스핀들소음 :","-" ) -> 스핀들소음 : | Z18: =IF(MOD($AD18,40)=0, "필터세척 :"& CHAR(10) & "FLOW (T1, T4 : / T2, T3 : / T4 : )","-" ) -> 필터세척 : FLOW (T1, T4 : / T2, T3 : / T4 : ) | AA18: =IF($AD18="","", IF(MOD(AD18,160)=0, "TENSION (XL : / ZL : / XR : / ZR : / Y : )" & CHAR(10) & "필터교체", "-" ) ) | AB18: - | AC18: - | AE18: =IF(AD18="","", IF(MOD($AD18,1)=0, "Dimensions: L W H", "-" ) ) | AF18: =IF(AG18="","", IF(MOD($AD18,1)=0, "완료", "-" ) )
K19: =IF(LEN(A19)>0, 상수!B$4, "") | M19: =IF(MOD($AD19,5)=0, "스핀들유격: ","-" ) -> 스핀들유격: | N19: =IF(MOD($AD19,5)=0, "스핀들유격: ","-" ) -> 스핀들유격: | O19: =IF(MOD($AD19,5)=0, "스핀들유격: ","-" ) -> 스핀들유격: | P19: =IF(MOD($AD19,5)=0, "스핀들유격: ","-" ) -> 스핀들유격: | Q19: =IF(MOD($AD19,5)=0, "000-000 :","-" ) -> 000-000 : | R19: =IF(MOD($AD19,5)=0, "000-000 :","-" ) -> 000-000 : | S19: =IF(MOD($AD19,5)=0, "000-000 :","-" ) -> 000-000 : | T19: =IF(MOD($AD19,5)=0, "000-000 :","-" ) -> 000-000 : | U19: =IF(MOD($AD19,5)=0, "000-000 :","-" ) -> 000-000 : | V19: =IF(MOD($AD19,5)=0, "000-000 :","-" ) -> 000-000 : | W19: =IF(MOD($AD19,5)=0, "000-000 :","-" ) -> 000-000 : | X19: =IF(MOD($AD19,5)=0, "000-000 :","-" ) -> 000-000 : | Y19: =IF(MOD($AD19,5)=0, "스핀들소음 :","-" ) -> 스핀들소음 : | Z19: =IF(MOD($AD19,40)=0, "필터세척 :"& CHAR(10) & "FLOW (T1, T4 : / T2, T3 : / T4 : )","-" ) -> 필터세척 : FLOW (T1, T4 : / T2, T3 : / T4 : ) | AA19: =IF($AD19="","", IF(MOD(AD19,160)=0, "TENSION (XL : / ZL : / XR : / ZR : / Y : )" & CHAR(10) & "필터교체", "-" ) ) | AB19: 장비 디스플레이에 "T4 OVER CURRENT" 시현 | AC19: RETRY 클릭 → 팝업닫힘 → 시험진행 | AE19: =IF(AD19="","", IF(MOD($AD19,1)=0, "Dimensions: L W H", "-" ) ) | AF19: =IF(AG19="","", IF(MOD($AD19,1)=0, "완료", "-" ) )
K20: =IF(LEN(A20)>0, 상수!B$4, "") | M20: =IF(MOD($AD20,5)=0, "스핀들유격: ","-" ) -> 스핀들유격: | N20: =IF(MOD($AD20,5)=0, "스핀들유격: ","-" ) -> 스핀들유격: | O20: =IF(MOD($AD20,5)=0, "스핀들유격: ","-" ) -> 스핀들유격: | P20: =IF(MOD($AD20,5)=0, "스핀들유격: ","-" ) -> 스핀들유격: | Q20: =IF(MOD($AD20,5)=0, "000-000 :","-" ) -> 000-000 : | R20: =IF(MOD($AD20,5)=0, "000-000 :","-" ) -> 000-000 : | S20: =IF(MOD($AD20,5)=0, "000-000 :","-" ) -> 000-000 : | T20: =IF(MOD($AD20,5)=0, "000-000 :","-" ) -> 000-000 : | U20: =IF(MOD($AD20,5)=0, "000-000 :","-" ) -> 000-000 : | V20: =IF(MOD($AD20,5)=0, "000-000 :","-" ) -> 000-000 : | W20: =IF(MOD($AD20,5)=0, "000-000 :","-" ) -> 000-000 : | X20: =IF(MOD($AD20,5)=0, "000-000 :","-" ) -> 000-000 : | Y20: =IF(MOD($AD20,5)=0, "스핀들소음 :","-" ) -> 스핀들소음 : | Z20: =IF(MOD($AD20,40)=0, "필터세척 :"& CHAR(10) & "FLOW (T1, T4 : / T2, T3 : / T4 : )","-" ) -> 필터세척 : FLOW (T1, T4 : / T2, T3 : / T4 : ) | AA20: =IF($AD20="","", IF(MOD(AD20,160)=0, "TENSION (XL : / ZL : / XR : / ZR : / Y : )" & CHAR(10) & "필터교체", "-" ) ) | AB20: 장비 디스플레이에 "T4 OVER CURRENT" 시현 | AC20: RETRY 클릭 → 팝업안닫힘 → 비정상UX흐름 판정 | AE20: =IF(AD20="","", IF(MOD($AD20,1)=0, "Dimensions: L W H", "-" ) ) | AF20: =IF(AG20="","", IF(MOD($AD20,1)=0, "완료", "-" ) )
K21: =IF(LEN(A21)>0, 상수!B$4, "") | M21: =IF(MOD($AD21,5)=0, "스핀들유격: ","-" ) -> 스핀들유격: | N21: =IF(MOD($AD21,5)=0, "스핀들유격: ","-" ) -> 스핀들유격: | O21: =IF(MOD($AD21,5)=0, "스핀들유격: ","-" ) -> 스핀들유격: | P21: =IF(MOD($AD21,5)=0, "스핀들유격: ","-" ) -> 스핀들유격: | Q21: =IF(MOD($AD21,5)=0, "000-000 :","-" ) -> 000-000 : | R21: =IF(MOD($AD21,5)=0, "000-000 :","-" ) -> 000-000 : | S21: =IF(MOD($AD21,5)=0, "000-000 :","-" ) -> 000-000 : | T21: =IF(MOD($AD21,5)=0, "000-000 :","-" ) -> 000-000 : | U21: =IF(MOD($AD21,5)=0, "000-000 :","-" ) -> 000-000 : | V21: =IF(MOD($AD21,5)=0, "000-000 :","-" ) -> 000-000 : | W21: =IF(MOD($AD21,5)=0, "000-000 :","-" ) -> 000-000 : | X21: =IF(MOD($AD21,5)=0, "000-000 :","-" ) -> 000-000 : | Y21: =IF(MOD($AD21,5)=0, "스핀들소음 :","-" ) -> 스핀들소음 : | Z21: =IF(MOD($AD21,40)=0, "필터세척 :"& CHAR(10) & "FLOW (T1, T4 : / T2, T3 : / T4 : )","-" ) -> 필터세척 : FLOW (T1, T4 : / T2, T3 : / T4 : ) | AA21: =IF($AD21="","", IF(MOD(AD21,160)=0, "TENSION (XL : / ZL : / XR : / ZR : / Y : )" & CHAR(10) & "필터교체", "-" ) ) | AE21: =IF(AD21="","", IF(MOD($AD21,1)=0, "Dimensions: L W H", "-" ) )
