Workbook

Sheet 시험
C4: 장비요소 주기점검
D5: if 50회 주기도래:
D6: 필터세척
D8: if 100회 주기도래:
D9: 필터세척
D10: 벨트 텐션 점검 (XL : / ZL : / XR : / ZR : / Y : )
D11: 유량 점검 (T1, T4 : / T2, T3 : / T4 : )

Sheet ES#8
A1: LM-10 SPINDLE 내구도 신뢰성 시험이력
A2: 수행기간 | B2: 산출물 | G2: 시험 적용 | Q2: 사전점검(시험 전 점검항목) | AG2: 특이사항
R4: 5회 가공회차 주기 | AE4: 40회 가공회차 주기 | AF4: 160회 가공회차 주기
G5: BUR 가공누적사용횟수 | L5: 가공물 | P5: 적용 상수 | Q5: 스핀들 유격 | R5: 스핀들 유격 점검 | V5: AG Mode Current(min-max) | Z5: 15000 RPM Current(min-max) and 스핀들 소음
A6: 가공일 | B6: 가공회차 | C6: 산출가공물 치수 측정결과 | D6: 시험완료여부 | E6: 가공시간(분) | F6: 비고 | G6: T1 | H6: T2 | I6: T3 | J6: T4 | K6: SPINDLE REV | L6: BLOCK 제조사 | M6: BLOCK 식별자 | N6: BLOCK 강도(MPa) | O6: BLOCK 재질 | P6: 가속 Factor | Q6: WATER TANK FILTER 청결상태 | R6: T1 | S6: T2 | T6: T3 | U6: T4 | V6: T1 | W6: T2 | X6: T3 | Y6: T4 | Z6: T1 | AA6: T2 | AB6: T3 | AC6: T4 | AD6: 스핀들 소음유무 측정 | AE6: 필터세척/유량계 유량 측정 | AF6: 필터교체/BELT TENSION 측정
A7: 45971 | B7: 1 | C7: =IF(B7="","", IF(MOD($B7,1)=0, "Dimensions: L W H", "-" ) ) -> Dimensions: L W H | D7: 완료 | E7: 21 | G7: 누락 | H7: - | I7: - | J7: 누락 | L7: VITA | M7: MARK II | N7: 160 | O7: - | P7: =IF(LEN(A7)>0, 종합!$C$27, "") -> 2.26 | Q7: - | R7: =IF(MOD($B7,5)=0, "스핀들유격: ","-" ) -> - | S7: =IF(MOD($B7,5)=0, "스핀들유격: ","-" ) -> - | T7: =IF(MOD($B7,5)=0, "스핀들유격: ","-" ) -> - | U7: =IF(MOD($B7,5)=0, "스핀들유격: ","-" ) -> - | V7: =IF(MOD($B7,5)=0, "000-000","-" ) -> - | W7: =IF(MOD($B7,5)=0, "000-000","-" ) -> - | X7: =IF(MOD($B7,5)=0, "000-000","-" ) -> - | Y7: =IF(MOD($B7,5)=0, "000-000","-" ) -> - | Z7: =IF(MOD($B7,5)=0, "000-000","-" ) -> - | AA7: =IF(MOD($B7,5)=0, "000-000","-" ) -> - | AB7: =IF(MOD($B7,5)=0, "000-000","-" ) -> - | AC7: =IF(MOD($B7,5)=0, "000-000","-" ) -> - | AD7: =IF(MOD($B7,5)=0, "스핀들소음 :","-" ) -> - | AE7: =IF(MOD($B7,40)=0, "필터세척 :"& CHAR(10) & "FLOW (T1, T4 : / T2, T3 : / T4 : )","-" ) -> - | AF7: =IF($B7="","", IF(MOD($B7,160)=0, "TENSION (XL : / ZL : / XR : / ZR : / Y : )" & CHAR(10) & "필터교체", "-" ) ) -> - | AG7: - | AH7: -
A8: 45971 | B8: =IF(NOT(LEN(A8)=0),B7+1,"") -> 2 | C8: =IF(B8="","", IF(MOD($B8,1)=0, "Dimensions: L W H", "-" ) ) -> Dimensions: L W H | D8: 완료 | E8: 21 | G8: 누락 | H8: - | I8: - | J8: 누락 | L8: =IF(NOT(LEN($J8)=0),L7,"") -> VITA | M8: =IF(NOT(LEN($J8)=0),M7,"") -> MARK II | N8: =IF(NOT(LEN($J8)=0),N7,"") -> 160 | O8: =IF(NOT(LEN($J8)=0),O7,"") -> - | P8: =IF(LEN(A8)>0, 종합!$C$27, "") -> 2.26 | Q8: - | R8: =IF(MOD($B8,5)=0, "스핀들유격: ","-" ) -> - | S8: =IF(MOD($B8,5)=0, "스핀들유격: ","-" ) -> - | T8: =IF(MOD($B8,5)=0, "스핀들유격: ","-" ) -> - | U8: =IF(MOD($B8,5)=0, "스핀들유격: ","-" ) -> - | V8: =IF(MOD($B8,5)=0, "000-000","-" ) -> - | W8: =IF(MOD($B8,5)=0, "000-000","-" ) -> - | X8: =IF(MOD($B8,5)=0, "000-000","-" ) -> - | Y8: =IF(MOD($B8,5)=0, "000-000","-" ) -> - | Z8: =IF(MOD($B8,5)=0, "000-000","-" ) -> - | AA8: =IF(MOD($B8,5)=0, "000-000","-" ) -> - | AB8: =IF(MOD($B8,5)=0, "000-000","-" ) -> - | AC8: =IF(MOD($B8,5)=0, "000-000","-" ) -> - | AD8: =IF(MOD($B8,5)=0, "스핀들소음 :","-" ) -> - | AE8: =IF(MOD($B8,40)=0, "필터세척 :"& CHAR(10) & "FLOW (T1, T4 : / T2, T3 : / T4 : )","-" ) -> - | AF8: =IF($B8="","", IF(MOD(B8,160)=0, "TENSION (XL : / ZL : / XR : / ZR : / Y : )" & CHAR(10) & "필터교체", "-" ) ) -> - | AG8: - | AH8: -
A9: 45971 | B9: =IF(NOT(LEN(A9)=0),B8+1,"") -> 3 | C9: =IF(B9="","", IF(MOD($B9,1)=0, "Dimensions: L W H", "-" ) ) -> Dimensions: L W H | D9: 완료 | E9: 21 | G9: 누락 | H9: - | I9: - | J9: 누락 | L9: VITA | M9: MARK II | N9: 161 | O9: - | P9: =IF(LEN(A9)>0, 종합!$C$27, "") -> 2.26 | Q9: - | R9: =IF(MOD($B9,5)=0, "스핀들유격: ","-" ) -> - | S9: =IF(MOD($B9,5)=0, "스핀들유격: ","-" ) -> - | T9: =IF(MOD($B9,5)=0, "스핀들유격: ","-" ) -> - | U9: =IF(MOD($B9,5)=0, "스핀들유격: ","-" ) -> - | V9: =IF(MOD($B9,5)=0, "000-000","-" ) -> - | W9: =IF(MOD($B9,5)=0, "000-000","-" ) -> - | X9: =IF(MOD($B9,5)=0, "000-000","-" ) -> - | Y9: =IF(MOD($B9,5)=0, "000-000","-" ) -> - | Z9: =IF(MOD($B9,5)=0, "000-000","-" ) -> - | AA9: =IF(MOD($B9,5)=0, "000-000","-" ) -> - | AB9: =IF(MOD($B9,5)=0, "000-000","-" ) -> - | AC9: =IF(MOD($B9,5)=0, "000-000","-" ) -> - | AD9: =IF(MOD($B9,5)=0, "스핀들소음 :","-" ) -> - | AE9: =IF(MOD($B9,40)=0, "필터세척 :"& CHAR(10) & "FLOW (T1, T4 : / T2, T3 : / T4 : )","-" ) -> - | AF9: =IF($B9="","", IF(MOD(B9,160)=0, "TENSION (XL : / ZL : / XR : / ZR : / Y : )" & CHAR(10) & "필터교체", "-" ) ) -> - | AG9: - | AH9: -
A10: 45971 | B10: =IF(NOT(LEN(A10)=0),B9+1,"") -> 4 | C10: =IF(B10="","", IF(MOD($B10,1)=0, "Dimensions: L W H", "-" ) ) -> Dimensions: L W H | D10: 완료 | E10: 21 | G10: 누락 | H10: - | I10: - | J10: 누락 | L10: =IF(NOT(LEN($J10)=0),L9,"") -> VITA | M10: =IF(NOT(LEN($J10)=0),M9,"") -> MARK II | N10: =IF(NOT(LEN($J10)=0),N9,"") -> 161 | O10: =IF(NOT(LEN($J10)=0),O9,"") -> - | P10: =IF(LEN(A10)>0, 종합!$C$27, "") -> 2.26 | Q10: - | R10: =IF(MOD($B10,5)=0, "스핀들유격: ","-" ) -> - | S10: =IF(MOD($B10,5)=0, "스핀들유격: ","-" ) -> - | T10: =IF(MOD($B10,5)=0, "스핀들유격: ","-" ) -> - | U10: =IF(MOD($B10,5)=0, "스핀들유격: ","-" ) -> - | V10: =IF(MOD($B10,5)=0, "000-000","-" ) -> - | W10: =IF(MOD($B10,5)=0, "000-000","-" ) -> - | X10: =IF(MOD($B10,5)=0, "000-000","-" ) -> - | Y10: =IF(MOD($B10,5)=0, "000-000","-" ) -> - | Z10: =IF(MOD($B10,5)=0, "000-000","-" ) -> - | AA10: =IF(MOD($B10,5)=0, "000-000","-" ) -> - | AB10: =IF(MOD($B10,5)=0, "000-000","-" ) -> - | AC10: =IF(MOD($B10,5)=0, "000-000","-" ) -> - | AD10: =IF(MOD($B10,5)=0, "스핀들소음 :","-" ) -> - | AE10: =IF(MOD($B10,40)=0, "필터세척 :"& CHAR(10) & "FLOW (T1, T4 : / T2, T3 : / T4 : )","-" ) -> - | AF10: =IF($B10="","", IF(MOD(B10,160)=0, "TENSION (XL : / ZL : / XR : / ZR : / Y : )" & CHAR(10) & "필터교체", "-" ) ) -> - | AG10: - | AH10: -
A11: 45972 | B11: =IF(NOT(LEN(A11)=0),B10+1,"") -> 5 | C11: =IF(B11="","", IF(MOD($B11,1)=0, "Dimensions: L W H", "-" ) ) -> Dimensions: L W H | D11: 완료 | E11: 23 | G11: 0 | H11: - | I11: - | J11: 0 | L11: VITA | M11: MARK II | N11: 162 | O11: - | P11: =IF(LEN(A11)>0, 종합!$C$27, "") -> 2.26 | Q11: - | R11: 적정 | S11: 적정 | T11: 적정 | U11: 적정 | V11: 260-385 | W11: 87-206 | X11: 160-266 | Y11: 173-286 | Z11: 282-297 | AA11: 252-274 | AB11: 210-264 | AC11: 260-281 | AD11: 적정 | AE11: =IF(MOD($B11,40)=0, "필터세척 :"& CHAR(10) & "FLOW (T1, T4 : / T2, T3 : / T4 : )","-" ) -> - | AF11: =IF($B11="","", IF(MOD(B11,160)=0, "TENSION (XL : / ZL : / XR : / ZR : / Y : )" & CHAR(10) & "필터교체", "-" ) ) -> - | AG11: - | AH11: -
A12: 45972 | B12: =IF(NOT(LEN(A12)=0),B11+1,"") -> 6 | C12: =IF(B12="","", IF(MOD($B12,1)=0, "Dimensions: L W H", "-" ) ) -> Dimensions: L W H | D12: 완료 | E12: 21 | G12: =IF(NOT(LEN($A12)=0),IF(G11+1>15,"버교체요망",G11+1),"") -> 1 | H12: - | I12: - | J12: =IF(NOT(LEN($A12)=0),IF(J11+1>15,"버교체요망",J11+1),"") -> 1 | L12: =IF(NOT(LEN($J12)=0),L11,"") -> VITA | M12: =IF(NOT(LEN($J12)=0),M11,"") -> MARK II | N12: =IF(NOT(LEN($J12)=0),N11,"") -> 162 | O12: =IF(NOT(LEN($J12)=0),O11,"") -> - | P12: =IF(LEN(A12)>0, 종합!$C$27, "") -> 2.26 | Q12: - | R12: =IF(MOD($B12,5)=0, "스핀들유격: ","-" ) -> - | S12: =IF(MOD($B12,5)=0, "스핀들유격: ","-" ) -> - | T12: =IF(MOD($B12,5)=0, "스핀들유격: ","-" ) -> - | U12: =IF(MOD($B12,5)=0, "스핀들유격: ","-" ) -> - | V12: =IF(MOD($B12,5)=0, "000-000","-" ) -> - | W12: =IF(MOD($B12,5)=0, "000-000","-" ) -> - | X12: =IF(MOD($B12,5)=0, "000-000","-" ) -> - | Y12: =IF(MOD($B12,5)=0, "000-000","-" ) -> - | Z12: =IF(MOD($B12,5)=0, "000-000","-" ) -> - | AA12: =IF(MOD($B12,5)=0, "000-000","-" ) -> - | AB12: =IF(MOD($B12,5)=0, "000-000","-" ) -> - | AC12: =IF(MOD($B12,5)=0, "000-000","-" ) -> - | AD12: =IF(MOD($B12,5)=0, "스핀들소음 :","-" ) -> - | AE12: =IF(MOD($B12,40)=0, "필터세척 :"& CHAR(10) & "FLOW (T1, T4 : / T2, T3 : / T4 : )","-" ) -> - | AF12: =IF($B12="","", IF(MOD(B12,160)=0, "TENSION (XL : / ZL : / XR : / ZR : / Y : )" & CHAR(10) & "필터교체", "-" ) ) -> - | AG12: issue_2025_11_10_1527 | AH12: -
A13: 45972 | B13: =IF(NOT(LEN(A13)=0),B12+1,"") -> 7 | C13: =IF(B13="","", IF(MOD($B13,1)=0, "Dimensions: L W H", "-" ) ) -> Dimensions: L W H | D13: 완료 | E13: 21 | G13: =IF(NOT(LEN($A13)=0),IF(G12+1>15,"버교체요망",G12+1),"") -> 2 | H13: - | I13: - | J13: =IF(NOT(LEN($A13)=0),IF(J12+1>15,"버교체요망",J12+1),"") -> 2 | L13: VITA | M13: MARK II | N13: 163 | O13: - | P13: =IF(LEN(A13)>0, 종합!$C$27, "") -> 2.26 | Q13: - | R13: =IF(MOD($B13,5)=0, "스핀들유격: ","-" ) -> - | S13: =IF(MOD($B13,5)=0, "스핀들유격: ","-" ) -> - | T13: =IF(MOD($B13,5)=0, "스핀들유격: ","-" ) -> - | U13: =IF(MOD($B13,5)=0, "스핀들유격: ","-" ) -> - | V13: =IF(MOD($B13,5)=0, "000-000","-" ) -> - | W13: =IF(MOD($B13,5)=0, "000-000","-" ) -> - | X13: =IF(MOD($B13,5)=0, "000-000","-" ) -> - | Y13: =IF(MOD($B13,5)=0, "000-000","-" ) -> - | Z13: =IF(MOD($B13,5)=0, "000-000","-" ) -> - | AA13: =IF(MOD($B13,5)=0, "000-000","-" ) -> - | AB13: =IF(MOD($B13,5)=0, "000-000","-" ) -> - | AC13: =IF(MOD($B13,5)=0, "000-000","-" ) -> - | AD13: =IF(MOD($B13,5)=0, "스핀들소음 :","-" ) -> - | AE13: =IF(MOD($B13,40)=0, "필터세척 :"& CHAR(10) & "FLOW (T1, T4 : / T2, T3 : / T4 : )","-" ) -> - | AF13: =IF($B13="","", IF(MOD(B13,160)=0, "TENSION (XL : / ZL : / XR : / ZR : / Y : )" & CHAR(10) & "필터교체", "-" ) ) -> - | AG13: issue_2025_11_10_1527 | AH13: -
A14: 45973 | B14: =IF(NOT(LEN(A14)=0),B13+1,"") -> 8 | C14: =IF(B14="","", IF(MOD($B14,1)=0, "Dimensions: L W H", "-" ) ) -> Dimensions: L W H | D14: 완료 | E14: 23 | G14: =IF(NOT(LEN($A14)=0),IF(G13+1>15,"버교체요망",G13+1),"") -> 3 | H14: - | I14: - | J14: =IF(NOT(LEN($A14)=0),IF(J13+1>15,"버교체요망",J13+1),"") -> 3 | L14: =IF(NOT(LEN($J14)=0),L13,"") -> VITA | M14: =IF(NOT(LEN($J14)=0),M13,"") -> MARK II | N14: =IF(NOT(LEN($J14)=0),N13,"") -> 163 | O14: =IF(NOT(LEN($J14)=0),O13,"") -> - | P14: =IF(LEN(A14)>0, 종합!$C$27, "") -> 2.26 | Q14: - | R14: =IF(MOD($B14,5)=0, "스핀들유격: ","-" ) -> - | S14: =IF(MOD($B14,5)=0, "스핀들유격: ","-" ) -> - | T14: =IF(MOD($B14,5)=0, "스핀들유격: ","-" ) -> - | U14: =IF(MOD($B14,5)=0, "스핀들유격: ","-" ) -> - | V14: =IF(MOD($B14,5)=0, "000-000","-" ) -> - | W14: =IF(MOD($B14,5)=0, "000-000","-" ) -> - | X14: =IF(MOD($B14,5)=0, "000-000","-" ) -> - | Y14: =IF(MOD($B14,5)=0, "000-000","-" ) -> - | Z14: =IF(MOD($B14,5)=0, "000-000","-" ) -> - | AA14: =IF(MOD($B14,5)=0, "000-000","-" ) -> - | AB14: =IF(MOD($B14,5)=0, "000-000","-" ) -> - | AC14: =IF(MOD($B14,5)=0, "000-000","-" ) -> - | AD14: =IF(MOD($B14,5)=0, "스핀들소음 :","-" ) -> - | AE14: =IF(MOD($B14,40)=0, "필터세척 :"& CHAR(10) & "FLOW (T1, T4 : / T2, T3 : / T4 : )","-" ) -> - | AF14: =IF($B14="","", IF(MOD(B14,160)=0, "TENSION (XL : / ZL : / XR : / ZR : / Y : )" & CHAR(10) & "필터교체", "-" ) ) -> - | AG14: issue_2025_11_10_1527 | AH14: -
A15: 45973 | B15: =IF(NOT(LEN(A15)=0),B14+1,"") -> 9 | C15: =IF(B15="","", IF(MOD($B15,1)=0, "Dimensions: L W H", "-" ) ) -> Dimensions: L W H | D15: 완료 | E15: 23 | G15: =IF(NOT(LEN($A15)=0),IF(G14+1>15,"버교체요망",G14+1),"") -> 4 | H15: - | I15: - | J15: =IF(NOT(LEN($A15)=0),IF(J14+1>15,"버교체요망",J14+1),"") -> 4 | L15: VITA | M15: MARK II | N15: 164 | O15: - | P15: =IF(LEN(A15)>0, 종합!$C$27, "") -> 2.26
A16: 45973 | B16: =IF(NOT(LEN(A16)=0),B15+1,"") -> 10 | C16: =IF(B16="","", IF(MOD($B16,1)=0, "Dimensions: L W H", "-" ) ) -> Dimensions: L W H | D16: =IF(NOT(LEN(B16)=0),"진행중","") -> 진행중 | E16: 21 | G16: =IF(NOT(LEN($A16)=0),IF(G15+1>15,"버교체요망",G15+1),"") -> 5 | H16: - | I16: - | J16: =IF(NOT(LEN($A16)=0),IF(J15+1>15,"버교체요망",J15+1),"") -> 5 | L16: VITA | M16: MARK II | N16: =IF(NOT(LEN($J16)=0),N15,"") -> 164 | O16: =IF(NOT(LEN($J16)=0),O15,"") -> - | P16: =IF(LEN(A16)>0, 종합!$C$27, "") -> 2.26
B17: =IF(NOT(LEN(A17)=0),B16+1,"") | C17: =IF(B17="","", IF(MOD($B17,1)=0, "Dimensions: L W H", "-" ) ) | D17: =IF(NOT(LEN(B17)=0),"진행중","")
B18: =IF(NOT(LEN(A18)=0),B17+1,"") | C18: =IF(B18="","", IF(MOD($B18,1)=0, "Dimensions: L W H", "-" ) ) | D18: =IF(NOT(LEN(B18)=0),"진행중","")
B19: =IF(NOT(LEN(A19)=0),B18+1,"") | C19: =IF(B19="","", IF(MOD($B19,1)=0, "Dimensions: L W H", "-" ) ) | D19: =IF(NOT(LEN(B19)=0),"진행중","")
B20: =IF(NOT(LEN(A20)=0),B19+1,"") | C20: =IF(B20="","", IF(MOD($B20,1)=0, "Dimensions: L W H", "-" ) ) | D20: =IF(NOT(LEN(B20)=0),"진행중","")
B21: =IF(NOT(LEN(A21)=0),B20+1,"") | C21: =IF(B21="","", IF(MOD($B21,1)=0, "Dimensions: L W H", "-" ) ) | D21: =IF(NOT(LEN(B21)=0),"진행중","")
B22: =IF(NOT(LEN(A22)=0),B21+1,"") | C22: =IF(B22="","", IF(MOD($B22,1)=0, "Dimensions: L W H", "-" ) ) | D22: =IF(NOT(LEN(B22)=0),"진행중","")
A23: TABLE OUTLINE | B23: TABLE OUTLINE | C23: TABLE OUTLINE | D23: TABLE OUTLINE | E23: TABLE OUTLINE | F23: TABLE OUTLINE | G23: TABLE OUTLINE | H23: TABLE OUTLINE | I23: TABLE OUTLINE | J23: TABLE OUTLINE | K23: TABLE OUTLINE | L23: TABLE OUTLINE | M23: TABLE OUTLINE | N23: TABLE OUTLINE | O23: TABLE OUTLINE | P23: TABLE OUTLINE | Q23: TABLE OUTLINE | R23: TABLE OUTLINE | S23: TABLE OUTLINE | T23: TABLE OUTLINE | U23: TABLE OUTLINE | V23: TABLE OUTLINE | W23: TABLE OUTLINE | X23: TABLE OUTLINE | Y23: TABLE OUTLINE | Z23: TABLE OUTLINE | AA23: TABLE OUTLINE | AB23: TABLE OUTLINE | AC23: TABLE OUTLINE | AD23: TABLE OUTLINE | AE23: TABLE OUTLINE | AF23: TABLE OUTLINE | AG23: TABLE OUTLINE | AH23: TABLE OUTLINE

Sheet ES#9
A1: LM-10 SPINDLE 내구도 신뢰성 시험이력
A2: 수행기간 | B2: 산출물 | G2: 시험 적용 | Q2: 사전점검(시험 전 점검항목) | AG2: 특이사항
R4: 5회 가공회차 주기 | AE4: 40회 가공회차 주기 | AF4: 160회 가공회차 주기
G5: BUR 가공누적사용횟수 | L5: 가공물 | P5: 적용 상수 | Q5: 스핀들 유격 | R5: 스핀들 유격 점검 | V5: AG Mode Current(min-max) | Z5: 15000 RPM Current(min-max) and 스핀들 소음
A6: 가공일 | B6: 가공회차 | C6: 산출가공물 치수 측정결과 | D6: 시험완료여부 | E6: 가공시간(분) | F6: 비고 | G6: T1 | H6: T2 | I6: T3 | J6: T4 | K6: SPINDLE REV | L6: BLOCK 제조사 | M6: BLOCK 식별자 | N6: BLOCK 강도(MPa) | O6: BLOCK 재질 | P6: 가속 Factor | Q6: WATER TANK FILTER 청결상태 | R6: T1 | S6: T2 | T6: T3 | U6: T4 | V6: T1 | W6: T2 | X6: T3 | Y6: T4 | Z6: T1 | AA6: T2 | AB6: T3 | AC6: T4 | AD6: 스핀들 소음유무 측정 | AE6: 필터세척/유량계 유량 측정 | AF6: 필터교체/BELT TENSION 측정
A7: 45971 | B7: 1 | C7: =IF(B7="","", IF(MOD($B7,1)=0, "Dimensions: L W H", "-" ) ) -> Dimensions: L W H | D7: 완료 | E7: 21 | G7: 누락 | H7: - | I7: - | J7: 누락 | L7: VITA | M7: MARK II | N7: 160 | O7: - | P7: =IF(LEN(A7)>0, 종합!$C$27, "") -> 2.26 | Q7: - | R7: =IF(MOD($B7,5)=0, "스핀들유격: ","-" ) -> - | S7: =IF(MOD($B7,5)=0, "스핀들유격: ","-" ) -> - | T7: =IF(MOD($B7,5)=0, "스핀들유격: ","-" ) -> - | U7: =IF(MOD($B7,5)=0, "스핀들유격: ","-" ) -> - | V7: =IF(MOD($B7,5)=0, "000-000","-" ) -> - | W7: =IF(MOD($B7,5)=0, "000-000","-" ) -> - | X7: =IF(MOD($B7,5)=0, "000-000","-" ) -> - | Y7: =IF(MOD($B7,5)=0, "000-000","-" ) -> - | Z7: =IF(MOD($B7,5)=0, "000-000","-" ) -> - | AA7: =IF(MOD($B7,5)=0, "000-000","-" ) -> - | AB7: =IF(MOD($B7,5)=0, "000-000","-" ) -> - | AC7: =IF(MOD($B7,5)=0, "000-000","-" ) -> - | AD7: =IF(MOD($B7,5)=0, "스핀들소음 :","-" ) -> - | AE7: =IF(MOD($B7,40)=0, "필터세척 :"& CHAR(10) & "FLOW (T1, T4 : / T2, T3 : / T4 : )","-" ) -> - | AF7: =IF($B7="","", IF(MOD($B7,160)=0, "TENSION (XL : / ZL : / XR : / ZR : / Y : )" & CHAR(10) & "필터교체", "-" ) ) -> - | AG7: - | AH7: -
A8: 45971 | B8: =IF(NOT(LEN(A8)=0),B7+1,"") -> 2 | C8: =IF(B8="","", IF(MOD($B8,1)=0, "Dimensions: L W H", "-" ) ) -> Dimensions: L W H | D8: 완료 | E8: 21 | G8: 누락 | H8: - | I8: - | J8: 누락 | L8: =IF(NOT(LEN($J8)=0),L7,"") -> VITA | M8: =IF(NOT(LEN($J8)=0),M7,"") -> MARK II | N8: =IF(NOT(LEN($J8)=0),N7,"") -> 160 | O8: =IF(NOT(LEN($J8)=0),O7,"") -> - | P8: =IF(LEN(A8)>0, 종합!$C$27, "") -> 2.26 | Q8: - | R8: =IF(MOD($B8,5)=0, "스핀들유격: ","-" ) -> - | S8: =IF(MOD($B8,5)=0, "스핀들유격: ","-" ) -> - | T8: =IF(MOD($B8,5)=0, "스핀들유격: ","-" ) -> - | U8: =IF(MOD($B8,5)=0, "스핀들유격: ","-" ) -> - | V8: =IF(MOD($B8,5)=0, "000-000","-" ) -> - | W8: =IF(MOD($B8,5)=0, "000-000","-" ) -> - | X8: =IF(MOD($B8,5)=0, "000-000","-" ) -> - | Y8: =IF(MOD($B8,5)=0, "000-000","-" ) -> - | Z8: =IF(MOD($B8,5)=0, "000-000","-" ) -> - | AA8: =IF(MOD($B8,5)=0, "000-000","-" ) -> - | AB8: =IF(MOD($B8,5)=0, "000-000","-" ) -> - | AC8: =IF(MOD($B8,5)=0, "000-000","-" ) -> - | AD8: =IF(MOD($B8,5)=0, "스핀들소음 :","-" ) -> - | AE8: =IF(MOD($B8,40)=0, "필터세척 :"& CHAR(10) & "FLOW (T1, T4 : / T2, T3 : / T4 : )","-" ) -> - | AF8: =IF($B8="","", IF(MOD(B8,160)=0, "TENSION (XL : / ZL : / XR : / ZR : / Y : )" & CHAR(10) & "필터교체", "-" ) ) -> - | AG8: - | AH8: -
A9: 45971 | B9: =IF(NOT(LEN(A9)=0),B8+1,"") -> 3 | C9: =IF(B9="","", IF(MOD($B9,1)=0, "Dimensions: L W H", "-" ) ) -> Dimensions: L W H | D9: 완료 | E9: 21 | G9: 누락 | H9: - | I9: - | J9: 누락 | L9: VITA | M9: MARK II | N9: 161 | O9: - | P9: =IF(LEN(A9)>0, 종합!$C$27, "") -> 2.26 | Q9: - | R9: =IF(MOD($B9,5)=0, "스핀들유격: ","-" ) -> - | S9: =IF(MOD($B9,5)=0, "스핀들유격: ","-" ) -> - | T9: =IF(MOD($B9,5)=0, "스핀들유격: ","-" ) -> - | U9: =IF(MOD($B9,5)=0, "스핀들유격: ","-" ) -> - | V9: =IF(MOD($B9,5)=0, "000-000","-" ) -> - | W9: =IF(MOD($B9,5)=0, "000-000","-" ) -> - | X9: =IF(MOD($B9,5)=0, "000-000","-" ) -> - | Y9: =IF(MOD($B9,5)=0, "000-000","-" ) -> - | Z9: =IF(MOD($B9,5)=0, "000-000","-" ) -> - | AA9: =IF(MOD($B9,5)=0, "000-000","-" ) -> - | AB9: =IF(MOD($B9,5)=0, "000-000","-" ) -> - | AC9: =IF(MOD($B9,5)=0, "000-000","-" ) -> - | AD9: =IF(MOD($B9,5)=0, "스핀들소음 :","-" ) -> - | AE9: =IF(MOD($B9,40)=0, "필터세척 :"& CHAR(10) & "FLOW (T1, T4 : / T2, T3 : / T4 : )","-" ) -> - | AF9: =IF($B9="","", IF(MOD(B9,160)=0, "TENSION (XL : / ZL : / XR : / ZR : / Y : )" & CHAR(10) & "필터교체", "-" ) ) -> - | AG9: - | AH9: -
A10: 45971 | B10: =IF(NOT(LEN(A10)=0),B9+1,"") -> 4 | C10: =IF(B10="","", IF(MOD($B10,1)=0, "Dimensions: L W H", "-" ) ) -> Dimensions: L W H | D10: 완료 | E10: 21 | G10: 누락 | H10: - | I10: - | J10: 누락 | L10: =IF(NOT(LEN($J10)=0),L9,"") -> VITA | M10: =IF(NOT(LEN($J10)=0),M9,"") -> MARK II | N10: =IF(NOT(LEN($J10)=0),N9,"") -> 161 | O10: =IF(NOT(LEN($J10)=0),O9,"") -> - | P10: =IF(LEN(A10)>0, 종합!$C$27, "") -> 2.26 | Q10: - | R10: =IF(MOD($B10,5)=0, "스핀들유격: ","-" ) -> - | S10: =IF(MOD($B10,5)=0, "스핀들유격: ","-" ) -> - | T10: =IF(MOD($B10,5)=0, "스핀들유격: ","-" ) -> - | U10: =IF(MOD($B10,5)=0, "스핀들유격: ","-" ) -> - | V10: =IF(MOD($B10,5)=0, "000-000","-" ) -> - | W10: =IF(MOD($B10,5)=0, "000-000","-" ) -> - | X10: =IF(MOD($B10,5)=0, "000-000","-" ) -> - | Y10: =IF(MOD($B10,5)=0, "000-000","-" ) -> - | Z10: =IF(MOD($B10,5)=0, "000-000","-" ) -> - | AA10: =IF(MOD($B10,5)=0, "000-000","-" ) -> - | AB10: =IF(MOD($B10,5)=0, "000-000","-" ) -> - | AC10: =IF(MOD($B10,5)=0, "000-000","-" ) -> - | AD10: =IF(MOD($B10,5)=0, "스핀들소음 :","-" ) -> - | AE10: =IF(MOD($B10,40)=0, "필터세척 :"& CHAR(10) & "FLOW (T1, T4 : / T2, T3 : / T4 : )","-" ) -> - | AF10: =IF($B10="","", IF(MOD(B10,160)=0, "TENSION (XL : / ZL : / XR : / ZR : / Y : )" & CHAR(10) & "필터교체", "-" ) ) -> - | AG10: - | AH10: -
A11: 45972 | B11: =IF(NOT(LEN(A11)=0),B10+1,"") -> 5 | C11: =IF(B11="","", IF(MOD($B11,1)=0, "Dimensions: L W H", "-" ) ) -> Dimensions: L W H | D11: 완료 | E11: 23 | G11: 0 | H11: - | I11: - | J11: 0 | L11: VITA | M11: MARK II | N11: 162 | O11: - | P11: =IF(LEN(A11)>0, 종합!$C$27, "") -> 2.26 | Q11: - | R11: 스핀들유격: 적정 | S11: 스핀들유격: 적정 | T11: 스핀들유격: 적정 | U11: 스핀들유격: 적정 | V11: 166-254 | W11: 170-230 | X11: 116-197 | Y11: 175-253 | Z11: 224-310 | AA11: 261-324 | AB11: 217-299 | AC11: 282-327 | AD11: 스핀들소음: 적정 | AE11: =IF(MOD($B11,40)=0, "필터세척 :"& CHAR(10) & "FLOW (T1, T4 : / T2, T3 : / T4 : )","-" ) -> - | AF11: =IF($B11="","", IF(MOD(B11,160)=0, "TENSION (XL : / ZL : / XR : / ZR : / Y : )" & CHAR(10) & "필터교체", "-" ) ) -> - | AG11: - | AH11: -
A12: 45972 | B12: =IF(NOT(LEN(A12)=0),B11+1,"") -> 6 | C12: =IF(B12="","", IF(MOD($B12,1)=0, "Dimensions: L W H", "-" ) ) -> Dimensions: L W H | D12: 완료 | E12: 21 | G12: 1 | H12: - | I12: - | J12: 1 | L12: =IF(NOT(LEN($J12)=0),L11,"") -> VITA | M12: =IF(NOT(LEN($J12)=0),M11,"") -> MARK II | N12: =IF(NOT(LEN($J12)=0),N11,"") -> 162 | O12: =IF(NOT(LEN($J12)=0),O11,"") -> - | P12: =IF(LEN(A12)>0, 종합!$C$27, "") -> 2.26 | Q12: - | R12: =IF(MOD($B12,5)=0, "스핀들유격: ","-" ) -> - | S12: =IF(MOD($B12,5)=0, "스핀들유격: ","-" ) -> - | T12: =IF(MOD($B12,5)=0, "스핀들유격: ","-" ) -> - | U12: =IF(MOD($B12,5)=0, "스핀들유격: ","-" ) -> - | V12: =IF(MOD($B12,5)=0, "000-000","-" ) -> - | W12: =IF(MOD($B12,5)=0, "000-000","-" ) -> - | X12: =IF(MOD($B12,5)=0, "000-000","-" ) -> - | Y12: =IF(MOD($B12,5)=0, "000-000","-" ) -> - | Z12: =IF(MOD($B12,5)=0, "000-000","-" ) -> - | AA12: =IF(MOD($B12,5)=0, "000-000","-" ) -> - | AB12: =IF(MOD($B12,5)=0, "000-000","-" ) -> - | AC12: =IF(MOD($B12,5)=0, "000-000","-" ) -> - | AD12: =IF(MOD($B12,5)=0, "스핀들소음 :","-" ) -> - | AE12: =IF(MOD($B12,40)=0, "필터세척 :"& CHAR(10) & "FLOW (T1, T4 : / T2, T3 : / T4 : )","-" ) -> - | AF12: =IF($B12="","", IF(MOD(B12,160)=0, "TENSION (XL : / ZL : / XR : / ZR : / Y : )" & CHAR(10) & "필터교체", "-" ) ) -> - | AG12: issue_2025_11_10_1527 | AH12: -
A13: 45972 | B13: =IF(NOT(LEN(A13)=0),B12+1,"") -> 7 | C13: =IF(B13="","", IF(MOD($B13,1)=0, "Dimensions: L W H", "-" ) ) -> Dimensions: L W H | D13: 완료 | E13: 21 | G13: 2 | H13: - | I13: - | J13: 2 | L13: VITA | M13: MARK II | N13: 163 | O13: - | P13: =IF(LEN(A13)>0, 종합!$C$27, "") -> 2.26 | Q13: - | R13: =IF(MOD($B13,5)=0, "스핀들유격: ","-" ) -> - | S13: =IF(MOD($B13,5)=0, "스핀들유격: ","-" ) -> - | T13: =IF(MOD($B13,5)=0, "스핀들유격: ","-" ) -> - | U13: =IF(MOD($B13,5)=0, "스핀들유격: ","-" ) -> - | V13: =IF(MOD($B13,5)=0, "000-000","-" ) -> - | W13: =IF(MOD($B13,5)=0, "000-000","-" ) -> - | X13: =IF(MOD($B13,5)=0, "000-000","-" ) -> - | Y13: =IF(MOD($B13,5)=0, "000-000","-" ) -> - | Z13: =IF(MOD($B13,5)=0, "000-000","-" ) -> - | AA13: =IF(MOD($B13,5)=0, "000-000","-" ) -> - | AB13: =IF(MOD($B13,5)=0, "000-000","-" ) -> - | AC13: =IF(MOD($B13,5)=0, "000-000","-" ) -> - | AD13: =IF(MOD($B13,5)=0, "스핀들소음 :","-" ) -> - | AE13: =IF(MOD($B13,40)=0, "필터세척 :"& CHAR(10) & "FLOW (T1, T4 : / T2, T3 : / T4 : )","-" ) -> - | AF13: =IF($B13="","", IF(MOD(B13,160)=0, "TENSION (XL : / ZL : / XR : / ZR : / Y : )" & CHAR(10) & "필터교체", "-" ) ) -> - | AG13: issue_2025_11_10_1527 | AH13: -
A14: 45973 | B14: =IF(NOT(LEN(A14)=0),B13+1,"") -> 8 | C14: =IF(B14="","", IF(MOD($B14,1)=0, "Dimensions: L W H", "-" ) ) -> Dimensions: L W H | D14: 완료 | E14: 23 | G14: 3 | H14: - | I14: - | J14: 3 | L14: =IF(NOT(LEN($J14)=0),L13,"") -> VITA | M14: =IF(NOT(LEN($J14)=0),M13,"") -> MARK II | N14: =IF(NOT(LEN($J14)=0),N13,"") -> 163 | O14: =IF(NOT(LEN($J14)=0),O13,"") -> - | P14: =IF(LEN(A14)>0, 종합!$C$27, "") -> 2.26 | Q14: - | R14: =IF(MOD($B14,5)=0, "스핀들유격: ","-" ) -> - | S14: =IF(MOD($B14,5)=0, "스핀들유격: ","-" ) -> - | T14: =IF(MOD($B14,5)=0, "스핀들유격: ","-" ) -> - | U14: =IF(MOD($B14,5)=0, "스핀들유격: ","-" ) -> - | V14: =IF(MOD($B14,5)=0, "000-000","-" ) -> - | W14: =IF(MOD($B14,5)=0, "000-000","-" ) -> - | X14: =IF(MOD($B14,5)=0, "000-000","-" ) -> - | Y14: =IF(MOD($B14,5)=0, "000-000","-" ) -> - | Z14: =IF(MOD($B14,5)=0, "000-000","-" ) -> - | AA14: =IF(MOD($B14,5)=0, "000-000","-" ) -> - | AB14: =IF(MOD($B14,5)=0, "000-000","-" ) -> - | AC14: =IF(MOD($B14,5)=0, "000-000","-" ) -> - | AD14: =IF(MOD($B14,5)=0, "스핀들소음 :","-" ) -> - | AE14: =IF(MOD($B14,40)=0, "필터세척 :"& CHAR(10) & "FLOW (T1, T4 : / T2, T3 : / T4 : )","-" ) -> - | AF14: =IF($B14="","", IF(MOD(B14,160)=0, "TENSION (XL : / ZL : / XR : / ZR : / Y : )" & CHAR(10) & "필터교체", "-" ) ) -> - | AG14: issue_2025_11_10_1527 | AH14: -
A15: 45973 | B15: =IF(NOT(LEN(A15)=0),B14+1,"") -> 9 | C15: =IF(B15="","", IF(MOD($B15,1)=0, "Dimensions: L W H", "-" ) ) -> Dimensions: L W H | D15: 완료 | E15: 23 | G15: 4 | H15: - | I15: - | J15: 3 | L15: VITA | M15: MARK II | N15: 164 | O15: - | P15: =IF(LEN(A15)>0, 종합!$C$27, "") -> 2.26
A16: 45973 | B16: =IF(NOT(LEN(A16)=0),B15+1,"") -> 10 | C16: =IF(B16="","", IF(MOD($B16,1)=0, "Dimensions: L W H", "-" ) ) -> Dimensions: L W H | D16: =IF(NOT(LEN(B16)=0),"진행중","") -> 진행중 | E16: 21 | G16: 5 | H16: - | I16: - | J16: 4 | L16: VITA | M16: MARK II | N16: =IF(NOT(LEN($J16)=0),N15,"") -> 164 | O16: =IF(NOT(LEN($J16)=0),O15,"") -> - | P16: =IF(LEN(A16)>0, 종합!$C$27, "") -> 2.26
B17: =IF(NOT(LEN(A17)=0),B16+1,"") | C17: =IF(B17="","", IF(MOD($B17,1)=0, "Dimensions: L W H", "-" ) ) | D17: =IF(NOT(LEN(B17)=0),"진행중","")
B18: =IF(NOT(LEN(A18)=0),B17+1,"") | C18: =IF(B18="","", IF(MOD($B18,1)=0, "Dimensions: L W H", "-" ) ) | D18: =IF(NOT(LEN(B18)=0),"진행중","")
B19: =IF(NOT(LEN(A19)=0),B18+1,"") | C19: =IF(B19="","", IF(MOD($B19,1)=0, "Dimensions: L W H", "-" ) ) | D19: =IF(NOT(LEN(B19)=0),"진행중","")
B20: =IF(NOT(LEN(A20)=0),B19+1,"") | C20: =IF(B20="","", IF(MOD($B20,1)=0, "Dimensions: L W H", "-" ) ) | D20: =IF(NOT(LEN(B20)=0),"진행중","")
B21: =IF(NOT(LEN(A21)=0),B20+1,"") | C21: =IF(B21="","", IF(MOD($B21,1)=0, "Dimensions: L W H", "-" ) ) | D21: =IF(NOT(LEN(B21)=0),"진행중","")
B22: =IF(NOT(LEN(A22)=0),B21+1,"") | C22: =IF(B22="","", IF(MOD($B22,1)=0, "Dimensions: L W H", "-" ) ) | D22: =IF(NOT(LEN(B22)=0),"진행중","")
A23: TABLE OUTLINE | B23: TABLE OUTLINE | C23: TABLE OUTLINE | D23: TABLE OUTLINE | E23: TABLE OUTLINE | F23: TABLE OUTLINE | G23: TABLE OUTLINE | H23: TABLE OUTLINE | I23: TABLE OUTLINE | J23: TABLE OUTLINE | K23: TABLE OUTLINE | L23: TABLE OUTLINE | M23: TABLE OUTLINE | N23: TABLE OUTLINE | O23: TABLE OUTLINE | P23: TABLE OUTLINE | Q23: TABLE OUTLINE | R23: TABLE OUTLINE | S23: TABLE OUTLINE | T23: TABLE OUTLINE | U23: TABLE OUTLINE | V23: TABLE OUTLINE | W23: TABLE OUTLINE | X23: TABLE OUTLINE | Y23: TABLE OUTLINE | Z23: TABLE OUTLINE | AA23: TABLE OUTLINE | AB23: TABLE OUTLINE | AC23: TABLE OUTLINE | AD23: TABLE OUTLINE | AE23: TABLE OUTLINE | AF23: TABLE OUTLINE | AG23: TABLE OUTLINE | AH23: TABLE OUTLINE

Sheet PP#2
A1: LM-10 SPINDLE 내구도 신뢰성 시험이력
A2: 수행기간 | B2: 산출물 | G2: 시험 적용 | Q2: 사전점검(시험 전 점검항목) | AG2: 특이사항
R4: 5회 가공회차 주기 | AE4: 40회 가공회차 주기 | AF4: 160회 가공회차 주기
G5: BUR 가공누적사용횟수 | L5: 가공물 | P5: 적용 상수 | Q5: 스핀들 유격 | R5: 스핀들 유격 점검 | V5: AG Mode Current(min-max) | Z5: 15000 RPM Current(min-max) and 스핀들 소음
A6: 가공일 | B6: 가공회차 | C6: 산출가공물 치수 측정결과 | D6: 시험완료여부 | E6: 가공시간(분) | F6: 비고 | G6: T1 | H6: T2 | I6: T3 | J6: T4 | K6: SPINDLE REV | L6: BLOCK 제조사 | M6: BLOCK 식별자 | N6: BLOCK 강도(MPa) | O6: BLOCK 재질 | P6: 가속 Factor | Q6: WATER TANK FILTER 청결상태 | R6: T1 | S6: T2 | T6: T3 | U6: T4 | V6: T1 | W6: T2 | X6: T3 | Y6: T4 | Z6: T1 | AA6: T2 | AB6: T3 | AC6: T4 | AD6: 스핀들 소음유무 측정 | AE6: 필터세척/유량계 유량 측정 | AF6: 필터교체/BELT TENSION 측정
A7: 45971 | B7: 1 | C7: =IF(B7="","", IF(MOD($B7,1)=0, "Dimensions: L W H", "-" ) ) -> Dimensions: L W H | D7: =IF(E7="","", IF(MOD($B7,1)=0, "완료", "-" ) ) -> 완료 | E7: 19 | G7: 누락 | H7: - | I7: - | J7: 누락 | L7: VITA | M7: MARK II | N7: 160 | O7: - | P7: =IF(LEN(A7)>0, 종합!$C$27, "") -> 2.26 | Q7: - | R7: =IF(MOD($B7,5)=0, "스핀들유격: ","-" ) -> - | S7: =IF(MOD($B7,5)=0, "스핀들유격: ","-" ) -> - | T7: =IF(MOD($B7,5)=0, "스핀들유격: ","-" ) -> - | U7: =IF(MOD($B7,5)=0, "스핀들유격: ","-" ) -> - | V7: =IF(MOD($B7,5)=0, "000-000","-" ) -> - | W7: =IF(MOD($B7,5)=0, "000-000","-" ) -> - | X7: =IF(MOD($B7,5)=0, "000-000","-" ) -> - | Y7: =IF(MOD($B7,5)=0, "000-000","-" ) -> - | Z7: =IF(MOD($B7,5)=0, "000-000","-" ) -> - | AA7: =IF(MOD($B7,5)=0, "000-000","-" ) -> - | AB7: =IF(MOD($B7,5)=0, "000-000","-" ) -> - | AC7: =IF(MOD($B7,5)=0, "000-000","-" ) -> - | AD7: =IF(MOD($B7,5)=0, "스핀들소음 :","-" ) -> - | AE7: =IF(MOD($B7,40)=0, "필터세척 :"& CHAR(10) & "FLOW (T1, T4 : / T2, T3 : / T4 : )","-" ) -> - | AF7: =IF($B7="","", IF(MOD($B7,160)=0, "TENSION (XL : / ZL : / XR : / ZR : / Y : )" & CHAR(10) & "필터교체", "-" ) ) -> - | AG7: -
A8: 45971 | B8: =IF(NOT(LEN(A8)=0),B7+1,"") -> 2 | C8: =IF(B8="","", IF(MOD($B8,1)=0, "Dimensions: L W H", "-" ) ) -> Dimensions: L W H | D8: =IF(E8="","", IF(MOD($B8,1)=0, "완료", "-" ) ) -> 완료 | E8: 19 | G8: 누락 | H8: - | I8: - | J8: 누락 | L8: =IF(NOT(LEN($J8)=0),L7,"") -> VITA | M8: =IF(NOT(LEN($J8)=0),M7,"") -> MARK II | N8: =IF(NOT(LEN($J8)=0),N7,"") -> 160 | O8: =IF(NOT(LEN($J8)=0),O7,"") -> - | P8: =IF(LEN(A8)>0, 종합!$C$27, "") -> 2.26 | Q8: - | R8: =IF(MOD($B8,5)=0, "스핀들유격: ","-" ) -> - | S8: =IF(MOD($B8,5)=0, "스핀들유격: ","-" ) -> - | T8: =IF(MOD($B8,5)=0, "스핀들유격: ","-" ) -> - | U8: =IF(MOD($B8,5)=0, "스핀들유격: ","-" ) -> - | V8: =IF(MOD($B8,5)=0, "000-000","-" ) -> - | W8: =IF(MOD($B8,5)=0, "000-000","-" ) -> - | X8: =IF(MOD($B8,5)=0, "000-000","-" ) -> - | Y8: =IF(MOD($B8,5)=0, "000-000","-" ) -> - | Z8: =IF(MOD($B8,5)=0, "000-000","-" ) -> - | AA8: =IF(MOD($B8,5)=0, "000-000","-" ) -> - | AB8: =IF(MOD($B8,5)=0, "000-000","-" ) -> - | AC8: =IF(MOD($B8,5)=0, "000-000","-" ) -> - | AD8: =IF(MOD($B8,5)=0, "스핀들소음 :","-" ) -> - | AE8: =IF(MOD($B8,40)=0, "필터세척 :"& CHAR(10) & "FLOW (T1, T4 : / T2, T3 : / T4 : )","-" ) -> - | AF8: =IF($B8="","", IF(MOD(B8,160)=0, "TENSION (XL : / ZL : / XR : / ZR : / Y : )" & CHAR(10) & "필터교체", "-" ) ) -> - | AG8: -
A9: 45971 | B9: =IF(NOT(LEN(A9)=0),B8+1,"") -> 3 | C9: =IF(B9="","", IF(MOD($B9,1)=0, "Dimensions: L W H", "-" ) ) -> Dimensions: L W H | D9: =IF(E9="","", IF(MOD($B9,1)=0, "완료", "-" ) ) -> 완료 | E9: 19 | G9: 누락 | H9: - | I9: - | J9: 누락 | L9: =IF(NOT(LEN($J9)=0),L8,"") -> VITA | M9: =IF(NOT(LEN($J9)=0),M8,"") -> MARK II | N9: =IF(NOT(LEN($J9)=0),N8,"") -> 160 | O9: =IF(NOT(LEN($J9)=0),O8,"") -> - | P9: =IF(LEN(A9)>0, 종합!$C$27, "") -> 2.26 | Q9: - | R9: =IF(MOD($B9,5)=0, "스핀들유격: ","-" ) -> - | S9: =IF(MOD($B9,5)=0, "스핀들유격: ","-" ) -> - | T9: =IF(MOD($B9,5)=0, "스핀들유격: ","-" ) -> - | U9: =IF(MOD($B9,5)=0, "스핀들유격: ","-" ) -> - | V9: =IF(MOD($B9,5)=0, "000-000","-" ) -> - | W9: =IF(MOD($B9,5)=0, "000-000","-" ) -> - | X9: =IF(MOD($B9,5)=0, "000-000","-" ) -> - | Y9: =IF(MOD($B9,5)=0, "000-000","-" ) -> - | Z9: =IF(MOD($B9,5)=0, "000-000","-" ) -> - | AA9: =IF(MOD($B9,5)=0, "000-000","-" ) -> - | AB9: =IF(MOD($B9,5)=0, "000-000","-" ) -> - | AC9: =IF(MOD($B9,5)=0, "000-000","-" ) -> - | AD9: =IF(MOD($B9,5)=0, "스핀들소음 :","-" ) -> - | AE9: =IF(MOD($B9,40)=0, "필터세척 :"& CHAR(10) & "FLOW (T1, T4 : / T2, T3 : / T4 : )","-" ) -> - | AF9: =IF($B9="","", IF(MOD(B9,160)=0, "TENSION (XL : / ZL : / XR : / ZR : / Y : )" & CHAR(10) & "필터교체", "-" ) ) -> - | AG9: -
A10: 45971 | B10: =IF(NOT(LEN(A10)=0),B9+1,"") -> 4 | C10: =IF(B10="","", IF(MOD($B10,1)=0, "Dimensions: L W H", "-" ) ) -> Dimensions: L W H | D10: =IF(E10="","", IF(MOD($B10,1)=0, "완료", "-" ) ) -> 완료 | E10: 21 | G10: 누락 | H10: - | I10: - | J10: 누락 | L10: =IF(NOT(LEN($J10)=0),L9,"") -> VITA | M10: =IF(NOT(LEN($J10)=0),M9,"") -> MARK II | N10: =IF(NOT(LEN($J10)=0),N9,"") -> 160 | O10: =IF(NOT(LEN($J10)=0),O9,"") -> - | P10: =IF(LEN(A10)>0, 종합!$C$27, "") -> 2.26 | Q10: - | R10: =IF(MOD($B10,5)=0, "스핀들유격: ","-" ) -> - | S10: =IF(MOD($B10,5)=0, "스핀들유격: ","-" ) -> - | T10: =IF(MOD($B10,5)=0, "스핀들유격: ","-" ) -> - | U10: =IF(MOD($B10,5)=0, "스핀들유격: ","-" ) -> - | V10: =IF(MOD($B10,5)=0, "000-000","-" ) -> - | W10: =IF(MOD($B10,5)=0, "000-000","-" ) -> - | X10: =IF(MOD($B10,5)=0, "000-000","-" ) -> - | Y10: =IF(MOD($B10,5)=0, "000-000","-" ) -> - | Z10: =IF(MOD($B10,5)=0, "000-000","-" ) -> - | AA10: =IF(MOD($B10,5)=0, "000-000","-" ) -> - | AB10: =IF(MOD($B10,5)=0, "000-000","-" ) -> - | AC10: =IF(MOD($B10,5)=0, "000-000","-" ) -> - | AD10: =IF(MOD($B10,5)=0, "스핀들소음 :","-" ) -> - | AE10: =IF(MOD($B10,40)=0, "필터세척 :"& CHAR(10) & "FLOW (T1, T4 : / T2, T3 : / T4 : )","-" ) -> - | AF10: =IF($B10="","", IF(MOD(B10,160)=0, "TENSION (XL : / ZL : / XR : / ZR : / Y : )" & CHAR(10) & "필터교체", "-" ) ) -> - | AG10: -
A11: 45971 | B11: =IF(NOT(LEN(A11)=0),B10+1,"") -> 5 | C11: =IF(B11="","", IF(MOD($B11,1)=0, "Dimensions: L W H", "-" ) ) -> Dimensions: L W H | D11: =IF(E11="","", IF(MOD($B11,1)=0, "완료", "-" ) ) -> 완료 | E11: 21 | G11: 누락 | H11: - | I11: - | J11: 누락 | L11: =IF(NOT(LEN($J11)=0),L10,"") -> VITA | M11: =IF(NOT(LEN($J11)=0),M10,"") -> MARK II | N11: =IF(NOT(LEN($J11)=0),N10,"") -> 160 | O11: =IF(NOT(LEN($J11)=0),O10,"") -> - | P11: =IF(LEN(A11)>0, 종합!$C$27, "") -> 2.26 | Q11: - | R11: 스핀들유격: 적정 | S11: 스핀들유격: 적정 | T11: 스핀들유격: 적정 | U11: 스핀들유격: 적정 | V11: 159-229 | W11: 92-170 | X11: 196-241 | Y11: 109-260 | Z11: 230-270 | AA11: 242-279 | AB11: 240-267 | AC11: 248-270 | AD11: 스핀들소음: 적정 | AE11: =IF(MOD($B11,40)=0, "필터세척 :"& CHAR(10) & "FLOW (T1, T4 : / T2, T3 : / T4 : )","-" ) -> - | AF11: =IF($B11="","", IF(MOD(B11,160)=0, "TENSION (XL : / ZL : / XR : / ZR : / Y : )" & CHAR(10) & "필터교체", "-" ) ) -> - | AG11: -
A12: 45971 | B12: =IF(NOT(LEN(A12)=0),B11+1,"") -> 6 | C12: =IF(B12="","", IF(MOD($B12,1)=0, "Dimensions: L W H", "-" ) ) -> Dimensions: L W H | D12: =IF(E12="","", IF(MOD($B12,1)=0, "완료", "-" ) ) -> 완료 | E12: 19 | G12: 누락 | H12: - | I12: - | J12: 누락 | L12: =IF(NOT(LEN($J12)=0),L11,"") -> VITA | M12: =IF(NOT(LEN($J12)=0),M11,"") -> MARK II | N12: =IF(NOT(LEN($J12)=0),N11,"") -> 160 | O12: =IF(NOT(LEN($J12)=0),O11,"") -> - | P12: =IF(LEN(A12)>0, 종합!$C$27, "") -> 2.26 | Q12: - | R12: =IF(MOD($B12,5)=0, "스핀들유격: ","-" ) -> - | S12: =IF(MOD($B12,5)=0, "스핀들유격: ","-" ) -> - | T12: =IF(MOD($B12,5)=0, "스핀들유격: ","-" ) -> - | U12: =IF(MOD($B12,5)=0, "스핀들유격: ","-" ) -> - | V12: =IF(MOD($B12,5)=0, "000-000","-" ) -> - | W12: =IF(MOD($B12,5)=0, "000-000","-" ) -> - | X12: =IF(MOD($B12,5)=0, "000-000","-" ) -> - | Y12: =IF(MOD($B12,5)=0, "000-000","-" ) -> - | Z12: =IF(MOD($B12,5)=0, "000-000","-" ) -> - | AA12: =IF(MOD($B12,5)=0, "000-000","-" ) -> - | AB12: =IF(MOD($B12,5)=0, "000-000","-" ) -> - | AC12: =IF(MOD($B12,5)=0, "000-000","-" ) -> - | AD12: =IF(MOD($B12,5)=0, "스핀들소음 :","-" ) -> - | AE12: =IF(MOD($B12,40)=0, "필터세척 :"& CHAR(10) & "FLOW (T1, T4 : / T2, T3 : / T4 : )","-" ) -> - | AF12: =IF($B12="","", IF(MOD(B12,160)=0, "TENSION (XL : / ZL : / XR : / ZR : / Y : )" & CHAR(10) & "필터교체", "-" ) ) -> - | AG12: -
A13: 45972 | B13: =IF(NOT(LEN(A13)=0),B12+1,"") -> 7 | C13: =IF(B13="","", IF(MOD($B13,1)=0, "Dimensions: L W H", "-" ) ) -> Dimensions: L W H | D13: =IF(E13="","", IF(MOD($B13,1)=0, "완료", "-" ) ) -> 완료 | E13: 23 | G13: 0 | H13: - | I13: - | J13: 0 | L13: =IF(NOT(LEN($J13)=0),L12,"") -> VITA | M13: =IF(NOT(LEN($J13)=0),M12,"") -> MARK II | N13: =IF(NOT(LEN($J13)=0),N12,"") -> 160 | O13: =IF(NOT(LEN($J13)=0),O12,"") -> - | P13: =IF(LEN(A13)>0, 종합!$C$27, "") -> 2.26 | Q13: - | R13: =IF(MOD($B13,5)=0, "스핀들유격: ","-" ) -> - | S13: =IF(MOD($B13,5)=0, "스핀들유격: ","-" ) -> - | T13: =IF(MOD($B13,5)=0, "스핀들유격: ","-" ) -> - | U13: =IF(MOD($B13,5)=0, "스핀들유격: ","-" ) -> - | V13: =IF(MOD($B13,5)=0, "000-000","-" ) -> - | W13: =IF(MOD($B13,5)=0, "000-000","-" ) -> - | X13: =IF(MOD($B13,5)=0, "000-000","-" ) -> - | Y13: =IF(MOD($B13,5)=0, "000-000","-" ) -> - | Z13: =IF(MOD($B13,5)=0, "000-000","-" ) -> - | AA13: =IF(MOD($B13,5)=0, "000-000","-" ) -> - | AB13: =IF(MOD($B13,5)=0, "000-000","-" ) -> - | AC13: =IF(MOD($B13,5)=0, "000-000","-" ) -> - | AD13: =IF(MOD($B13,5)=0, "스핀들소음 :","-" ) -> - | AE13: =IF(MOD($B13,40)=0, "필터세척 :"& CHAR(10) & "FLOW (T1, T4 : / T2, T3 : / T4 : )","-" ) -> - | AF13: =IF($B13="","", IF(MOD(B13,160)=0, "TENSION (XL : / ZL : / XR : / ZR : / Y : )" & CHAR(10) & "필터교체", "-" ) ) -> - | AG13: -
A14: 45972 | B14: =IF(NOT(LEN(A14)=0),B13+1,"") -> 8 | C14: =IF(B14="","", IF(MOD($B14,1)=0, "Dimensions: L W H", "-" ) ) -> Dimensions: L W H | D14: =IF(E14="","", IF(MOD($B14,1)=0, "완료", "-" ) ) -> 완료 | E14: 21 | G14: =IF(NOT(LEN($A14)=0),IF(G13+1>15,"버교체요망",G13+1),"") -> 1 | H14: - | I14: - | J14: =IF(NOT(LEN($A14)=0),IF(J13+1>15,"버교체요망",J13+1),"") -> 1 | L14: =IF(NOT(LEN($J14)=0),L13,"") -> VITA | M14: =IF(NOT(LEN($J14)=0),M13,"") -> MARK II | N14: =IF(NOT(LEN($J14)=0),N13,"") -> 160 | O14: =IF(NOT(LEN($J14)=0),O13,"") -> - | P14: =IF(LEN(A14)>0, 종합!$C$27, "") -> 2.26 | Q14: - | R14: =IF(MOD($B14,5)=0, "스핀들유격: ","-" ) -> - | S14: =IF(MOD($B14,5)=0, "스핀들유격: ","-" ) -> - | T14: =IF(MOD($B14,5)=0, "스핀들유격: ","-" ) -> - | U14: =IF(MOD($B14,5)=0, "스핀들유격: ","-" ) -> - | V14: =IF(MOD($B14,5)=0, "000-000","-" ) -> - | W14: =IF(MOD($B14,5)=0, "000-000","-" ) -> - | X14: =IF(MOD($B14,5)=0, "000-000","-" ) -> - | Y14: =IF(MOD($B14,5)=0, "000-000","-" ) -> - | Z14: =IF(MOD($B14,5)=0, "000-000","-" ) -> - | AA14: =IF(MOD($B14,5)=0, "000-000","-" ) -> - | AB14: =IF(MOD($B14,5)=0, "000-000","-" ) -> - | AC14: =IF(MOD($B14,5)=0, "000-000","-" ) -> - | AD14: =IF(MOD($B14,5)=0, "스핀들소음 :","-" ) -> - | AE14: =IF(MOD($B14,40)=0, "필터세척 :"& CHAR(10) & "FLOW (T1, T4 : / T2, T3 : / T4 : )","-" ) -> - | AF14: =IF($B14="","", IF(MOD(B14,160)=0, "TENSION (XL : / ZL : / XR : / ZR : / Y : )" & CHAR(10) & "필터교체", "-" ) ) -> - | AG14: -
A15: 45972 | B15: =IF(NOT(LEN(A15)=0),B14+1,"") -> 9 | C15: =IF(B15="","", IF(MOD($B15,1)=0, "Dimensions: L W H", "-" ) ) -> Dimensions: L W H | D15: =IF(E15="","", IF(MOD($B15,1)=0, "완료", "-" ) ) -> 완료 | E15: 21 | G15: =IF(NOT(LEN($A15)=0),IF(G14+1>15,"버교체요망",G14+1),"") -> 2 | H15: - | I15: - | J15: =IF(NOT(LEN($A15)=0),IF(J14+1>15,"버교체요망",J14+1),"") -> 2 | L15: =IF(NOT(LEN($J15)=0),L14,"") -> VITA | M15: =IF(NOT(LEN($J15)=0),M14,"") -> MARK II | N15: =IF(NOT(LEN($J15)=0),N14,"") -> 160 | O15: =IF(NOT(LEN($J15)=0),O14,"") -> - | P15: =IF(LEN(A15)>0, 종합!$C$27, "") -> 2.26 | Q15: - | R15: =IF(MOD($B15,5)=0, "스핀들유격: ","-" ) -> - | S15: =IF(MOD($B15,5)=0, "스핀들유격: ","-" ) -> - | T15: =IF(MOD($B15,5)=0, "스핀들유격: ","-" ) -> - | U15: =IF(MOD($B15,5)=0, "스핀들유격: ","-" ) -> - | V15: =IF(MOD($B15,5)=0, "000-000","-" ) -> - | W15: =IF(MOD($B15,5)=0, "000-000","-" ) -> - | X15: =IF(MOD($B15,5)=0, "000-000","-" ) -> - | Y15: =IF(MOD($B15,5)=0, "000-000","-" ) -> - | Z15: =IF(MOD($B15,5)=0, "000-000","-" ) -> - | AA15: =IF(MOD($B15,5)=0, "000-000","-" ) -> - | AB15: =IF(MOD($B15,5)=0, "000-000","-" ) -> - | AC15: =IF(MOD($B15,5)=0, "000-000","-" ) -> - | AD15: =IF(MOD($B15,5)=0, "스핀들소음 :","-" ) -> - | AE15: =IF(MOD($B15,40)=0, "필터세척 :"& CHAR(10) & "FLOW (T1, T4 : / T2, T3 : / T4 : )","-" ) -> - | AF15: =IF($B15="","", IF(MOD(B15,160)=0, "TENSION (XL : / ZL : / XR : / ZR : / Y : )" & CHAR(10) & "필터교체", "-" ) ) -> - | AG15: -
A16: 45972 | B16: =IF(NOT(LEN(A16)=0),B15+1,"") -> 10 | C16: =IF(B16="","", IF(MOD($B16,1)=0, "Dimensions: L W H", "-" ) ) -> Dimensions: L W H | D16: =IF(E16="","", IF(MOD($B16,1)=0, "완료", "-" ) ) -> 완료 | E16: 21 | G16: =IF(NOT(LEN($A16)=0),IF(G15+1>15,"버교체요망",G15+1),"") -> 3 | H16: - | I16: - | J16: =IF(NOT(LEN($A16)=0),IF(J15+1>15,"버교체요망",J15+1),"") -> 3 | L16: =IF(NOT(LEN($J16)=0),L15,"") -> VITA | M16: =IF(NOT(LEN($J16)=0),M15,"") -> MARK II | N16: =IF(NOT(LEN($J16)=0),N15,"") -> 160 | O16: =IF(NOT(LEN($J16)=0),O15,"") -> - | P16: =IF(LEN(A16)>0, 종합!$C$27, "") -> 2.26 | Q16: - | R16: =IF(MOD($B16,5)=0, "스핀들유격: ","-" ) -> 스핀들유격: | S16: =IF(MOD($B16,5)=0, "스핀들유격: ","-" ) -> 스핀들유격: | T16: =IF(MOD($B16,5)=0, "스핀들유격: ","-" ) -> 스핀들유격: | U16: =IF(MOD($B16,5)=0, "스핀들유격: ","-" ) -> 스핀들유격: | V16: =IF(MOD($B16,5)=0, "000-000","-" ) -> 000-000 | W16: =IF(MOD($B16,5)=0, "000-000","-" ) -> 000-000 | X16: =IF(MOD($B16,5)=0, "000-000","-" ) -> 000-000 | Y16: =IF(MOD($B16,5)=0, "000-000","-" ) -> 000-000 | Z16: =IF(MOD($B16,5)=0, "000-000","-" ) -> 000-000 | AA16: =IF(MOD($B16,5)=0, "000-000","-" ) -> 000-000 | AB16: =IF(MOD($B16,5)=0, "000-000","-" ) -> 000-000 | AC16: =IF(MOD($B16,5)=0, "000-000","-" ) -> 000-000 | AD16: =IF(MOD($B16,5)=0, "스핀들소음 :","-" ) -> 스핀들소음 : | AE16: =IF(MOD($B16,40)=0, "필터세척 :"& CHAR(10) & "FLOW (T1, T4 : / T2, T3 : / T4 : )","-" ) -> - | AF16: =IF($B16="","", IF(MOD(B16,160)=0, "TENSION (XL : / ZL : / XR : / ZR : / Y : )" & CHAR(10) & "필터교체", "-" ) ) -> - | AG16: -
A17: 45973 | B17: =IF(NOT(LEN(A17)=0),B16+1,"") -> 11 | C17: =IF(B17="","", IF(MOD($B17,1)=0, "Dimensions: L W H", "-" ) ) -> Dimensions: L W H | D17: =IF(E17="","", IF(MOD($B17,1)=0, "완료", "-" ) ) -> 완료 | E17: 21 | G17: =IF(NOT(LEN($A17)=0),IF(G16+1>15,"버교체요망",G16+1),"") -> 4 | H17: - | I17: - | J17: =IF(NOT(LEN($A17)=0),IF(J16+1>15,"버교체요망",J16+1),"") -> 4 | L17: =IF(NOT(LEN($J17)=0),L16,"") -> VITA | M17: =IF(NOT(LEN($J17)=0),M16,"") -> MARK II | N17: =IF(NOT(LEN($J17)=0),N16,"") -> 160 | O17: =IF(NOT(LEN($J17)=0),O16,"") -> - | P17: =IF(LEN(A17)>0, 종합!$C$27, "") -> 2.26 | Q17: - | R17: =IF(MOD($B17,5)=0, "스핀들유격: ","-" ) -> - | S17: =IF(MOD($B17,5)=0, "스핀들유격: ","-" ) -> - | T17: =IF(MOD($B17,5)=0, "스핀들유격: ","-" ) -> - | U17: =IF(MOD($B17,5)=0, "스핀들유격: ","-" ) -> - | V17: =IF(MOD($B17,5)=0, "000-000","-" ) -> - | W17: =IF(MOD($B17,5)=0, "000-000","-" ) -> - | X17: =IF(MOD($B17,5)=0, "000-000","-" ) -> - | Y17: =IF(MOD($B17,5)=0, "000-000","-" ) -> - | Z17: =IF(MOD($B17,5)=0, "000-000","-" ) -> - | AA17: =IF(MOD($B17,5)=0, "000-000","-" ) -> - | AB17: =IF(MOD($B17,5)=0, "000-000","-" ) -> - | AC17: =IF(MOD($B17,5)=0, "000-000","-" ) -> - | AD17: =IF(MOD($B17,5)=0, "스핀들소음 :","-" ) -> - | AE17: =IF(MOD($B17,40)=0, "필터세척 :"& CHAR(10) & "FLOW (T1, T4 : / T2, T3 : / T4 : )","-" ) -> - | AF17: =IF($B17="","", IF(MOD(B17,160)=0, "TENSION (XL : / ZL : / XR : / ZR : / Y : )" & CHAR(10) & "필터교체", "-" ) ) -> - | AG17: -
A18: 45973 | B18: =IF(NOT(LEN(A18)=0),B17+1,"") -> 12 | C18: =IF(B18="","", IF(MOD($B18,1)=0, "Dimensions: L W H", "-" ) ) -> Dimensions: L W H | D18: =IF(NOT(LEN(B18)=0),"진행중","") -> 진행중 | E18: 23 | G18: =IF(NOT(LEN($A18)=0),IF(G17+1>15,"버교체요망",G17+1),"") -> 5 | J18: =IF(NOT(LEN($A18)=0),IF(J17+1>15,"버교체요망",J17+1),"") -> 5 | L18: =IF(NOT(LEN($J18)=0),L17,"") -> VITA | M18: =IF(NOT(LEN($J18)=0),M17,"") -> MARK II | N18: =IF(NOT(LEN($J18)=0),N17,"") -> 160 | O18: =IF(NOT(LEN($J18)=0),O17,"") -> - | P18: =IF(LEN(A18)>0, 종합!$C$27, "") -> 2.26
B19: =IF(NOT(LEN(A19)=0),B18+1,"") | C19: =IF(B19="","", IF(MOD($B19,1)=0, "Dimensions: L W H", "-" ) ) | D19: =IF(NOT(LEN(B19)=0),"진행중","") | G19: =IF(NOT(LEN($A19)=0),IF(G18+1>15,"버교체요망",G18+1),"") | J19: =IF(NOT(LEN($A19)=0),IF(J18+1>15,"버교체요망",J18+1),"")
B20: =IF(NOT(LEN(A20)=0),B19+1,"") | C20: =IF(B20="","", IF(MOD($B20,1)=0, "Dimensions: L W H", "-" ) ) | D20: =IF(NOT(LEN(B20)=0),"진행중","") | G20: =IF(NOT(LEN($A20)=0),IF(G19+1>15,"버교체요망",G19+1),"") | J20: =IF(NOT(LEN($A20)=0),IF(J19+1>15,"버교체요망",J19+1),"")
B21: =IF(NOT(LEN(A21)=0),B20+1,"") | C21: =IF(B21="","", IF(MOD($B21,1)=0, "Dimensions: L W H", "-" ) ) | D21: =IF(NOT(LEN(B21)=0),"진행중","") | G21: =IF(NOT(LEN($A21)=0),IF(G20+1>15,"버교체요망",G20+1),"") | J21: =IF(NOT(LEN($A21)=0),IF(J20+1>15,"버교체요망",J20+1),"")
B22: =IF(NOT(LEN(A22)=0),B21+1,"") | C22: =IF(B22="","", IF(MOD($B22,1)=0, "Dimensions: L W H", "-" ) ) | D22: =IF(NOT(LEN(B22)=0),"진행중","") | G22: =IF(NOT(LEN($A22)=0),IF(G21+1>15,"버교체요망",G21+1),"") | J22: =IF(NOT(LEN($A22)=0),IF(J21+1>15,"버교체요망",J21+1),"")
A23: TABLE OUTLINE | B23: TABLE OUTLINE | C23: TABLE OUTLINE | D23: TABLE OUTLINE | E23: TABLE OUTLINE | F23: TABLE OUTLINE | G23: TABLE OUTLINE | H23: TABLE OUTLINE | I23: TABLE OUTLINE | J23: TABLE OUTLINE | K23: TABLE OUTLINE | L23: TABLE OUTLINE | M23: TABLE OUTLINE | N23: TABLE OUTLINE | O23: TABLE OUTLINE | P23: TABLE OUTLINE | Q23: TABLE OUTLINE | R23: TABLE OUTLINE | S23: TABLE OUTLINE | T23: TABLE OUTLINE | U23: TABLE OUTLINE | V23: TABLE OUTLINE | W23: TABLE OUTLINE | X23: TABLE OUTLINE | Y23: TABLE OUTLINE | Z23: TABLE OUTLINE | AA23: TABLE OUTLINE | AB23: TABLE OUTLINE | AC23: TABLE OUTLINE | AD23: TABLE OUTLINE | AE23: TABLE OUTLINE | AF23: TABLE OUTLINE | AG23: TABLE OUTLINE | AH23: TABLE OUTLINE

Sheet PP#3
A1: LM-10 SPINDLE 내구도 신뢰성 시험이력
A2: 수행기간 | B2: 산출물 | G2: 시험 적용 | Q2: 사전점검(시험 전 점검항목) | AG2: 특이사항
R4: 5회 가공회차 주기 | AE4: 40회 가공회차 주기 | AF4: 160회 가공회차 주기
G5: BUR 가공누적사용횟수 | L5: 가공물 | P5: 적용 상수 | Q5: 스핀들 유격 | R5: 스핀들 유격 점검 | V5: AG Mode Current(min-max) | Z5: 15000 RPM Current(min-max) and 스핀들 소음
A6: 가공일 | B6: 가공회차 | C6: 산출가공물 치수 측정결과 | D6: 시험완료여부 | E6: 가공시간(분) | F6: 비고 | G6: T1 | H6: T2 | I6: T3 | J6: T4 | K6: SPINDLE REV | L6: BLOCK 제조사 | M6: BLOCK 식별자 | N6: BLOCK 강도(MPa) | O6: BLOCK 재질 | P6: 가속 Factor | Q6: WATER TANK FILTER 청결상태 | R6: T1 | S6: T2 | T6: T3 | U6: T4 | V6: T1 | W6: T2 | X6: T3 | Y6: T4 | Z6: T1 | AA6: T2 | AB6: T3 | AC6: T4 | AD6: 스핀들 소음유무 측정 | AE6: 필터세척/유량계 유량 측정 | AF6: 필터교체/BELT TENSION 측정
A7: 45971 | B7: 1 | C7: =IF(B7="","", IF(MOD($B7,1)=0, "Dimensions: L W H", "-" ) ) -> Dimensions: L W H | D7: =IF(E7="","", IF(MOD($B7,1)=0, "완료", "-" ) ) -> 완료 | E7: 19 | G7: 누락 | H7: - | I7: - | J7: 누락 | L7: VITA | M7: MARK II | N7: 160 | O7: - | P7: =IF(LEN(A7)>0, 종합!$C$27, "") -> 2.26 | Q7: - | R7: =IF(MOD($B7,5)=0, "스핀들유격: ","-" ) -> - | S7: =IF(MOD($B7,5)=0, "스핀들유격: ","-" ) -> - | T7: =IF(MOD($B7,5)=0, "스핀들유격: ","-" ) -> - | U7: =IF(MOD($B7,5)=0, "스핀들유격: ","-" ) -> - | V7: =IF(MOD($B7,5)=0, "000-000","-" ) -> - | W7: =IF(MOD($B7,5)=0, "000-000","-" ) -> - | X7: =IF(MOD($B7,5)=0, "000-000","-" ) -> - | Y7: =IF(MOD($B7,5)=0, "000-000","-" ) -> - | Z7: =IF(MOD($B7,5)=0, "000-000","-" ) -> - | AA7: =IF(MOD($B7,5)=0, "000-000","-" ) -> - | AB7: =IF(MOD($B7,5)=0, "000-000","-" ) -> - | AC7: =IF(MOD($B7,5)=0, "000-000","-" ) -> - | AD7: =IF(MOD($B7,5)=0, "스핀들소음 :","-" ) -> - | AE7: =IF(MOD($B7,40)=0, "필터세척 :"& CHAR(10) & "FLOW (T1, T4 : / T2, T3 : / T4 : )","-" ) -> - | AF7: =IF($B7="","", IF(MOD($B7,160)=0, "TENSION (XL : / ZL : / XR : / ZR : / Y : )" & CHAR(10) & "필터교체", "-" ) ) -> - | AG7: -
A8: 45971 | B8: =IF(NOT(LEN(A8)=0),B7+1,"") -> 2 | C8: =IF(B8="","", IF(MOD($B8,1)=0, "Dimensions: L W H", "-" ) ) -> Dimensions: L W H | D8: =IF(E8="","", IF(MOD($B8,1)=0, "완료", "-" ) ) -> 완료 | E8: 19 | G8: 누락 | H8: - | I8: - | J8: 누락 | L8: =IF(NOT(LEN($J8)=0),L7,"") -> VITA | M8: =IF(NOT(LEN($J8)=0),M7,"") -> MARK II | N8: =IF(NOT(LEN($J8)=0),N7,"") -> 160 | O8: =IF(NOT(LEN($J8)=0),O7,"") -> - | P8: =IF(LEN(A8)>0, 종합!$C$27, "") -> 2.26 | Q8: - | R8: =IF(MOD($B8,5)=0, "스핀들유격: ","-" ) -> - | S8: =IF(MOD($B8,5)=0, "스핀들유격: ","-" ) -> - | T8: =IF(MOD($B8,5)=0, "스핀들유격: ","-" ) -> - | U8: =IF(MOD($B8,5)=0, "스핀들유격: ","-" ) -> - | V8: =IF(MOD($B8,5)=0, "000-000","-" ) -> - | W8: =IF(MOD($B8,5)=0, "000-000","-" ) -> - | X8: =IF(MOD($B8,5)=0, "000-000","-" ) -> - | Y8: =IF(MOD($B8,5)=0, "000-000","-" ) -> - | Z8: =IF(MOD($B8,5)=0, "000-000","-" ) -> - | AA8: =IF(MOD($B8,5)=0, "000-000","-" ) -> - | AB8: =IF(MOD($B8,5)=0, "000-000","-" ) -> - | AC8: =IF(MOD($B8,5)=0, "000-000","-" ) -> - | AD8: =IF(MOD($B8,5)=0, "스핀들소음 :","-" ) -> - | AE8: =IF(MOD($B8,40)=0, "필터세척 :"& CHAR(10) & "FLOW (T1, T4 : / T2, T3 : / T4 : )","-" ) -> - | AF8: =IF($B8="","", IF(MOD(B8,160)=0, "TENSION (XL : / ZL : / XR : / ZR : / Y : )" & CHAR(10) & "필터교체", "-" ) ) -> - | AG8: -
A9: 45971 | B9: =IF(NOT(LEN(A9)=0),B8+1,"") -> 3 | C9: =IF(B9="","", IF(MOD($B9,1)=0, "Dimensions: L W H", "-" ) ) -> Dimensions: L W H | D9: =IF(E9="","", IF(MOD($B9,1)=0, "완료", "-" ) ) -> 완료 | E9: 19 | G9: 누락 | H9: - | I9: - | J9: 누락 | L9: =IF(NOT(LEN($J9)=0),L8,"") -> VITA | M9: =IF(NOT(LEN($J9)=0),M8,"") -> MARK II | N9: =IF(NOT(LEN($J9)=0),N8,"") -> 160 | O9: =IF(NOT(LEN($J9)=0),O8,"") -> - | P9: =IF(LEN(A9)>0, 종합!$C$27, "") -> 2.26 | Q9: - | R9: =IF(MOD($B9,5)=0, "스핀들유격: ","-" ) -> - | S9: =IF(MOD($B9,5)=0, "스핀들유격: ","-" ) -> - | T9: =IF(MOD($B9,5)=0, "스핀들유격: ","-" ) -> - | U9: =IF(MOD($B9,5)=0, "스핀들유격: ","-" ) -> - | V9: =IF(MOD($B9,5)=0, "000-000","-" ) -> - | W9: =IF(MOD($B9,5)=0, "000-000","-" ) -> - | X9: =IF(MOD($B9,5)=0, "000-000","-" ) -> - | Y9: =IF(MOD($B9,5)=0, "000-000","-" ) -> - | Z9: =IF(MOD($B9,5)=0, "000-000","-" ) -> - | AA9: =IF(MOD($B9,5)=0, "000-000","-" ) -> - | AB9: =IF(MOD($B9,5)=0, "000-000","-" ) -> - | AC9: =IF(MOD($B9,5)=0, "000-000","-" ) -> - | AD9: =IF(MOD($B9,5)=0, "스핀들소음 :","-" ) -> - | AE9: =IF(MOD($B9,40)=0, "필터세척 :"& CHAR(10) & "FLOW (T1, T4 : / T2, T3 : / T4 : )","-" ) -> - | AF9: =IF($B9="","", IF(MOD(B9,160)=0, "TENSION (XL : / ZL : / XR : / ZR : / Y : )" & CHAR(10) & "필터교체", "-" ) ) -> - | AG9: -
A10: 45971 | B10: =IF(NOT(LEN(A10)=0),B9+1,"") -> 4 | C10: =IF(B10="","", IF(MOD($B10,1)=0, "Dimensions: L W H", "-" ) ) -> Dimensions: L W H | D10: =IF(E10="","", IF(MOD($B10,1)=0, "완료", "-" ) ) -> 완료 | E10: 21 | G10: 누락 | H10: - | I10: - | J10: 누락 | L10: =IF(NOT(LEN($J10)=0),L9,"") -> VITA | M10: =IF(NOT(LEN($J10)=0),M9,"") -> MARK II | N10: =IF(NOT(LEN($J10)=0),N9,"") -> 160 | O10: =IF(NOT(LEN($J10)=0),O9,"") -> - | P10: =IF(LEN(A10)>0, 종합!$C$27, "") -> 2.26 | Q10: - | R10: =IF(MOD($B10,5)=0, "스핀들유격: ","-" ) -> - | S10: =IF(MOD($B10,5)=0, "스핀들유격: ","-" ) -> - | T10: =IF(MOD($B10,5)=0, "스핀들유격: ","-" ) -> - | U10: =IF(MOD($B10,5)=0, "스핀들유격: ","-" ) -> - | V10: =IF(MOD($B10,5)=0, "000-000","-" ) -> - | W10: =IF(MOD($B10,5)=0, "000-000","-" ) -> - | X10: =IF(MOD($B10,5)=0, "000-000","-" ) -> - | Y10: =IF(MOD($B10,5)=0, "000-000","-" ) -> - | Z10: =IF(MOD($B10,5)=0, "000-000","-" ) -> - | AA10: =IF(MOD($B10,5)=0, "000-000","-" ) -> - | AB10: =IF(MOD($B10,5)=0, "000-000","-" ) -> - | AC10: =IF(MOD($B10,5)=0, "000-000","-" ) -> - | AD10: =IF(MOD($B10,5)=0, "스핀들소음 :","-" ) -> - | AE10: =IF(MOD($B10,40)=0, "필터세척 :"& CHAR(10) & "FLOW (T1, T4 : / T2, T3 : / T4 : )","-" ) -> - | AF10: =IF($B10="","", IF(MOD(B10,160)=0, "TENSION (XL : / ZL : / XR : / ZR : / Y : )" & CHAR(10) & "필터교체", "-" ) ) -> - | AG10: -
A11: 45971 | B11: =IF(NOT(LEN(A11)=0),B10+1,"") -> 5 | C11: =IF(B11="","", IF(MOD($B11,1)=0, "Dimensions: L W H", "-" ) ) -> Dimensions: L W H | D11: =IF(E11="","", IF(MOD($B11,1)=0, "완료", "-" ) ) -> 완료 | E11: 21 | G11: 누락 | H11: - | I11: - | J11: 누락 | L11: =IF(NOT(LEN($J11)=0),L10,"") -> VITA | M11: =IF(NOT(LEN($J11)=0),M10,"") -> MARK II | N11: =IF(NOT(LEN($J11)=0),N10,"") -> 160 | O11: =IF(NOT(LEN($J11)=0),O10,"") -> - | P11: =IF(LEN(A11)>0, 종합!$C$27, "") -> 2.26 | Q11: - | R11: 스핀들유격: 적정 | S11: 스핀들유격: 적정 | T11: 스핀들유격: 적정 | U11: 스핀들유격: 적정 | V11: 101-223 | W11: 132-320 | X11: 113-202 | Y11: 100-343 | Z11: 245-291 | AA11: 264-310 | AB11: 208-270 | AC11: 206-250 | AD11: 스핀들소음: 적정 | AE11: =IF(MOD($B11,40)=0, "필터세척 :"& CHAR(10) & "FLOW (T1, T4 : / T2, T3 : / T4 : )","-" ) -> - | AF11: =IF($B11="","", IF(MOD(B11,160)=0, "TENSION (XL : / ZL : / XR : / ZR : / Y : )" & CHAR(10) & "필터교체", "-" ) ) -> - | AG11: -
A12: 45971 | B12: =IF(NOT(LEN(A12)=0),B11+1,"") -> 6 | C12: =IF(B12="","", IF(MOD($B12,1)=0, "Dimensions: L W H", "-" ) ) -> Dimensions: L W H | D12: =IF(E12="","", IF(MOD($B12,1)=0, "완료", "-" ) ) -> 완료 | E12: 19 | G12: 누락 | H12: - | I12: - | J12: 누락 | L12: =IF(NOT(LEN($J12)=0),L11,"") -> VITA | M12: =IF(NOT(LEN($J12)=0),M11,"") -> MARK II | N12: =IF(NOT(LEN($J12)=0),N11,"") -> 160 | O12: =IF(NOT(LEN($J12)=0),O11,"") -> - | P12: =IF(LEN(A12)>0, 종합!$C$27, "") -> 2.26 | Q12: - | R12: =IF(MOD($B12,5)=0, "스핀들유격: ","-" ) -> - | S12: =IF(MOD($B12,5)=0, "스핀들유격: ","-" ) -> - | T12: =IF(MOD($B12,5)=0, "스핀들유격: ","-" ) -> - | U12: =IF(MOD($B12,5)=0, "스핀들유격: ","-" ) -> - | V12: =IF(MOD($B12,5)=0, "000-000","-" ) -> - | W12: =IF(MOD($B12,5)=0, "000-000","-" ) -> - | X12: =IF(MOD($B12,5)=0, "000-000","-" ) -> - | Y12: =IF(MOD($B12,5)=0, "000-000","-" ) -> - | Z12: =IF(MOD($B12,5)=0, "000-000","-" ) -> - | AA12: =IF(MOD($B12,5)=0, "000-000","-" ) -> - | AB12: =IF(MOD($B12,5)=0, "000-000","-" ) -> - | AC12: =IF(MOD($B12,5)=0, "000-000","-" ) -> - | AD12: =IF(MOD($B12,5)=0, "스핀들소음 :","-" ) -> - | AE12: =IF(MOD($B12,40)=0, "필터세척 :"& CHAR(10) & "FLOW (T1, T4 : / T2, T3 : / T4 : )","-" ) -> - | AF12: =IF($B12="","", IF(MOD(B12,160)=0, "TENSION (XL : / ZL : / XR : / ZR : / Y : )" & CHAR(10) & "필터교체", "-" ) ) -> - | AG12: -
A13: 45972 | B13: =IF(NOT(LEN(A13)=0),B12+1,"") -> 7 | C13: =IF(B13="","", IF(MOD($B13,1)=0, "Dimensions: L W H", "-" ) ) -> Dimensions: L W H | D13: =IF(E13="","", IF(MOD($B13,1)=0, "완료", "-" ) ) -> 완료 | E13: 23 | G13: 0 | H13: - | I13: - | J13: 0 | L13: =IF(NOT(LEN($J13)=0),L12,"") -> VITA | M13: =IF(NOT(LEN($J13)=0),M12,"") -> MARK II | N13: =IF(NOT(LEN($J13)=0),N12,"") -> 160 | O13: =IF(NOT(LEN($J13)=0),O12,"") -> - | P13: =IF(LEN(A13)>0, 종합!$C$27, "") -> 2.26 | Q13: - | R13: =IF(MOD($B13,5)=0, "스핀들유격: ","-" ) -> - | S13: =IF(MOD($B13,5)=0, "스핀들유격: ","-" ) -> - | T13: =IF(MOD($B13,5)=0, "스핀들유격: ","-" ) -> - | U13: =IF(MOD($B13,5)=0, "스핀들유격: ","-" ) -> - | V13: =IF(MOD($B13,5)=0, "000-000","-" ) -> - | W13: =IF(MOD($B13,5)=0, "000-000","-" ) -> - | X13: =IF(MOD($B13,5)=0, "000-000","-" ) -> - | Y13: =IF(MOD($B13,5)=0, "000-000","-" ) -> - | Z13: =IF(MOD($B13,5)=0, "000-000","-" ) -> - | AA13: =IF(MOD($B13,5)=0, "000-000","-" ) -> - | AB13: =IF(MOD($B13,5)=0, "000-000","-" ) -> - | AC13: =IF(MOD($B13,5)=0, "000-000","-" ) -> - | AD13: =IF(MOD($B13,5)=0, "스핀들소음 :","-" ) -> - | AE13: =IF(MOD($B13,40)=0, "필터세척 :"& CHAR(10) & "FLOW (T1, T4 : / T2, T3 : / T4 : )","-" ) -> - | AF13: =IF($B13="","", IF(MOD(B13,160)=0, "TENSION (XL : / ZL : / XR : / ZR : / Y : )" & CHAR(10) & "필터교체", "-" ) ) -> - | AG13: -
A14: 45972 | B14: =IF(NOT(LEN(A14)=0),B13+1,"") -> 8 | C14: =IF(B14="","", IF(MOD($B14,1)=0, "Dimensions: L W H", "-" ) ) -> Dimensions: L W H | D14: =IF(E14="","", IF(MOD($B14,1)=0, "완료", "-" ) ) -> 완료 | E14: 21 | G14: =IF(NOT(LEN($A14)=0),IF(G13+1>15,"버교체요망",G13+1),"") -> 1 | H14: - | I14: - | J14: =IF(NOT(LEN($A14)=0),IF(J13+1>15,"버교체요망",J13+1),"") -> 1 | L14: =IF(NOT(LEN($J14)=0),L13,"") -> VITA | M14: =IF(NOT(LEN($J14)=0),M13,"") -> MARK II | N14: =IF(NOT(LEN($J14)=0),N13,"") -> 160 | O14: =IF(NOT(LEN($J14)=0),O13,"") -> - | P14: =IF(LEN(A14)>0, 종합!$C$27, "") -> 2.26 | Q14: - | R14: =IF(MOD($B14,5)=0, "스핀들유격: ","-" ) -> - | S14: =IF(MOD($B14,5)=0, "스핀들유격: ","-" ) -> - | T14: =IF(MOD($B14,5)=0, "스핀들유격: ","-" ) -> - | U14: =IF(MOD($B14,5)=0, "스핀들유격: ","-" ) -> - | V14: =IF(MOD($B14,5)=0, "000-000","-" ) -> - | W14: =IF(MOD($B14,5)=0, "000-000","-" ) -> - | X14: =IF(MOD($B14,5)=0, "000-000","-" ) -> - | Y14: =IF(MOD($B14,5)=0, "000-000","-" ) -> - | Z14: =IF(MOD($B14,5)=0, "000-000","-" ) -> - | AA14: =IF(MOD($B14,5)=0, "000-000","-" ) -> - | AB14: =IF(MOD($B14,5)=0, "000-000","-" ) -> - | AC14: =IF(MOD($B14,5)=0, "000-000","-" ) -> - | AD14: =IF(MOD($B14,5)=0, "스핀들소음 :","-" ) -> - | AE14: =IF(MOD($B14,40)=0, "필터세척 :"& CHAR(10) & "FLOW (T1, T4 : / T2, T3 : / T4 : )","-" ) -> - | AF14: =IF($B14="","", IF(MOD(B14,160)=0, "TENSION (XL : / ZL : / XR : / ZR : / Y : )" & CHAR(10) & "필터교체", "-" ) ) -> - | AG14: -
A15: 45972 | B15: =IF(NOT(LEN(A15)=0),B14+1,"") -> 9 | C15: =IF(B15="","", IF(MOD($B15,1)=0, "Dimensions: L W H", "-" ) ) -> Dimensions: L W H | D15: =IF(E15="","", IF(MOD($B15,1)=0, "완료", "-" ) ) -> 완료 | E15: 21 | G15: =IF(NOT(LEN($A15)=0),IF(G14+1>15,"버교체요망",G14+1),"") -> 2 | H15: - | I15: - | J15: =IF(NOT(LEN($A15)=0),IF(J14+1>15,"버교체요망",J14+1),"") -> 2 | L15: =IF(NOT(LEN($J15)=0),L14,"") -> VITA | M15: =IF(NOT(LEN($J15)=0),M14,"") -> MARK II | N15: =IF(NOT(LEN($J15)=0),N14,"") -> 160 | O15: =IF(NOT(LEN($J15)=0),O14,"") -> - | P15: =IF(LEN(A15)>0, 종합!$C$27, "") -> 2.26 | Q15: - | R15: =IF(MOD($B15,5)=0, "스핀들유격: ","-" ) -> - | S15: =IF(MOD($B15,5)=0, "스핀들유격: ","-" ) -> - | T15: =IF(MOD($B15,5)=0, "스핀들유격: ","-" ) -> - | U15: =IF(MOD($B15,5)=0, "스핀들유격: ","-" ) -> - | V15: =IF(MOD($B15,5)=0, "000-000","-" ) -> - | W15: =IF(MOD($B15,5)=0, "000-000","-" ) -> - | X15: =IF(MOD($B15,5)=0, "000-000","-" ) -> - | Y15: =IF(MOD($B15,5)=0, "000-000","-" ) -> - | Z15: =IF(MOD($B15,5)=0, "000-000","-" ) -> - | AA15: =IF(MOD($B15,5)=0, "000-000","-" ) -> - | AB15: =IF(MOD($B15,5)=0, "000-000","-" ) -> - | AC15: =IF(MOD($B15,5)=0, "000-000","-" ) -> - | AD15: =IF(MOD($B15,5)=0, "스핀들소음 :","-" ) -> - | AE15: =IF(MOD($B15,40)=0, "필터세척 :"& CHAR(10) & "FLOW (T1, T4 : / T2, T3 : / T4 : )","-" ) -> - | AF15: =IF($B15="","", IF(MOD(B15,160)=0, "TENSION (XL : / ZL : / XR : / ZR : / Y : )" & CHAR(10) & "필터교체", "-" ) ) -> - | AG15: -
A16: 45972 | B16: =IF(NOT(LEN(A16)=0),B15+1,"") -> 10 | C16: =IF(B16="","", IF(MOD($B16,1)=0, "Dimensions: L W H", "-" ) ) -> Dimensions: L W H | D16: =IF(E16="","", IF(MOD($B16,1)=0, "완료", "-" ) ) -> 완료 | E16: 21 | G16: =IF(NOT(LEN($A16)=0),IF(G15+1>15,"버교체요망",G15+1),"") -> 3 | H16: - | I16: - | J16: =IF(NOT(LEN($A16)=0),IF(J15+1>15,"버교체요망",J15+1),"") -> 3 | L16: =IF(NOT(LEN($J16)=0),L15,"") -> VITA | M16: =IF(NOT(LEN($J16)=0),M15,"") -> MARK II | N16: =IF(NOT(LEN($J16)=0),N15,"") -> 160 | O16: =IF(NOT(LEN($J16)=0),O15,"") -> - | P16: =IF(LEN(A16)>0, 종합!$C$27, "") -> 2.26 | Q16: - | R16: =IF(MOD($B16,5)=0, "스핀들유격: ","-" ) -> 스핀들유격: | S16: =IF(MOD($B16,5)=0, "스핀들유격: ","-" ) -> 스핀들유격: | T16: =IF(MOD($B16,5)=0, "스핀들유격: ","-" ) -> 스핀들유격: | U16: =IF(MOD($B16,5)=0, "스핀들유격: ","-" ) -> 스핀들유격: | V16: =IF(MOD($B16,5)=0, "000-000","-" ) -> 000-000 | W16: =IF(MOD($B16,5)=0, "000-000","-" ) -> 000-000 | X16: =IF(MOD($B16,5)=0, "000-000","-" ) -> 000-000 | Y16: =IF(MOD($B16,5)=0, "000-000","-" ) -> 000-000 | Z16: =IF(MOD($B16,5)=0, "000-000","-" ) -> 000-000 | AA16: =IF(MOD($B16,5)=0, "000-000","-" ) -> 000-000 | AB16: =IF(MOD($B16,5)=0, "000-000","-" ) -> 000-000 | AC16: =IF(MOD($B16,5)=0, "000-000","-" ) -> 000-000 | AD16: =IF(MOD($B16,5)=0, "스핀들소음 :","-" ) -> 스핀들소음 : | AE16: =IF(MOD($B16,40)=0, "필터세척 :"& CHAR(10) & "FLOW (T1, T4 : / T2, T3 : / T4 : )","-" ) -> - | AF16: =IF($B16="","", IF(MOD(B16,160)=0, "TENSION (XL : / ZL : / XR : / ZR : / Y : )" & CHAR(10) & "필터교체", "-" ) ) -> - | AG16: issue_2025_11_11_1100
A17: 45973 | B17: =IF(NOT(LEN(A17)=0),B16+1,"") -> 11 | C17: =IF(B17="","", IF(MOD($B17,1)=0, "Dimensions: L W H", "-" ) ) -> Dimensions: L W H | D17: =IF(E17="","", IF(MOD($B17,1)=0, "완료", "-" ) ) -> 완료 | E17: 23 | G17: =IF(NOT(LEN($A17)=0),IF(G16+1>15,"버교체요망",G16+1),"") -> 4 | H17: - | I17: - | J17: =IF(NOT(LEN($A17)=0),IF(J16+1>15,"버교체요망",J16+1),"") -> 4 | L17: =IF(NOT(LEN($J17)=0),L16,"") -> VITA | M17: =IF(NOT(LEN($J17)=0),M16,"") -> MARK II | N17: =IF(NOT(LEN($J17)=0),N16,"") -> 160 | O17: =IF(NOT(LEN($J17)=0),O16,"") -> - | P17: =IF(LEN(A17)>0, 종합!$C$27, "") -> 2.26 | Q17: - | R17: =IF(MOD($B17,5)=0, "스핀들유격: ","-" ) -> - | S17: =IF(MOD($B17,5)=0, "스핀들유격: ","-" ) -> - | T17: =IF(MOD($B17,5)=0, "스핀들유격: ","-" ) -> - | U17: =IF(MOD($B17,5)=0, "스핀들유격: ","-" ) -> - | V17: =IF(MOD($B17,5)=0, "000-000","-" ) -> - | W17: =IF(MOD($B17,5)=0, "000-000","-" ) -> - | X17: =IF(MOD($B17,5)=0, "000-000","-" ) -> - | Y17: =IF(MOD($B17,5)=0, "000-000","-" ) -> - | Z17: =IF(MOD($B17,5)=0, "000-000","-" ) -> - | AA17: =IF(MOD($B17,5)=0, "000-000","-" ) -> - | AB17: =IF(MOD($B17,5)=0, "000-000","-" ) -> - | AC17: =IF(MOD($B17,5)=0, "000-000","-" ) -> - | AD17: =IF(MOD($B17,5)=0, "스핀들소음 :","-" ) -> - | AE17: =IF(MOD($B17,40)=0, "필터세척 :"& CHAR(10) & "FLOW (T1, T4 : / T2, T3 : / T4 : )","-" ) -> - | AF17: =IF($B17="","", IF(MOD(B17,160)=0, "TENSION (XL : / ZL : / XR : / ZR : / Y : )" & CHAR(10) & "필터교체", "-" ) ) -> - | AG17: issue_2025_11_11_1100 이슈 있지만 물닦으면서 가공진행
A18: 45973 | B18: =IF(NOT(LEN(A18)=0),B17+1,"") -> 12 | C18: =IF(B18="","", IF(MOD($B18,1)=0, "Dimensions: L W H", "-" ) ) -> Dimensions: L W H | D18: =IF(NOT(LEN(B18)=0),"진행중","") -> 진행중 | E18: 21 | G18: =IF(NOT(LEN($A18)=0),IF(G17+1>15,"버교체요망",G17+1),"") -> 5 | J18: =IF(NOT(LEN($A18)=0),IF(J17+1>15,"버교체요망",J17+1),"") -> 5 | L18: =IF(NOT(LEN($J18)=0),L17,"") -> VITA | M18: =IF(NOT(LEN($J18)=0),M17,"") -> MARK II | N18: =IF(NOT(LEN($J18)=0),N17,"") -> 160 | O18: =IF(NOT(LEN($J18)=0),O17,"") -> - | P18: =IF(LEN(A18)>0, 종합!$C$27, "") -> 2.26
B19: =IF(NOT(LEN(A19)=0),B18+1,"") | C19: =IF(B19="","", IF(MOD($B19,1)=0, "Dimensions: L W H", "-" ) ) | D19: =IF(NOT(LEN(B19)=0),"진행중","") | G19: =IF(NOT(LEN($A19)=0),IF(G18+1>15,"버교체요망",G18+1),"") | J19: =IF(NOT(LEN($A19)=0),IF(J18+1>15,"버교체요망",J18+1),"")
B20: =IF(NOT(LEN(A20)=0),B19+1,"") | C20: =IF(B20="","", IF(MOD($B20,1)=0, "Dimensions: L W H", "-" ) ) | D20: =IF(NOT(LEN(B20)=0),"진행중","") | G20: =IF(NOT(LEN($A20)=0),IF(G19+1>15,"버교체요망",G19+1),"") | J20: =IF(NOT(LEN($A20)=0),IF(J19+1>15,"버교체요망",J19+1),"")
B21: =IF(NOT(LEN(A21)=0),B20+1,"") | C21: =IF(B21="","", IF(MOD($B21,1)=0, "Dimensions: L W H", "-" ) ) | D21: =IF(NOT(LEN(B21)=0),"진행중","") | G21: =IF(NOT(LEN($A21)=0),IF(G20+1>15,"버교체요망",G20+1),"") | J21: =IF(NOT(LEN($A21)=0),IF(J20+1>15,"버교체요망",J20+1),"")
B22: =IF(NOT(LEN(A22)=0),B21+1,"") | C22: =IF(B22="","", IF(MOD($B22,1)=0, "Dimensions: L W H", "-" ) ) | D22: =IF(NOT(LEN(B22)=0),"진행중","") | G22: =IF(NOT(LEN($A22)=0),IF(G21+1>15,"버교체요망",G21+1),"") | J22: =IF(NOT(LEN($A22)=0),IF(J21+1>15,"버교체요망",J21+1),"")
A23: TABLE OUTLINE | B23: TABLE OUTLINE | C23: TABLE OUTLINE | D23: TABLE OUTLINE | E23: TABLE OUTLINE | F23: TABLE OUTLINE | G23: TABLE OUTLINE | H23: TABLE OUTLINE | I23: TABLE OUTLINE | J23: TABLE OUTLINE | K23: TABLE OUTLINE | L23: TABLE OUTLINE | M23: TABLE OUTLINE | N23: TABLE OUTLINE | O23: TABLE OUTLINE | P23: TABLE OUTLINE | Q23: TABLE OUTLINE | R23: TABLE OUTLINE | S23: TABLE OUTLINE | T23: TABLE OUTLINE | U23: TABLE OUTLINE | V23: TABLE OUTLINE | W23: TABLE OUTLINE | X23: TABLE OUTLINE | Y23: TABLE OUTLINE | Z23: TABLE OUTLINE | AA23: TABLE OUTLINE | AB23: TABLE OUTLINE | AC23: TABLE OUTLINE | AD23: TABLE OUTLINE | AE23: TABLE OUTLINE | AF23: TABLE OUTLINE | AG23: TABLE OUTLINE | AH23: TABLE OUTLINE

Sheet PP#4
A1: LM-10 SPINDLE 내구도 신뢰성 시험이력
A2: 수행기간 | B2: 산출물 | G2: 시험 적용 | Q2: 사전점검(시험 전 점검항목) | AG2: 특이사항
R4: 5회 가공회차 주기 | AE4: 40회 가공회차 주기 | AF4: 160회 가공회차 주기
